{"directory":"/Resources/BlockStructure/","configurationData":{"type":1,"distance":12,"padding":0,"height":8,"isTwoDirection":false},"blocks":[{"position":{"x":-7,"y":0,"z":6},"blockType":9},{"position":{"x":-6,"y":0,"z":6},"blockType":9},{"position":{"x":-5,"y":0,"z":6},"blockType":9},{"position":{"x":4,"y":0,"z":6},"blockType":9},{"position":{"x":5,"y":0,"z":6},"blockType":9},{"position":{"x":6,"y":0,"z":6},"blockType":9},{"position":{"x":-7,"y":0,"z":-7},"blockType":9},{"position":{"x":-6,"y":0,"z":-7},"blockType":9},{"position":{"x":-5,"y":0,"z":-7},"blockType":9},{"position":{"x":-4,"y":0,"z":-7},"blockType":9},{"position":{"x":3,"y":0,"z":-7},"blockType":9},{"position":{"x":4,"y":0,"z":-7},"blockType":9},{"position":{"x":5,"y":0,"z":-7},"blockType":9},{"position":{"x":6,"y":0,"z":-7},"blockType":9},{"position":{"x":2,"y":0,"z":5},"blockType":9},{"position":{"x":-3,"y":0,"z":5},"blockType":9},{"position":{"x":3,"y":0,"z":6},"blockType":9},{"position":{"x":7,"y":0,"z":6},"blockType":9},{"position":{"x":8,"y":0,"z":6},"blockType":9},{"position":{"x":9,"y":0,"z":6},"blockType":9},{"position":{"x":-8,"y":0,"z":6},"blockType":9},{"position":{"x":-9,"y":0,"z":6},"blockType":9},{"position":{"x":-10,"y":0,"z":6},"blockType":9},{"position":{"x":-11,"y":0,"z":6},"blockType":9},{"position":{"x":-11,"y":0,"z":5},"blockType":9},{"position":{"x":-11,"y":0,"z":4},"blockType":9},{"position":{"x":-11,"y":0,"z":3},"blockType":9},{"position":{"x":-11,"y":0,"z":2},"blockType":9},{"position":{"x":-11,"y":0,"z":1},"blockType":9},{"position":{"x":-11,"y":0,"z":0},"blockType":9},{"position":{"x":-11,"y":0,"z":-1},"blockType":9},{"position":{"x":-11,"y":0,"z":-2},"blockType":9},{"position":{"x":-11,"y":0,"z":-3},"blockType":9},{"position":{"x":-11,"y":0,"z":-4},"blockType":9},{"position":{"x":-11,"y":0,"z":-5},"blockType":9},{"position":{"x":-11,"y":0,"z":-6},"blockType":9},{"position":{"x":-11,"y":0,"z":-7},"blockType":9},{"position":{"x":-10,"y":0,"z":-7},"blockType":9},{"position":{"x":-9,"y":0,"z":-7},"blockType":9},{"position":{"x":-8,"y":0,"z":-7},"blockType":9},{"position":{"x":7,"y":0,"z":-7},"blockType":9},{"position":{"x":8,"y":0,"z":-7},"blockType":9},{"position":{"x":9,"y":0,"z":-7},"blockType":9},{"position":{"x":9,"y":0,"z":-6},"blockType":9},{"position":{"x":9,"y":0,"z":-5},"blockType":9},{"position":{"x":9,"y":0,"z":-4},"blockType":9},{"position":{"x":9,"y":0,"z":-3},"blockType":9},{"position":{"x":9,"y":0,"z":-2},"blockType":9},{"position":{"x":9,"y":0,"z":-1},"blockType":9},{"position":{"x":9,"y":0,"z":0},"blockType":9},{"position":{"x":9,"y":0,"z":1},"blockType":9},{"position":{"x":9,"y":0,"z":2},"blockType":9},{"position":{"x":9,"y":0,"z":3},"blockType":9},{"position":{"x":9,"y":0,"z":4},"blockType":9},{"position":{"x":9,"y":0,"z":5},"blockType":9},{"position":{"x":-4,"y":0,"z":5},"blockType":9},{"position":{"x":3,"y":0,"z":5},"blockType":9},{"position":{"x":-2,"y":0,"z":5},"blockType":9},{"position":{"x":-1,"y":0,"z":5},"blockType":9},{"position":{"x":0,"y":0,"z":5},"blockType":9},{"position":{"x":1,"y":0,"z":5},"blockType":9},{"position":{"x":-4,"y":0,"z":6},"blockType":9},{"position":{"x":-4,"y":0,"z":-6},"blockType":9},{"position":{"x":-4,"y":0,"z":-5},"blockType":9},{"position":{"x":-4,"y":0,"z":-4},"blockType":9},{"position":{"x":-4,"y":0,"z":-3},"blockType":9},{"position":{"x":-4,"y":0,"z":-2},"blockType":9},{"position":{"x":-3,"y":0,"z":-2},"blockType":9},{"position":{"x":-2,"y":0,"z":-2},"blockType":9},{"position":{"x":-1,"y":0,"z":-2},"blockType":9},{"position":{"x":0,"y":0,"z":-2},"blockType":9},{"position":{"x":1,"y":0,"z":-2},"blockType":9},{"position":{"x":2,"y":0,"z":-2},"blockType":9},{"position":{"x":3,"y":0,"z":-2},"blockType":9},{"position":{"x":3,"y":0,"z":-3},"blockType":9},{"position":{"x":3,"y":0,"z":-4},"blockType":9},{"position":{"x":3,"y":0,"z":-5},"blockType":9},{"position":{"x":3,"y":0,"z":-6},"blockType":9},{"position":{"x":-8,"y":0,"z":4},"blockType":6},{"position":{"x":-8,"y":0,"z":3},"blockType":6},{"position":{"x":-7,"y":0,"z":3},"blockType":6},{"position":{"x":-7,"y":0,"z":2},"blockType":6},{"position":{"x":-7,"y":0,"z":1},"blockType":6},{"position":{"x":-8,"y":0,"z":1},"blockType":6},{"position":{"x":-8,"y":0,"z":0},"blockType":6},{"position":{"x":-9,"y":0,"z":4},"blockType":6},{"position":{"x":-7,"y":0,"z":4},"blockType":6},{"position":{"x":-6,"y":0,"z":4},"blockType":6},{"position":{"x":2,"y":0,"z":3},"blockType":6},{"position":{"x":5,"y":0,"z":4},"blockType":6},{"position":{"x":6,"y":0,"z":4},"blockType":6},{"position":{"x":-9,"y":0,"z":3},"blockType":6},{"position":{"x":-6,"y":0,"z":3},"blockType":6},{"position":{"x":-5,"y":0,"z":3},"blockType":6},{"position":{"x":-4,"y":0,"z":3},"blockType":6},{"position":{"x":-3,"y":0,"z":3},"blockType":6},{"position":{"x":3,"y":0,"z":3},"blockType":6},{"position":{"x":4,"y":0,"z":3},"blockType":6},{"position":{"x":-9,"y":0,"z":2},"blockType":6},{"position":{"x":-8,"y":0,"z":2},"blockType":6},{"position":{"x":-6,"y":0,"z":2},"blockType":6},{"position":{"x":-5,"y":0,"z":2},"blockType":6},{"position":{"x":-4,"y":0,"z":2},"blockType":6},{"position":{"x":-3,"y":0,"z":2},"blockType":6},{"position":{"x":2,"y":0,"z":2},"blockType":6},{"position":{"x":3,"y":0,"z":2},"blockType":6},{"position":{"x":4,"y":0,"z":2},"blockType":6},{"position":{"x":5,"y":0,"z":2},"blockType":6},{"position":{"x":6,"y":0,"z":2},"blockType":6},{"position":{"x":-6,"y":0,"z":1},"blockType":6},{"position":{"x":-5,"y":0,"z":1},"blockType":6},{"position":{"x":-4,"y":0,"z":1},"blockType":6},{"position":{"x":-3,"y":0,"z":1},"blockType":6},{"position":{"x":-2,"y":0,"z":1},"blockType":6},{"position":{"x":-1,"y":0,"z":1},"blockType":6},{"position":{"x":0,"y":0,"z":1},"blockType":6},{"position":{"x":1,"y":0,"z":1},"blockType":6},{"position":{"x":2,"y":0,"z":1},"blockType":6},{"position":{"x":3,"y":0,"z":1},"blockType":6},{"position":{"x":4,"y":0,"z":1},"blockType":6},{"position":{"x":5,"y":0,"z":1},"blockType":6},{"position":{"x":6,"y":0,"z":1},"blockType":6},{"position":{"x":-9,"y":0,"z":-4},"blockType":6},{"position":{"x":-4,"y":0,"z":0},"blockType":6},{"position":{"x":-6,"y":0,"z":-4},"blockType":6},{"position":{"x":-6,"y":0,"z":-5},"blockType":6},{"position":{"x":-6,"y":0,"z":-3},"blockType":6},{"position":{"x":-6,"y":0,"z":-2},"blockType":6},{"position":{"x":-6,"y":0,"z":-1},"blockType":6},{"position":{"x":-6,"y":0,"z":0},"blockType":6},{"position":{"x":-7,"y":0,"z":-3},"blockType":6},{"position":{"x":-7,"y":0,"z":-4},"blockType":6},{"position":{"x":-8,"y":0,"z":-4},"blockType":6},{"position":{"x":-8,"y":0,"z":-5},"blockType":6},{"position":{"x":-9,"y":0,"z":-3},"blockType":6},{"position":{"x":-7,"y":0,"z":-5},"blockType":6},{"position":{"x":-9,"y":0,"z":-5},"blockType":6},{"position":{"x":-9,"y":0,"z":-2},"blockType":6},{"position":{"x":-8,"y":0,"z":-1},"blockType":6},{"position":{"x":-8,"y":0,"z":-2},"blockType":6},{"position":{"x":-8,"y":0,"z":-3},"blockType":6},{"position":{"x":-7,"y":0,"z":-1},"blockType":6},{"position":{"x":-7,"y":0,"z":0},"blockType":6},{"position":{"x":-7,"y":0,"z":-2},"blockType":6},{"position":{"x":-5,"y":0,"z":0},"blockType":6},{"position":{"x":-3,"y":0,"z":0},"blockType":6},{"position":{"x":3,"y":0,"z":0},"blockType":6},{"position":{"x":-2,"y":0,"z":0},"blockType":6},{"position":{"x":-1,"y":0,"z":0},"blockType":6},{"position":{"x":0,"y":0,"z":0},"blockType":6},{"position":{"x":1,"y":0,"z":0},"blockType":6},{"position":{"x":2,"y":0,"z":0},"blockType":6},{"position":{"x":4,"y":0,"z":0},"blockType":6},{"position":{"x":5,"y":0,"z":0},"blockType":6},{"position":{"x":7,"y":0,"z":1},"blockType":6},{"position":{"x":5,"y":0,"z":3},"blockType":6},{"position":{"x":6,"y":0,"z":3},"blockType":6},{"position":{"x":7,"y":0,"z":2},"blockType":6},{"position":{"x":7,"y":0,"z":-1},"blockType":6},{"position":{"x":7,"y":0,"z":-2},"blockType":6},{"position":{"x":7,"y":0,"z":-3},"blockType":6},{"position":{"x":5,"y":0,"z":-1},"blockType":6},{"position":{"x":6,"y":0,"z":-5},"blockType":6},{"position":{"x":7,"y":0,"z":-5},"blockType":6},{"position":{"x":7,"y":0,"z":-4},"blockType":6},{"position":{"x":7,"y":0,"z":0},"blockType":6},{"position":{"x":6,"y":0,"z":0},"blockType":6},{"position":{"x":6,"y":0,"z":-1},"blockType":6},{"position":{"x":6,"y":0,"z":-2},"blockType":6},{"position":{"x":6,"y":0,"z":-3},"blockType":6},{"position":{"x":6,"y":0,"z":-4},"blockType":6},{"position":{"x":5,"y":0,"z":-5},"blockType":6},{"position":{"x":7,"y":0,"z":4},"blockType":6},{"position":{"x":7,"y":0,"z":3},"blockType":6},{"position":{"x":-2,"y":0,"z":-3},"blockType":7},{"position":{"x":1,"y":0,"z":-3},"blockType":7},{"position":{"x":-1,"y":0,"z":-3},"blockType":6},{"position":{"x":0,"y":0,"z":-3},"blockType":6},{"position":{"x":-10,"y":0,"z":5},"blockType":7},{"position":{"x":-9,"y":0,"z":5},"blockType":7},{"position":{"x":-8,"y":0,"z":5},"blockType":7},{"position":{"x":-7,"y":0,"z":5},"blockType":7},{"position":{"x":-6,"y":0,"z":5},"blockType":7},{"position":{"x":-5,"y":0,"z":5},"blockType":7},{"position":{"x":-10,"y":0,"z":4},"blockType":7},{"position":{"x":-10,"y":0,"z":3},"blockType":7},{"position":{"x":-10,"y":0,"z":2},"blockType":7},{"position":{"x":-10,"y":0,"z":1},"blockType":7},{"position":{"x":-10,"y":0,"z":0},"blockType":7},{"position":{"x":-10,"y":0,"z":-1},"blockType":7},{"position":{"x":-10,"y":0,"z":-2},"blockType":7},{"position":{"x":-10,"y":0,"z":-6},"blockType":7},{"position":{"x":-10,"y":0,"z":-5},"blockType":7},{"position":{"x":-10,"y":0,"z":-4},"blockType":7},{"position":{"x":-10,"y":0,"z":-3},"blockType":7},{"position":{"x":-9,"y":0,"z":-6},"blockType":7},{"position":{"x":-8,"y":0,"z":-6},"blockType":7},{"position":{"x":-7,"y":0,"z":-6},"blockType":7},{"position":{"x":-6,"y":0,"z":-6},"blockType":7},{"position":{"x":-5,"y":0,"z":-6},"blockType":7},{"position":{"x":-5,"y":0,"z":-5},"blockType":7},{"position":{"x":-5,"y":0,"z":-4},"blockType":7},{"position":{"x":-5,"y":0,"z":-3},"blockType":7},{"position":{"x":-5,"y":0,"z":-2},"blockType":7},{"position":{"x":-5,"y":0,"z":-1},"blockType":7},{"position":{"x":-4,"y":0,"z":-1},"blockType":7},{"position":{"x":-3,"y":0,"z":-1},"blockType":7},{"position":{"x":-2,"y":0,"z":-1},"blockType":7},{"position":{"x":-1,"y":0,"z":-1},"blockType":7},{"position":{"x":0,"y":0,"z":-1},"blockType":7},{"position":{"x":1,"y":0,"z":-1},"blockType":7},{"position":{"x":2,"y":0,"z":-1},"blockType":7},{"position":{"x":3,"y":0,"z":-1},"blockType":7},{"position":{"x":4,"y":0,"z":-1},"blockType":7},{"position":{"x":4,"y":0,"z":-6},"blockType":7},{"position":{"x":4,"y":0,"z":-5},"blockType":7},{"position":{"x":4,"y":0,"z":-4},"blockType":7},{"position":{"x":4,"y":0,"z":-3},"blockType":7},{"position":{"x":4,"y":0,"z":-2},"blockType":7},{"position":{"x":-9,"y":0,"z":-1},"blockType":6},{"position":{"x":-9,"y":0,"z":0},"blockType":6},{"position":{"x":-9,"y":0,"z":1},"blockType":6},{"position":{"x":5,"y":0,"z":-4},"blockType":6},{"position":{"x":5,"y":0,"z":-3},"blockType":6},{"position":{"x":5,"y":0,"z":-2},"blockType":6},{"position":{"x":5,"y":0,"z":-6},"blockType":7},{"position":{"x":6,"y":0,"z":-6},"blockType":7},{"position":{"x":7,"y":0,"z":-6},"blockType":7},{"position":{"x":8,"y":0,"z":-6},"blockType":7},{"position":{"x":8,"y":0,"z":-5},"blockType":7},{"position":{"x":8,"y":0,"z":-4},"blockType":7},{"position":{"x":8,"y":0,"z":-3},"blockType":7},{"position":{"x":8,"y":0,"z":-2},"blockType":7},{"position":{"x":8,"y":0,"z":-1},"blockType":7},{"position":{"x":8,"y":0,"z":0},"blockType":7},{"position":{"x":8,"y":0,"z":1},"blockType":7},{"position":{"x":8,"y":0,"z":2},"blockType":7},{"position":{"x":8,"y":0,"z":3},"blockType":7},{"position":{"x":8,"y":0,"z":4},"blockType":7},{"position":{"x":8,"y":0,"z":5},"blockType":7},{"position":{"x":7,"y":0,"z":5},"blockType":7},{"position":{"x":6,"y":0,"z":5},"blockType":7},{"position":{"x":5,"y":0,"z":5},"blockType":7},{"position":{"x":4,"y":0,"z":5},"blockType":7},{"position":{"x":4,"y":0,"z":4},"blockType":7},{"position":{"x":3,"y":0,"z":4},"blockType":7},{"position":{"x":2,"y":0,"z":4},"blockType":7},{"position":{"x":-2,"y":0,"z":4},"blockType":9},{"position":{"x":-1,"y":0,"z":4},"blockType":9},{"position":{"x":0,"y":0,"z":4},"blockType":9},{"position":{"x":1,"y":0,"z":4},"blockType":9},{"position":{"x":-3,"y":0,"z":4},"blockType":7},{"position":{"x":1,"y":0,"z":3},"blockType":9},{"position":{"x":-1,"y":0,"z":3},"blockType":9},{"position":{"x":-4,"y":0,"z":4},"blockType":7},{"position":{"x":0,"y":0,"z":3},"blockType":9},{"position":{"x":-2,"y":0,"z":2},"blockType":9},{"position":{"x":-5,"y":0,"z":4},"blockType":7},{"position":{"x":-1,"y":0,"z":2},"blockType":9},{"position":{"x":-2,"y":0,"z":3},"blockType":9},{"position":{"x":0,"y":0,"z":2},"blockType":9},{"position":{"x":1,"y":0,"z":2},"blockType":9},{"position":{"x":-11,"y":-1,"z":-7},"blockType":2},{"position":{"x":-10,"y":-1,"z":-7},"blockType":2},{"position":{"x":-9,"y":-1,"z":-7},"blockType":2},{"position":{"x":-8,"y":-1,"z":-7},"blockType":2},{"position":{"x":-7,"y":-1,"z":-7},"blockType":2},{"position":{"x":-6,"y":-1,"z":-7},"blockType":2},{"position":{"x":-5,"y":-1,"z":-7},"blockType":2},{"position":{"x":-4,"y":-1,"z":-7},"blockType":2},{"position":{"x":-4,"y":-1,"z":-6},"blockType":2},{"position":{"x":-4,"y":-1,"z":-5},"blockType":2},{"position":{"x":-4,"y":-1,"z":-4},"blockType":2},{"position":{"x":-4,"y":-1,"z":-3},"blockType":2},{"position":{"x":-4,"y":-1,"z":-2},"blockType":2},{"position":{"x":-3,"y":-1,"z":-2},"blockType":2},{"position":{"x":-2,"y":-1,"z":-2},"blockType":2},{"position":{"x":-1,"y":-1,"z":-2},"blockType":2},{"position":{"x":0,"y":-1,"z":-2},"blockType":2},{"position":{"x":1,"y":-1,"z":-2},"blockType":2},{"position":{"x":2,"y":-1,"z":-2},"blockType":2},{"position":{"x":3,"y":-1,"z":-2},"blockType":2},{"position":{"x":3,"y":-1,"z":-3},"blockType":2},{"position":{"x":3,"y":-1,"z":-4},"blockType":2},{"position":{"x":3,"y":-1,"z":-5},"blockType":2},{"position":{"x":3,"y":-1,"z":-6},"blockType":2},{"position":{"x":3,"y":-1,"z":-7},"blockType":2},{"position":{"x":4,"y":-1,"z":-7},"blockType":2},{"position":{"x":5,"y":-1,"z":-7},"blockType":2},{"position":{"x":6,"y":-1,"z":-7},"blockType":2},{"position":{"x":7,"y":-1,"z":-7},"blockType":2},{"position":{"x":8,"y":-1,"z":-7},"blockType":2},{"position":{"x":9,"y":-1,"z":-7},"blockType":2},{"position":{"x":-11,"y":-1,"z":-6},"blockType":2},{"position":{"x":-11,"y":-1,"z":-5},"blockType":2},{"position":{"x":-11,"y":-1,"z":-4},"blockType":2},{"position":{"x":-11,"y":-1,"z":-3},"blockType":2},{"position":{"x":-11,"y":-1,"z":-2},"blockType":2},{"position":{"x":-11,"y":-1,"z":-1},"blockType":2},{"position":{"x":-11,"y":-1,"z":0},"blockType":2},{"position":{"x":-11,"y":-1,"z":1},"blockType":2},{"position":{"x":-11,"y":-1,"z":2},"blockType":2},{"position":{"x":-11,"y":-1,"z":3},"blockType":2},{"position":{"x":-11,"y":-1,"z":4},"blockType":2},{"position":{"x":-11,"y":-1,"z":5},"blockType":2},{"position":{"x":-11,"y":-1,"z":6},"blockType":2},{"position":{"x":-10,"y":-1,"z":6},"blockType":2},{"position":{"x":-9,"y":-1,"z":6},"blockType":2},{"position":{"x":-8,"y":-1,"z":6},"blockType":2},{"position":{"x":-7,"y":-1,"z":6},"blockType":2},{"position":{"x":-6,"y":-1,"z":6},"blockType":2},{"position":{"x":-5,"y":-1,"z":6},"blockType":2},{"position":{"x":-4,"y":-1,"z":6},"blockType":2},{"position":{"x":-4,"y":-1,"z":5},"blockType":2},{"position":{"x":-3,"y":-1,"z":5},"blockType":2},{"position":{"x":-2,"y":-1,"z":5},"blockType":2},{"position":{"x":-1,"y":-1,"z":5},"blockType":2},{"position":{"x":0,"y":-1,"z":5},"blockType":2},{"position":{"x":1,"y":-1,"z":5},"blockType":2},{"position":{"x":2,"y":-1,"z":5},"blockType":2},{"position":{"x":3,"y":-1,"z":5},"blockType":2},{"position":{"x":3,"y":-1,"z":6},"blockType":2},{"position":{"x":4,"y":-1,"z":6},"blockType":2},{"position":{"x":5,"y":-1,"z":6},"blockType":2},{"position":{"x":6,"y":-1,"z":6},"blockType":2},{"position":{"x":7,"y":-1,"z":6},"blockType":2},{"position":{"x":8,"y":-1,"z":6},"blockType":2},{"position":{"x":9,"y":-1,"z":6},"blockType":2},{"position":{"x":9,"y":-1,"z":5},"blockType":2},{"position":{"x":9,"y":-1,"z":4},"blockType":2},{"position":{"x":9,"y":-1,"z":3},"blockType":2},{"position":{"x":9,"y":-1,"z":2},"blockType":2},{"position":{"x":9,"y":-1,"z":1},"blockType":2},{"position":{"x":9,"y":-1,"z":0},"blockType":2},{"position":{"x":9,"y":-1,"z":-1},"blockType":2},{"position":{"x":9,"y":-1,"z":-2},"blockType":2},{"position":{"x":9,"y":-1,"z":-3},"blockType":2},{"position":{"x":9,"y":-1,"z":-4},"blockType":2},{"position":{"x":9,"y":-1,"z":-5},"blockType":2},{"position":{"x":9,"y":-1,"z":-6},"blockType":2},{"position":{"x":-2,"y":-1,"z":-3},"blockType":9},{"position":{"x":-1,"y":-1,"z":-3},"blockType":9},{"position":{"x":0,"y":-1,"z":-3},"blockType":9},{"position":{"x":1,"y":-1,"z":-3},"blockType":9},{"position":{"x":-2,"y":-1,"z":-4},"blockType":7},{"position":{"x":1,"y":-1,"z":-4},"blockType":7},{"position":{"x":-1,"y":-1,"z":-4},"blockType":6},{"position":{"x":0,"y":-1,"z":-4},"blockType":6},{"position":{"x":-11,"y":-2,"z":-7},"blockType":2},{"position":{"x":-10,"y":-2,"z":-7},"blockType":2},{"position":{"x":-9,"y":-2,"z":-7},"blockType":2},{"position":{"x":-8,"y":-2,"z":-7},"blockType":2},{"position":{"x":-7,"y":-2,"z":-7},"blockType":2},{"position":{"x":-6,"y":-2,"z":-7},"blockType":2},{"position":{"x":-5,"y":-2,"z":-7},"blockType":2},{"position":{"x":-4,"y":-2,"z":-7},"blockType":2},{"position":{"x":-4,"y":-2,"z":-6},"blockType":2},{"position":{"x":-4,"y":-2,"z":-5},"blockType":2},{"position":{"x":-4,"y":-2,"z":-4},"blockType":2},{"position":{"x":-4,"y":-2,"z":-3},"blockType":2},{"position":{"x":-4,"y":-2,"z":-2},"blockType":2},{"position":{"x":-3,"y":-2,"z":-2},"blockType":2},{"position":{"x":-2,"y":-2,"z":-2},"blockType":2},{"position":{"x":-1,"y":-2,"z":-2},"blockType":2},{"position":{"x":0,"y":-2,"z":-2},"blockType":2},{"position":{"x":1,"y":-2,"z":-2},"blockType":2},{"position":{"x":2,"y":-2,"z":-2},"blockType":2},{"position":{"x":3,"y":-2,"z":-2},"blockType":2},{"position":{"x":3,"y":-2,"z":-3},"blockType":2},{"position":{"x":3,"y":-2,"z":-4},"blockType":2},{"position":{"x":3,"y":-2,"z":-5},"blockType":2},{"position":{"x":3,"y":-2,"z":-6},"blockType":2},{"position":{"x":3,"y":-2,"z":-7},"blockType":2},{"position":{"x":4,"y":-2,"z":-7},"blockType":2},{"position":{"x":5,"y":-2,"z":-7},"blockType":2},{"position":{"x":6,"y":-2,"z":-7},"blockType":2},{"position":{"x":7,"y":-2,"z":-7},"blockType":2},{"position":{"x":8,"y":-2,"z":-7},"blockType":2},{"position":{"x":9,"y":-2,"z":-7},"blockType":2},{"position":{"x":-11,"y":-2,"z":-6},"blockType":2},{"position":{"x":-11,"y":-2,"z":-5},"blockType":2},{"position":{"x":-11,"y":-2,"z":-4},"blockType":2},{"position":{"x":-11,"y":-2,"z":-3},"blockType":2},{"position":{"x":-11,"y":-2,"z":-2},"blockType":2},{"position":{"x":-11,"y":-2,"z":-1},"blockType":2},{"position":{"x":-11,"y":-2,"z":0},"blockType":2},{"position":{"x":-11,"y":-2,"z":1},"blockType":2},{"position":{"x":-11,"y":-2,"z":2},"blockType":2},{"position":{"x":-11,"y":-2,"z":3},"blockType":2},{"position":{"x":-11,"y":-2,"z":4},"blockType":2},{"position":{"x":-11,"y":-2,"z":5},"blockType":2},{"position":{"x":-11,"y":-2,"z":6},"blockType":2},{"position":{"x":-10,"y":-2,"z":6},"blockType":2},{"position":{"x":-9,"y":-2,"z":6},"blockType":2},{"position":{"x":-8,"y":-2,"z":6},"blockType":2},{"position":{"x":-7,"y":-2,"z":6},"blockType":2},{"position":{"x":-6,"y":-2,"z":6},"blockType":2},{"position":{"x":-5,"y":-2,"z":6},"blockType":2},{"position":{"x":-4,"y":-2,"z":6},"blockType":2},{"position":{"x":-4,"y":-2,"z":5},"blockType":2},{"position":{"x":-3,"y":-2,"z":5},"blockType":2},{"position":{"x":-2,"y":-2,"z":5},"blockType":2},{"position":{"x":-1,"y":-2,"z":5},"blockType":2},{"position":{"x":0,"y":-2,"z":5},"blockType":2},{"position":{"x":1,"y":-2,"z":5},"blockType":2},{"position":{"x":2,"y":-2,"z":5},"blockType":2},{"position":{"x":3,"y":-2,"z":5},"blockType":2},{"position":{"x":3,"y":-2,"z":6},"blockType":2},{"position":{"x":4,"y":-2,"z":6},"blockType":2},{"position":{"x":5,"y":-2,"z":6},"blockType":2},{"position":{"x":6,"y":-2,"z":6},"blockType":2},{"position":{"x":7,"y":-2,"z":6},"blockType":2},{"position":{"x":8,"y":-2,"z":6},"blockType":2},{"position":{"x":9,"y":-2,"z":6},"blockType":2},{"position":{"x":9,"y":-2,"z":5},"blockType":2},{"position":{"x":9,"y":-2,"z":4},"blockType":2},{"position":{"x":9,"y":-2,"z":3},"blockType":2},{"position":{"x":9,"y":-2,"z":2},"blockType":2},{"position":{"x":9,"y":-2,"z":1},"blockType":2},{"position":{"x":9,"y":-2,"z":0},"blockType":2},{"position":{"x":9,"y":-2,"z":-1},"blockType":2},{"position":{"x":9,"y":-2,"z":-2},"blockType":2},{"position":{"x":9,"y":-2,"z":-3},"blockType":2},{"position":{"x":9,"y":-2,"z":-4},"blockType":2},{"position":{"x":9,"y":-2,"z":-5},"blockType":2},{"position":{"x":9,"y":-2,"z":-6},"blockType":2},{"position":{"x":-2,"y":-2,"z":-4},"blockType":9},{"position":{"x":-1,"y":-2,"z":-4},"blockType":9},{"position":{"x":0,"y":-2,"z":-4},"blockType":9},{"position":{"x":1,"y":-2,"z":-4},"blockType":9},{"position":{"x":1,"y":-2,"z":-3},"blockType":9},{"position":{"x":-2,"y":-2,"z":-3},"blockType":9},{"position":{"x":-2,"y":-2,"z":-5},"blockType":7},{"position":{"x":1,"y":-2,"z":-5},"blockType":7},{"position":{"x":-1,"y":-2,"z":-5},"blockType":6},{"position":{"x":0,"y":-2,"z":-5},"blockType":6},{"position":{"x":-11,"y":-3,"z":-7},"blockType":2},{"position":{"x":-10,"y":-3,"z":-7},"blockType":2},{"position":{"x":-9,"y":-3,"z":-7},"blockType":2},{"position":{"x":-8,"y":-3,"z":-7},"blockType":2},{"position":{"x":-7,"y":-3,"z":-7},"blockType":2},{"position":{"x":-6,"y":-3,"z":-7},"blockType":2},{"position":{"x":-5,"y":-3,"z":-7},"blockType":2},{"position":{"x":-4,"y":-3,"z":-7},"blockType":2},{"position":{"x":-4,"y":-3,"z":-6},"blockType":2},{"position":{"x":-4,"y":-3,"z":-5},"blockType":2},{"position":{"x":-4,"y":-3,"z":-4},"blockType":2},{"position":{"x":-4,"y":-3,"z":-3},"blockType":2},{"position":{"x":-4,"y":-3,"z":-2},"blockType":2},{"position":{"x":-3,"y":-3,"z":-2},"blockType":2},{"position":{"x":-2,"y":-3,"z":-2},"blockType":2},{"position":{"x":-1,"y":-3,"z":-2},"blockType":2},{"position":{"x":0,"y":-3,"z":-2},"blockType":2},{"position":{"x":1,"y":-3,"z":-2},"blockType":2},{"position":{"x":2,"y":-3,"z":-2},"blockType":2},{"position":{"x":3,"y":-3,"z":-2},"blockType":2},{"position":{"x":3,"y":-3,"z":-3},"blockType":2},{"position":{"x":3,"y":-3,"z":-4},"blockType":2},{"position":{"x":3,"y":-3,"z":-5},"blockType":2},{"position":{"x":3,"y":-3,"z":-6},"blockType":2},{"position":{"x":3,"y":-3,"z":-7},"blockType":2},{"position":{"x":4,"y":-3,"z":-7},"blockType":2},{"position":{"x":5,"y":-3,"z":-7},"blockType":2},{"position":{"x":6,"y":-3,"z":-7},"blockType":2},{"position":{"x":7,"y":-3,"z":-7},"blockType":2},{"position":{"x":8,"y":-3,"z":-7},"blockType":2},{"position":{"x":9,"y":-3,"z":-7},"blockType":2},{"position":{"x":-11,"y":-3,"z":-6},"blockType":2},{"position":{"x":-11,"y":-3,"z":-5},"blockType":2},{"position":{"x":-11,"y":-3,"z":-4},"blockType":2},{"position":{"x":-11,"y":-3,"z":-3},"blockType":2},{"position":{"x":-11,"y":-3,"z":-2},"blockType":2},{"position":{"x":-11,"y":-3,"z":-1},"blockType":2},{"position":{"x":-11,"y":-3,"z":0},"blockType":2},{"position":{"x":-11,"y":-3,"z":1},"blockType":2},{"position":{"x":-11,"y":-3,"z":2},"blockType":2},{"position":{"x":-11,"y":-3,"z":3},"blockType":2},{"position":{"x":-11,"y":-3,"z":4},"blockType":2},{"position":{"x":-11,"y":-3,"z":5},"blockType":2},{"position":{"x":-11,"y":-3,"z":6},"blockType":2},{"position":{"x":-10,"y":-3,"z":6},"blockType":2},{"position":{"x":-9,"y":-3,"z":6},"blockType":2},{"position":{"x":-8,"y":-3,"z":6},"blockType":2},{"position":{"x":-7,"y":-3,"z":6},"blockType":2},{"position":{"x":-6,"y":-3,"z":6},"blockType":2},{"position":{"x":-5,"y":-3,"z":6},"blockType":2},{"position":{"x":-4,"y":-3,"z":6},"blockType":2},{"position":{"x":-4,"y":-3,"z":5},"blockType":2},{"position":{"x":-3,"y":-3,"z":5},"blockType":2},{"position":{"x":-2,"y":-3,"z":5},"blockType":2},{"position":{"x":-1,"y":-3,"z":5},"blockType":2},{"position":{"x":0,"y":-3,"z":5},"blockType":2},{"position":{"x":1,"y":-3,"z":5},"blockType":2},{"position":{"x":2,"y":-3,"z":5},"blockType":2},{"position":{"x":3,"y":-3,"z":5},"blockType":2},{"position":{"x":3,"y":-3,"z":6},"blockType":2},{"position":{"x":4,"y":-3,"z":6},"blockType":2},{"position":{"x":5,"y":-3,"z":6},"blockType":2},{"position":{"x":6,"y":-3,"z":6},"blockType":2},{"position":{"x":7,"y":-3,"z":6},"blockType":2},{"position":{"x":8,"y":-3,"z":6},"blockType":2},{"position":{"x":9,"y":-3,"z":6},"blockType":2},{"position":{"x":9,"y":-3,"z":5},"blockType":2},{"position":{"x":9,"y":-3,"z":4},"blockType":2},{"position":{"x":9,"y":-3,"z":3},"blockType":2},{"position":{"x":9,"y":-3,"z":2},"blockType":2},{"position":{"x":9,"y":-3,"z":1},"blockType":2},{"position":{"x":9,"y":-3,"z":0},"blockType":2},{"position":{"x":9,"y":-3,"z":-1},"blockType":2},{"position":{"x":9,"y":-3,"z":-2},"blockType":2},{"position":{"x":9,"y":-3,"z":-3},"blockType":2},{"position":{"x":9,"y":-3,"z":-4},"blockType":2},{"position":{"x":9,"y":-3,"z":-5},"blockType":2},{"position":{"x":9,"y":-3,"z":-6},"blockType":2},{"position":{"x":-2,"y":-3,"z":-5},"blockType":9},{"position":{"x":-1,"y":-3,"z":-5},"blockType":9},{"position":{"x":0,"y":-3,"z":-5},"blockType":9},{"position":{"x":1,"y":-3,"z":-5},"blockType":9},{"position":{"x":-2,"y":-3,"z":-4},"blockType":9},{"position":{"x":-2,"y":-3,"z":-3},"blockType":9},{"position":{"x":1,"y":-3,"z":-4},"blockType":9},{"position":{"x":1,"y":-3,"z":-3},"blockType":9},{"position":{"x":-2,"y":-3,"z":-6},"blockType":7},{"position":{"x":1,"y":-3,"z":-6},"blockType":7},{"position":{"x":-1,"y":-3,"z":-6},"blockType":6},{"position":{"x":0,"y":-3,"z":-6},"blockType":6},{"position":{"x":-11,"y":-4,"z":-7},"blockType":2},{"position":{"x":-10,"y":-4,"z":-7},"blockType":2},{"position":{"x":-9,"y":-4,"z":-7},"blockType":2},{"position":{"x":-8,"y":-4,"z":-7},"blockType":2},{"position":{"x":-7,"y":-4,"z":-7},"blockType":2},{"position":{"x":-6,"y":-4,"z":-7},"blockType":2},{"position":{"x":-5,"y":-4,"z":-7},"blockType":2},{"position":{"x":-4,"y":-4,"z":-7},"blockType":2},{"position":{"x":-4,"y":-4,"z":-6},"blockType":2},{"position":{"x":-4,"y":-4,"z":-5},"blockType":2},{"position":{"x":-4,"y":-4,"z":-4},"blockType":2},{"position":{"x":-4,"y":-4,"z":-3},"blockType":2},{"position":{"x":-4,"y":-4,"z":-2},"blockType":2},{"position":{"x":-3,"y":-4,"z":-2},"blockType":2},{"position":{"x":-2,"y":-4,"z":-2},"blockType":2},{"position":{"x":-1,"y":-4,"z":-2},"blockType":2},{"position":{"x":0,"y":-4,"z":-2},"blockType":2},{"position":{"x":1,"y":-4,"z":-2},"blockType":2},{"position":{"x":2,"y":-4,"z":-2},"blockType":2},{"position":{"x":3,"y":-4,"z":-2},"blockType":2},{"position":{"x":3,"y":-4,"z":-3},"blockType":2},{"position":{"x":3,"y":-4,"z":-4},"blockType":2},{"position":{"x":3,"y":-4,"z":-5},"blockType":2},{"position":{"x":3,"y":-4,"z":-6},"blockType":2},{"position":{"x":3,"y":-4,"z":-7},"blockType":2},{"position":{"x":4,"y":-4,"z":-7},"blockType":2},{"position":{"x":5,"y":-4,"z":-7},"blockType":2},{"position":{"x":6,"y":-4,"z":-7},"blockType":2},{"position":{"x":7,"y":-4,"z":-7},"blockType":2},{"position":{"x":8,"y":-4,"z":-7},"blockType":2},{"position":{"x":9,"y":-4,"z":-7},"blockType":2},{"position":{"x":-11,"y":-4,"z":-6},"blockType":2},{"position":{"x":-11,"y":-4,"z":-5},"blockType":2},{"position":{"x":-11,"y":-4,"z":-4},"blockType":2},{"position":{"x":-11,"y":-4,"z":-3},"blockType":2},{"position":{"x":-11,"y":-4,"z":-2},"blockType":2},{"position":{"x":-11,"y":-4,"z":-1},"blockType":2},{"position":{"x":-11,"y":-4,"z":0},"blockType":2},{"position":{"x":-11,"y":-4,"z":1},"blockType":2},{"position":{"x":-11,"y":-4,"z":2},"blockType":2},{"position":{"x":-11,"y":-4,"z":3},"blockType":2},{"position":{"x":-11,"y":-4,"z":4},"blockType":2},{"position":{"x":-11,"y":-4,"z":5},"blockType":2},{"position":{"x":-11,"y":-4,"z":6},"blockType":2},{"position":{"x":-10,"y":-4,"z":6},"blockType":2},{"position":{"x":-9,"y":-4,"z":6},"blockType":2},{"position":{"x":-8,"y":-4,"z":6},"blockType":2},{"position":{"x":-7,"y":-4,"z":6},"blockType":2},{"position":{"x":-6,"y":-4,"z":6},"blockType":2},{"position":{"x":-5,"y":-4,"z":6},"blockType":2},{"position":{"x":-4,"y":-4,"z":6},"blockType":2},{"position":{"x":-4,"y":-4,"z":5},"blockType":2},{"position":{"x":-3,"y":-4,"z":5},"blockType":2},{"position":{"x":-2,"y":-4,"z":5},"blockType":2},{"position":{"x":-1,"y":-4,"z":5},"blockType":2},{"position":{"x":0,"y":-4,"z":5},"blockType":2},{"position":{"x":1,"y":-4,"z":5},"blockType":2},{"position":{"x":2,"y":-4,"z":5},"blockType":2},{"position":{"x":3,"y":-4,"z":5},"blockType":2},{"position":{"x":3,"y":-4,"z":6},"blockType":2},{"position":{"x":4,"y":-4,"z":6},"blockType":2},{"position":{"x":5,"y":-4,"z":6},"blockType":2},{"position":{"x":6,"y":-4,"z":6},"blockType":2},{"position":{"x":7,"y":-4,"z":6},"blockType":2},{"position":{"x":8,"y":-4,"z":6},"blockType":2},{"position":{"x":9,"y":-4,"z":6},"blockType":2},{"position":{"x":9,"y":-4,"z":5},"blockType":2},{"position":{"x":9,"y":-4,"z":4},"blockType":2},{"position":{"x":9,"y":-4,"z":3},"blockType":2},{"position":{"x":9,"y":-4,"z":2},"blockType":2},{"position":{"x":9,"y":-4,"z":1},"blockType":2},{"position":{"x":9,"y":-4,"z":0},"blockType":2},{"position":{"x":9,"y":-4,"z":-1},"blockType":2},{"position":{"x":9,"y":-4,"z":-2},"blockType":2},{"position":{"x":9,"y":-4,"z":-3},"blockType":2},{"position":{"x":9,"y":-4,"z":-4},"blockType":2},{"position":{"x":9,"y":-4,"z":-5},"blockType":2},{"position":{"x":9,"y":-4,"z":-6},"blockType":2},{"position":{"x":-2,"y":-4,"z":-6},"blockType":9},{"position":{"x":-1,"y":-4,"z":-6},"blockType":9},{"position":{"x":0,"y":-4,"z":-6},"blockType":9},{"position":{"x":1,"y":-4,"z":-6},"blockType":9},{"position":{"x":-2,"y":-4,"z":-5},"blockType":9},{"position":{"x":-2,"y":-4,"z":-4},"blockType":9},{"position":{"x":-2,"y":-4,"z":-3},"blockType":9},{"position":{"x":1,"y":-4,"z":-5},"blockType":9},{"position":{"x":1,"y":-4,"z":-4},"blockType":9},{"position":{"x":1,"y":-4,"z":-3},"blockType":9},{"position":{"x":-2,"y":-4,"z":-7},"blockType":7},{"position":{"x":1,"y":-4,"z":-7},"blockType":7},{"position":{"x":-1,"y":-4,"z":-7},"blockType":6},{"position":{"x":0,"y":-4,"z":-7},"blockType":6},{"position":{"x":-11,"y":-5,"z":-7},"blockType":2},{"position":{"x":-10,"y":-5,"z":-7},"blockType":2},{"position":{"x":-9,"y":-5,"z":-7},"blockType":2},{"position":{"x":-8,"y":-5,"z":-7},"blockType":2},{"position":{"x":-7,"y":-5,"z":-7},"blockType":2},{"position":{"x":-6,"y":-5,"z":-7},"blockType":2},{"position":{"x":-5,"y":-5,"z":-7},"blockType":2},{"position":{"x":-4,"y":-5,"z":-7},"blockType":2},{"position":{"x":-4,"y":-5,"z":-6},"blockType":2},{"position":{"x":-4,"y":-5,"z":-5},"blockType":2},{"position":{"x":-4,"y":-5,"z":-4},"blockType":2},{"position":{"x":-4,"y":-5,"z":-3},"blockType":2},{"position":{"x":-4,"y":-5,"z":-2},"blockType":2},{"position":{"x":-3,"y":-5,"z":-2},"blockType":2},{"position":{"x":-2,"y":-5,"z":-2},"blockType":2},{"position":{"x":-1,"y":-5,"z":-2},"blockType":2},{"position":{"x":0,"y":-5,"z":-2},"blockType":2},{"position":{"x":1,"y":-5,"z":-2},"blockType":2},{"position":{"x":2,"y":-5,"z":-2},"blockType":2},{"position":{"x":3,"y":-5,"z":-2},"blockType":2},{"position":{"x":3,"y":-5,"z":-3},"blockType":2},{"position":{"x":3,"y":-5,"z":-4},"blockType":2},{"position":{"x":3,"y":-5,"z":-5},"blockType":2},{"position":{"x":3,"y":-5,"z":-6},"blockType":2},{"position":{"x":3,"y":-5,"z":-7},"blockType":2},{"position":{"x":4,"y":-5,"z":-7},"blockType":2},{"position":{"x":5,"y":-5,"z":-7},"blockType":2},{"position":{"x":6,"y":-5,"z":-7},"blockType":2},{"position":{"x":7,"y":-5,"z":-7},"blockType":2},{"position":{"x":8,"y":-5,"z":-7},"blockType":2},{"position":{"x":9,"y":-5,"z":-7},"blockType":2},{"position":{"x":-11,"y":-5,"z":-6},"blockType":2},{"position":{"x":-11,"y":-5,"z":-5},"blockType":2},{"position":{"x":-11,"y":-5,"z":-4},"blockType":2},{"position":{"x":-11,"y":-5,"z":-3},"blockType":2},{"position":{"x":-11,"y":-5,"z":-2},"blockType":2},{"position":{"x":-11,"y":-5,"z":-1},"blockType":2},{"position":{"x":-11,"y":-5,"z":0},"blockType":2},{"position":{"x":-11,"y":-5,"z":1},"blockType":2},{"position":{"x":-11,"y":-5,"z":2},"blockType":2},{"position":{"x":-11,"y":-5,"z":3},"blockType":2},{"position":{"x":-11,"y":-5,"z":4},"blockType":2},{"position":{"x":-11,"y":-5,"z":5},"blockType":2},{"position":{"x":-11,"y":-5,"z":6},"blockType":2},{"position":{"x":-10,"y":-5,"z":6},"blockType":2},{"position":{"x":-9,"y":-5,"z":6},"blockType":2},{"position":{"x":-8,"y":-5,"z":6},"blockType":2},{"position":{"x":-7,"y":-5,"z":6},"blockType":2},{"position":{"x":-6,"y":-5,"z":6},"blockType":2},{"position":{"x":-5,"y":-5,"z":6},"blockType":2},{"position":{"x":-4,"y":-5,"z":6},"blockType":2},{"position":{"x":-4,"y":-5,"z":5},"blockType":2},{"position":{"x":-3,"y":-5,"z":5},"blockType":2},{"position":{"x":-2,"y":-5,"z":5},"blockType":2},{"position":{"x":-1,"y":-5,"z":5},"blockType":2},{"position":{"x":0,"y":-5,"z":5},"blockType":2},{"position":{"x":1,"y":-5,"z":5},"blockType":2},{"position":{"x":2,"y":-5,"z":5},"blockType":2},{"position":{"x":3,"y":-5,"z":5},"blockType":2},{"position":{"x":3,"y":-5,"z":6},"blockType":2},{"position":{"x":4,"y":-5,"z":6},"blockType":2},{"position":{"x":5,"y":-5,"z":6},"blockType":2},{"position":{"x":6,"y":-5,"z":6},"blockType":2},{"position":{"x":7,"y":-5,"z":6},"blockType":2},{"position":{"x":8,"y":-5,"z":6},"blockType":2},{"position":{"x":9,"y":-5,"z":6},"blockType":2},{"position":{"x":9,"y":-5,"z":5},"blockType":2},{"position":{"x":9,"y":-5,"z":4},"blockType":2},{"position":{"x":9,"y":-5,"z":3},"blockType":2},{"position":{"x":9,"y":-5,"z":2},"blockType":2},{"position":{"x":9,"y":-5,"z":1},"blockType":2},{"position":{"x":9,"y":-5,"z":0},"blockType":2},{"position":{"x":9,"y":-5,"z":-1},"blockType":2},{"position":{"x":9,"y":-5,"z":-2},"blockType":2},{"position":{"x":9,"y":-5,"z":-3},"blockType":2},{"position":{"x":9,"y":-5,"z":-4},"blockType":2},{"position":{"x":9,"y":-5,"z":-5},"blockType":2},{"position":{"x":9,"y":-5,"z":-6},"blockType":2},{"position":{"x":-2,"y":-5,"z":-7},"blockType":9},{"position":{"x":-1,"y":-5,"z":-7},"blockType":9},{"position":{"x":0,"y":-5,"z":-7},"blockType":9},{"position":{"x":1,"y":-5,"z":-7},"blockType":9},{"position":{"x":1,"y":-5,"z":-6},"blockType":9},{"position":{"x":1,"y":-5,"z":-5},"blockType":9},{"position":{"x":1,"y":-5,"z":-4},"blockType":9},{"position":{"x":1,"y":-5,"z":-3},"blockType":9},{"position":{"x":-2,"y":-5,"z":-6},"blockType":9},{"position":{"x":-2,"y":-5,"z":-5},"blockType":9},{"position":{"x":-2,"y":-5,"z":-4},"blockType":9},{"position":{"x":-2,"y":-5,"z":-3},"blockType":9},{"position":{"x":-11,"y":1,"z":-7},"blockType":11},{"position":{"x":-10,"y":1,"z":-7},"blockType":11},{"position":{"x":-9,"y":1,"z":-7},"blockType":11},{"position":{"x":-8,"y":1,"z":-7},"blockType":11},{"position":{"x":-7,"y":1,"z":-7},"blockType":11},{"position":{"x":-6,"y":1,"z":-7},"blockType":11},{"position":{"x":-5,"y":1,"z":-7},"blockType":11},{"position":{"x":-4,"y":1,"z":-7},"blockType":11},{"position":{"x":-11,"y":1,"z":-6},"blockType":11},{"position":{"x":-11,"y":1,"z":-5},"blockType":11},{"position":{"x":-11,"y":1,"z":-4},"blockType":11},{"position":{"x":-11,"y":1,"z":-3},"blockType":11},{"position":{"x":-11,"y":1,"z":-2},"blockType":11},{"position":{"x":-11,"y":1,"z":-1},"blockType":11},{"position":{"x":-11,"y":1,"z":0},"blockType":11},{"position":{"x":-11,"y":1,"z":1},"blockType":11},{"position":{"x":-11,"y":1,"z":2},"blockType":11},{"position":{"x":-11,"y":1,"z":3},"blockType":11},{"position":{"x":-11,"y":1,"z":4},"blockType":11},{"position":{"x":-11,"y":1,"z":5},"blockType":11},{"position":{"x":-11,"y":1,"z":6},"blockType":11},{"position":{"x":-10,"y":1,"z":6},"blockType":11},{"position":{"x":-9,"y":1,"z":6},"blockType":11},{"position":{"x":-8,"y":1,"z":6},"blockType":11},{"position":{"x":-7,"y":1,"z":6},"blockType":11},{"position":{"x":-6,"y":1,"z":6},"blockType":11},{"position":{"x":-5,"y":1,"z":6},"blockType":11},{"position":{"x":-4,"y":1,"z":6},"blockType":11},{"position":{"x":-4,"y":1,"z":5},"blockType":11},{"position":{"x":-3,"y":1,"z":5},"blockType":11},{"position":{"x":-2,"y":1,"z":5},"blockType":11},{"position":{"x":-1,"y":1,"z":5},"blockType":11},{"position":{"x":0,"y":1,"z":5},"blockType":11},{"position":{"x":1,"y":1,"z":5},"blockType":11},{"position":{"x":2,"y":1,"z":5},"blockType":11},{"position":{"x":3,"y":1,"z":5},"blockType":11},{"position":{"x":1,"y":1,"z":3},"blockType":9},{"position":{"x":1,"y":1,"z":4},"blockType":9},{"position":{"x":-2,"y":1,"z":4},"blockType":9},{"position":{"x":-2,"y":1,"z":3},"blockType":9},{"position":{"x":-2,"y":1,"z":2},"blockType":9},{"position":{"x":1,"y":1,"z":2},"blockType":9},{"position":{"x":-4,"y":1,"z":-6},"blockType":11},{"position":{"x":-4,"y":1,"z":-5},"blockType":11},{"position":{"x":-4,"y":1,"z":-4},"blockType":11},{"position":{"x":-4,"y":1,"z":-3},"blockType":11},{"position":{"x":-4,"y":1,"z":-2},"blockType":11},{"position":{"x":3,"y":1,"z":-7},"blockType":11},{"position":{"x":3,"y":1,"z":-6},"blockType":11},{"position":{"x":3,"y":1,"z":-5},"blockType":11},{"position":{"x":3,"y":1,"z":-4},"blockType":11},{"position":{"x":9,"y":1,"z":-5},"blockType":11},{"position":{"x":9,"y":1,"z":-4},"blockType":11},{"position":{"x":9,"y":1,"z":-3},"blockType":11},{"position":{"x":9,"y":1,"z":-2},"blockType":11},{"position":{"x":9,"y":1,"z":6},"blockType":11},{"position":{"x":9,"y":1,"z":5},"blockType":11},{"position":{"x":6,"y":1,"z":6},"blockType":11},{"position":{"x":7,"y":1,"z":6},"blockType":11},{"position":{"x":8,"y":1,"z":6},"blockType":11},{"position":{"x":-11,"y":2,"z":-7},"blockType":11},{"position":{"x":-10,"y":2,"z":-7},"blockType":11},{"position":{"x":-9,"y":2,"z":-7},"blockType":11},{"position":{"x":-6,"y":2,"z":-7},"blockType":11},{"position":{"x":-5,"y":2,"z":-7},"blockType":11},{"position":{"x":-4,"y":2,"z":-7},"blockType":11},{"position":{"x":-11,"y":2,"z":-6},"blockType":11},{"position":{"x":-11,"y":2,"z":-5},"blockType":11},{"position":{"x":-11,"y":2,"z":-4},"blockType":11},{"position":{"x":-11,"y":2,"z":-3},"blockType":11},{"position":{"x":-11,"y":2,"z":-2},"blockType":11},{"position":{"x":-11,"y":2,"z":1},"blockType":11},{"position":{"x":-11,"y":2,"z":2},"blockType":11},{"position":{"x":-11,"y":2,"z":3},"blockType":11},{"position":{"x":-11,"y":2,"z":4},"blockType":11},{"position":{"x":-11,"y":2,"z":5},"blockType":11},{"position":{"x":-11,"y":2,"z":6},"blockType":11},{"position":{"x":-10,"y":2,"z":6},"blockType":11},{"position":{"x":-9,"y":2,"z":6},"blockType":11},{"position":{"x":-8,"y":2,"z":6},"blockType":11},{"position":{"x":-7,"y":2,"z":6},"blockType":11},{"position":{"x":-6,"y":2,"z":6},"blockType":11},{"position":{"x":-5,"y":2,"z":6},"blockType":11},{"position":{"x":-4,"y":2,"z":6},"blockType":11},{"position":{"x":-4,"y":2,"z":5},"blockType":11},{"position":{"x":-3,"y":2,"z":5},"blockType":11},{"position":{"x":-2,"y":2,"z":5},"blockType":11},{"position":{"x":-1,"y":2,"z":5},"blockType":11},{"position":{"x":0,"y":2,"z":5},"blockType":11},{"position":{"x":1,"y":2,"z":5},"blockType":11},{"position":{"x":-2,"y":2,"z":4},"blockType":9},{"position":{"x":-2,"y":2,"z":3},"blockType":9},{"position":{"x":1,"y":2,"z":3},"blockType":9},{"position":{"x":1,"y":2,"z":4},"blockType":9},{"position":{"x":1,"y":2,"z":2},"blockType":9},{"position":{"x":-2,"y":2,"z":2},"blockType":9},{"position":{"x":-4,"y":2,"z":-6},"blockType":11},{"position":{"x":-4,"y":2,"z":-5},"blockType":11},{"position":{"x":-4,"y":2,"z":-4},"blockType":11},{"position":{"x":-4,"y":2,"z":-3},"blockType":11},{"position":{"x":3,"y":2,"z":-6},"blockType":11},{"position":{"x":3,"y":2,"z":-5},"blockType":11},{"position":{"x":9,"y":2,"z":-4},"blockType":11},{"position":{"x":9,"y":2,"z":6},"blockType":11},{"position":{"x":8,"y":2,"z":6},"blockType":11},{"position":{"x":-11,"y":3,"z":-7},"blockType":11},{"position":{"x":-10,"y":3,"z":-7},"blockType":11},{"position":{"x":-9,"y":3,"z":-7},"blockType":11},{"position":{"x":-6,"y":3,"z":-7},"blockType":11},{"position":{"x":-5,"y":3,"z":-7},"blockType":11},{"position":{"x":-4,"y":3,"z":-7},"blockType":11},{"position":{"x":-11,"y":3,"z":-6},"blockType":11},{"position":{"x":-11,"y":3,"z":-5},"blockType":11},{"position":{"x":-11,"y":3,"z":-4},"blockType":11},{"position":{"x":-11,"y":3,"z":-3},"blockType":11},{"position":{"x":-11,"y":3,"z":-2},"blockType":11},{"position":{"x":-11,"y":3,"z":1},"blockType":11},{"position":{"x":-11,"y":3,"z":2},"blockType":11},{"position":{"x":-11,"y":3,"z":3},"blockType":11},{"position":{"x":-11,"y":3,"z":4},"blockType":11},{"position":{"x":-11,"y":3,"z":5},"blockType":11},{"position":{"x":-11,"y":3,"z":6},"blockType":11},{"position":{"x":-10,"y":3,"z":6},"blockType":11},{"position":{"x":-9,"y":3,"z":6},"blockType":11},{"position":{"x":-8,"y":3,"z":6},"blockType":11},{"position":{"x":-7,"y":3,"z":6},"blockType":11},{"position":{"x":-6,"y":3,"z":6},"blockType":11},{"position":{"x":-5,"y":3,"z":6},"blockType":11},{"position":{"x":-4,"y":3,"z":6},"blockType":11},{"position":{"x":-4,"y":3,"z":5},"blockType":11},{"position":{"x":-3,"y":3,"z":5},"blockType":11},{"position":{"x":-2,"y":3,"z":5},"blockType":11},{"position":{"x":-1,"y":3,"z":5},"blockType":11},{"position":{"x":0,"y":3,"z":5},"blockType":11},{"position":{"x":1,"y":3,"z":5},"blockType":11},{"position":{"x":2,"y":3,"z":5},"blockType":11},{"position":{"x":1,"y":3,"z":4},"blockType":9},{"position":{"x":1,"y":3,"z":3},"blockType":9},{"position":{"x":-2,"y":3,"z":4},"blockType":9},{"position":{"x":-2,"y":3,"z":3},"blockType":9},{"position":{"x":-4,"y":3,"z":-6},"blockType":11},{"position":{"x":-4,"y":3,"z":-5},"blockType":11},{"position":{"x":9,"y":3,"z":-4},"blockType":11},{"position":{"x":-11,"y":4,"z":-7},"blockType":11},{"position":{"x":-10,"y":4,"z":-7},"blockType":11},{"position":{"x":-9,"y":4,"z":-7},"blockType":11},{"position":{"x":-6,"y":4,"z":-7},"blockType":11},{"position":{"x":-5,"y":4,"z":-7},"blockType":11},{"position":{"x":-4,"y":4,"z":-7},"blockType":11},{"position":{"x":-11,"y":4,"z":-6},"blockType":11},{"position":{"x":-11,"y":4,"z":-5},"blockType":11},{"position":{"x":-11,"y":4,"z":-4},"blockType":11},{"position":{"x":-11,"y":4,"z":-3},"blockType":11},{"position":{"x":-11,"y":4,"z":-2},"blockType":11},{"position":{"x":-11,"y":4,"z":1},"blockType":11},{"position":{"x":-11,"y":4,"z":2},"blockType":11},{"position":{"x":-11,"y":4,"z":3},"blockType":11},{"position":{"x":-11,"y":4,"z":4},"blockType":11},{"position":{"x":-11,"y":4,"z":5},"blockType":11},{"position":{"x":-11,"y":4,"z":6},"blockType":11},{"position":{"x":-10,"y":4,"z":6},"blockType":11},{"position":{"x":-9,"y":4,"z":6},"blockType":11},{"position":{"x":-8,"y":4,"z":6},"blockType":11},{"position":{"x":-7,"y":4,"z":6},"blockType":11},{"position":{"x":-6,"y":4,"z":6},"blockType":11},{"position":{"x":-5,"y":4,"z":6},"blockType":11},{"position":{"x":-4,"y":4,"z":6},"blockType":11},{"position":{"x":-4,"y":4,"z":5},"blockType":11},{"position":{"x":-3,"y":4,"z":5},"blockType":11},{"position":{"x":-2,"y":4,"z":5},"blockType":11},{"position":{"x":-1,"y":4,"z":5},"blockType":11},{"position":{"x":0,"y":4,"z":5},"blockType":11},{"position":{"x":1,"y":4,"z":5},"blockType":11},{"position":{"x":2,"y":4,"z":5},"blockType":11},{"position":{"x":3,"y":4,"z":5},"blockType":11},{"position":{"x":-2,"y":4,"z":3},"blockType":8},{"position":{"x":-1,"y":4,"z":3},"blockType":8},{"position":{"x":0,"y":4,"z":3},"blockType":8},{"position":{"x":1,"y":4,"z":3},"blockType":8},{"position":{"x":-2,"y":4,"z":4},"blockType":8},{"position":{"x":1,"y":4,"z":4},"blockType":8},{"position":{"x":-11,"y":5,"z":-7},"blockType":11},{"position":{"x":-10,"y":5,"z":-7},"blockType":11},{"position":{"x":-9,"y":5,"z":-7},"blockType":11},{"position":{"x":-6,"y":5,"z":-7},"blockType":11},{"position":{"x":-5,"y":5,"z":-7},"blockType":11},{"position":{"x":-4,"y":5,"z":-7},"blockType":11},{"position":{"x":-11,"y":5,"z":-6},"blockType":11},{"position":{"x":-11,"y":5,"z":-5},"blockType":11},{"position":{"x":-11,"y":5,"z":-4},"blockType":11},{"position":{"x":-11,"y":5,"z":-3},"blockType":11},{"position":{"x":-11,"y":5,"z":-2},"blockType":11},{"position":{"x":-11,"y":5,"z":1},"blockType":11},{"position":{"x":-11,"y":5,"z":2},"blockType":11},{"position":{"x":-11,"y":5,"z":3},"blockType":11},{"position":{"x":-11,"y":5,"z":4},"blockType":11},{"position":{"x":-11,"y":5,"z":5},"blockType":11},{"position":{"x":-11,"y":5,"z":6},"blockType":11},{"position":{"x":-10,"y":5,"z":6},"blockType":11},{"position":{"x":-9,"y":5,"z":6},"blockType":11},{"position":{"x":-8,"y":5,"z":6},"blockType":11},{"position":{"x":-7,"y":5,"z":6},"blockType":11},{"position":{"x":-6,"y":5,"z":6},"blockType":11},{"position":{"x":-5,"y":5,"z":6},"blockType":11},{"position":{"x":-4,"y":5,"z":6},"blockType":11},{"position":{"x":-4,"y":5,"z":5},"blockType":11},{"position":{"x":-3,"y":5,"z":5},"blockType":11},{"position":{"x":-2,"y":5,"z":5},"blockType":11},{"position":{"x":-1,"y":5,"z":5},"blockType":11},{"position":{"x":0,"y":5,"z":5},"blockType":11},{"position":{"x":1,"y":5,"z":5},"blockType":11},{"position":{"x":2,"y":5,"z":5},"blockType":11},{"position":{"x":3,"y":5,"z":5},"blockType":11},{"position":{"x":-2,"y":5,"z":4},"blockType":9},{"position":{"x":-1,"y":5,"z":3},"blockType":9},{"position":{"x":0,"y":5,"z":3},"blockType":9},{"position":{"x":1,"y":5,"z":4},"blockType":9},{"position":{"x":-11,"y":5,"z":0},"blockType":11},{"position":{"x":-11,"y":5,"z":-1},"blockType":11},{"position":{"x":-8,"y":5,"z":-7},"blockType":11},{"position":{"x":-7,"y":5,"z":-7},"blockType":11},{"position":{"x":-2,"y":5,"z":3},"blockType":9},{"position":{"x":1,"y":5,"z":3},"blockType":9}]}