{"directory":"/Resources/BlockStructure/","configurationData":{"type":1,"distance":8,"padding":0,"height":-43,"isTwoDirection":true},"blocks":[{"position":{"x":-5,"y":-43,"z":2},"blockType":2},{"position":{"x":-5,"y":-43,"z":1},"blockType":2},{"position":{"x":-5,"y":-43,"z":0},"blockType":2},{"position":{"x":-5,"y":-43,"z":-1},"blockType":2},{"position":{"x":-5,"y":-43,"z":-2},"blockType":2},{"position":{"x":-4,"y":-43,"z":-3},"blockType":2},{"position":{"x":-3,"y":-43,"z":-4},"blockType":2},{"position":{"x":-4,"y":-43,"z":3},"blockType":2},{"position":{"x":-3,"y":-43,"z":4},"blockType":2},{"position":{"x":-2,"y":-43,"z":5},"blockType":2},{"position":{"x":-1,"y":-43,"z":5},"blockType":2},{"position":{"x":0,"y":-43,"z":5},"blockType":2},{"position":{"x":1,"y":-43,"z":5},"blockType":2},{"position":{"x":2,"y":-43,"z":5},"blockType":2},{"position":{"x":3,"y":-43,"z":4},"blockType":2},{"position":{"x":4,"y":-43,"z":3},"blockType":2},{"position":{"x":5,"y":-43,"z":2},"blockType":2},{"position":{"x":5,"y":-43,"z":1},"blockType":2},{"position":{"x":5,"y":-43,"z":0},"blockType":2},{"position":{"x":5,"y":-43,"z":-1},"blockType":2},{"position":{"x":5,"y":-43,"z":-2},"blockType":2},{"position":{"x":4,"y":-43,"z":-3},"blockType":2},{"position":{"x":3,"y":-43,"z":-4},"blockType":2},{"position":{"x":-2,"y":-43,"z":-5},"blockType":2},{"position":{"x":-1,"y":-43,"z":-5},"blockType":2},{"position":{"x":0,"y":-43,"z":-5},"blockType":2},{"position":{"x":1,"y":-43,"z":-5},"blockType":2},{"position":{"x":2,"y":-43,"z":-5},"blockType":2},{"position":{"x":2,"y":-43,"z":6},"blockType":2},{"position":{"x":1,"y":-43,"z":6},"blockType":2},{"position":{"x":0,"y":-43,"z":6},"blockType":2},{"position":{"x":-1,"y":-43,"z":6},"blockType":2},{"position":{"x":-2,"y":-43,"z":6},"blockType":2},{"position":{"x":-6,"y":-43,"z":2},"blockType":2},{"position":{"x":-6,"y":-43,"z":1},"blockType":2},{"position":{"x":-6,"y":-43,"z":0},"blockType":2},{"position":{"x":-6,"y":-43,"z":-1},"blockType":2},{"position":{"x":-6,"y":-43,"z":-2},"blockType":2},{"position":{"x":2,"y":-43,"z":-6},"blockType":2},{"position":{"x":1,"y":-43,"z":-6},"blockType":2},{"position":{"x":0,"y":-43,"z":-6},"blockType":2},{"position":{"x":-1,"y":-43,"z":-6},"blockType":2},{"position":{"x":-2,"y":-43,"z":-6},"blockType":2},{"position":{"x":6,"y":-43,"z":2},"blockType":2},{"position":{"x":6,"y":-43,"z":1},"blockType":2},{"position":{"x":6,"y":-43,"z":0},"blockType":2},{"position":{"x":6,"y":-43,"z":-1},"blockType":2},{"position":{"x":6,"y":-43,"z":-2},"blockType":2},{"position":{"x":7,"y":-43,"z":2},"blockType":2},{"position":{"x":7,"y":-43,"z":1},"blockType":2},{"position":{"x":7,"y":-43,"z":0},"blockType":2},{"position":{"x":7,"y":-43,"z":-1},"blockType":2},{"position":{"x":7,"y":-43,"z":-2},"blockType":2},{"position":{"x":2,"y":-43,"z":-7},"blockType":2},{"position":{"x":1,"y":-43,"z":-7},"blockType":2},{"position":{"x":0,"y":-43,"z":-7},"blockType":2},{"position":{"x":-1,"y":-43,"z":-7},"blockType":2},{"position":{"x":-2,"y":-43,"z":-7},"blockType":2},{"position":{"x":-7,"y":-43,"z":-2},"blockType":2},{"position":{"x":-7,"y":-43,"z":-1},"blockType":2},{"position":{"x":-7,"y":-43,"z":0},"blockType":2},{"position":{"x":-7,"y":-43,"z":1},"blockType":2},{"position":{"x":-7,"y":-43,"z":2},"blockType":2},{"position":{"x":2,"y":-43,"z":7},"blockType":2},{"position":{"x":1,"y":-43,"z":7},"blockType":2},{"position":{"x":0,"y":-43,"z":7},"blockType":2},{"position":{"x":-1,"y":-43,"z":7},"blockType":2},{"position":{"x":-2,"y":-43,"z":7},"blockType":2},{"position":{"x":8,"y":-43,"z":2},"blockType":2},{"position":{"x":8,"y":-43,"z":1},"blockType":2},{"position":{"x":8,"y":-43,"z":0},"blockType":2},{"position":{"x":8,"y":-43,"z":-1},"blockType":2},{"position":{"x":8,"y":-43,"z":-2},"blockType":2},{"position":{"x":2,"y":-43,"z":8},"blockType":2},{"position":{"x":1,"y":-43,"z":8},"blockType":2},{"position":{"x":0,"y":-43,"z":8},"blockType":2},{"position":{"x":-1,"y":-43,"z":8},"blockType":2},{"position":{"x":-2,"y":-43,"z":8},"blockType":2},{"position":{"x":-8,"y":-43,"z":-2},"blockType":2},{"position":{"x":-8,"y":-43,"z":-1},"blockType":2},{"position":{"x":-8,"y":-43,"z":0},"blockType":2},{"position":{"x":-8,"y":-43,"z":1},"blockType":2},{"position":{"x":-8,"y":-43,"z":2},"blockType":2},{"position":{"x":-2,"y":-43,"z":-8},"blockType":2},{"position":{"x":-1,"y":-43,"z":-8},"blockType":2},{"position":{"x":0,"y":-43,"z":-8},"blockType":2},{"position":{"x":1,"y":-43,"z":-8},"blockType":2},{"position":{"x":2,"y":-43,"z":-8},"blockType":2},{"position":{"x":5,"y":-43,"z":-3},"blockType":2},{"position":{"x":4,"y":-43,"z":-4},"blockType":2},{"position":{"x":3,"y":-43,"z":-5},"blockType":2},{"position":{"x":6,"y":-43,"z":-3},"blockType":2},{"position":{"x":5,"y":-43,"z":-4},"blockType":2},{"position":{"x":4,"y":-43,"z":-5},"blockType":2},{"position":{"x":3,"y":-43,"z":-6},"blockType":2},{"position":{"x":7,"y":-43,"z":-3},"blockType":2},{"position":{"x":6,"y":-43,"z":-4},"blockType":2},{"position":{"x":5,"y":-43,"z":-5},"blockType":2},{"position":{"x":4,"y":-43,"z":-6},"blockType":2},{"position":{"x":3,"y":-43,"z":-7},"blockType":2},{"position":{"x":5,"y":-43,"z":3},"blockType":2},{"position":{"x":4,"y":-43,"z":4},"blockType":2},{"position":{"x":3,"y":-43,"z":5},"blockType":2},{"position":{"x":3,"y":-43,"z":6},"blockType":2},{"position":{"x":4,"y":-43,"z":5},"blockType":2},{"position":{"x":5,"y":-43,"z":4},"blockType":2},{"position":{"x":6,"y":-43,"z":3},"blockType":2},{"position":{"x":7,"y":-43,"z":3},"blockType":2},{"position":{"x":6,"y":-43,"z":4},"blockType":2},{"position":{"x":5,"y":-43,"z":5},"blockType":2},{"position":{"x":4,"y":-43,"z":6},"blockType":2},{"position":{"x":3,"y":-43,"z":7},"blockType":2},{"position":{"x":-3,"y":-43,"z":-5},"blockType":2},{"position":{"x":-4,"y":-43,"z":-4},"blockType":2},{"position":{"x":-5,"y":-43,"z":-3},"blockType":2},{"position":{"x":-6,"y":-43,"z":-3},"blockType":2},{"position":{"x":-5,"y":-43,"z":-4},"blockType":2},{"position":{"x":-4,"y":-43,"z":-5},"blockType":2},{"position":{"x":-3,"y":-43,"z":-6},"blockType":2},{"position":{"x":-3,"y":-43,"z":-7},"blockType":2},{"position":{"x":-4,"y":-43,"z":-6},"blockType":2},{"position":{"x":-5,"y":-43,"z":-5},"blockType":2},{"position":{"x":-6,"y":-43,"z":-4},"blockType":2},{"position":{"x":-7,"y":-43,"z":-3},"blockType":2},{"position":{"x":-3,"y":-43,"z":5},"blockType":2},{"position":{"x":-4,"y":-43,"z":4},"blockType":2},{"position":{"x":-5,"y":-43,"z":3},"blockType":2},{"position":{"x":-6,"y":-43,"z":3},"blockType":2},{"position":{"x":-5,"y":-43,"z":4},"blockType":2},{"position":{"x":-4,"y":-43,"z":5},"blockType":2},{"position":{"x":-3,"y":-43,"z":6},"blockType":2},{"position":{"x":-3,"y":-43,"z":7},"blockType":2},{"position":{"x":-4,"y":-43,"z":6},"blockType":2},{"position":{"x":-5,"y":-43,"z":5},"blockType":2},{"position":{"x":-6,"y":-43,"z":4},"blockType":2},{"position":{"x":-7,"y":-43,"z":3},"blockType":2},{"position":{"x":-4,"y":-43,"z":-1},"blockType":6},{"position":{"x":-4,"y":-43,"z":0},"blockType":6},{"position":{"x":-4,"y":-43,"z":1},"blockType":6},{"position":{"x":-3,"y":-43,"z":-1},"blockType":6},{"position":{"x":-3,"y":-43,"z":0},"blockType":6},{"position":{"x":-3,"y":-43,"z":1},"blockType":6},{"position":{"x":-4,"y":-42,"z":-3},"blockType":2},{"position":{"x":-3,"y":-42,"z":-4},"blockType":2},{"position":{"x":-4,"y":-42,"z":3},"blockType":2},{"position":{"x":-3,"y":-42,"z":4},"blockType":2},{"position":{"x":-2,"y":-42,"z":5},"blockType":2},{"position":{"x":-1,"y":-42,"z":5},"blockType":2},{"position":{"x":0,"y":-42,"z":5},"blockType":2},{"position":{"x":1,"y":-42,"z":5},"blockType":2},{"position":{"x":2,"y":-42,"z":5},"blockType":2},{"position":{"x":3,"y":-42,"z":4},"blockType":2},{"position":{"x":4,"y":-42,"z":3},"blockType":2},{"position":{"x":5,"y":-42,"z":2},"blockType":2},{"position":{"x":5,"y":-42,"z":1},"blockType":2},{"position":{"x":5,"y":-42,"z":0},"blockType":2},{"position":{"x":5,"y":-42,"z":-1},"blockType":2},{"position":{"x":5,"y":-42,"z":-2},"blockType":2},{"position":{"x":4,"y":-42,"z":-3},"blockType":2},{"position":{"x":3,"y":-42,"z":-4},"blockType":2},{"position":{"x":-2,"y":-42,"z":-5},"blockType":2},{"position":{"x":-1,"y":-42,"z":-5},"blockType":2},{"position":{"x":0,"y":-42,"z":-5},"blockType":2},{"position":{"x":1,"y":-42,"z":-5},"blockType":2},{"position":{"x":2,"y":-42,"z":-5},"blockType":2},{"position":{"x":2,"y":-42,"z":6},"blockType":2},{"position":{"x":1,"y":-42,"z":6},"blockType":2},{"position":{"x":0,"y":-42,"z":6},"blockType":2},{"position":{"x":-1,"y":-42,"z":6},"blockType":2},{"position":{"x":-2,"y":-42,"z":6},"blockType":2},{"position":{"x":2,"y":-42,"z":-6},"blockType":2},{"position":{"x":1,"y":-42,"z":-6},"blockType":2},{"position":{"x":0,"y":-42,"z":-6},"blockType":2},{"position":{"x":-1,"y":-42,"z":-6},"blockType":2},{"position":{"x":-2,"y":-42,"z":-6},"blockType":2},{"position":{"x":6,"y":-42,"z":2},"blockType":2},{"position":{"x":6,"y":-42,"z":1},"blockType":2},{"position":{"x":6,"y":-42,"z":0},"blockType":2},{"position":{"x":6,"y":-42,"z":-1},"blockType":2},{"position":{"x":6,"y":-42,"z":-2},"blockType":2},{"position":{"x":7,"y":-42,"z":2},"blockType":2},{"position":{"x":7,"y":-42,"z":1},"blockType":2},{"position":{"x":7,"y":-42,"z":0},"blockType":2},{"position":{"x":7,"y":-42,"z":-1},"blockType":2},{"position":{"x":7,"y":-42,"z":-2},"blockType":2},{"position":{"x":2,"y":-42,"z":-7},"blockType":2},{"position":{"x":1,"y":-42,"z":-7},"blockType":2},{"position":{"x":0,"y":-42,"z":-7},"blockType":2},{"position":{"x":-1,"y":-42,"z":-7},"blockType":2},{"position":{"x":-2,"y":-42,"z":-7},"blockType":2},{"position":{"x":2,"y":-42,"z":7},"blockType":2},{"position":{"x":1,"y":-42,"z":7},"blockType":2},{"position":{"x":0,"y":-42,"z":7},"blockType":2},{"position":{"x":-1,"y":-42,"z":7},"blockType":2},{"position":{"x":-2,"y":-42,"z":7},"blockType":2},{"position":{"x":8,"y":-42,"z":2},"blockType":2},{"position":{"x":8,"y":-42,"z":1},"blockType":2},{"position":{"x":8,"y":-42,"z":0},"blockType":2},{"position":{"x":8,"y":-42,"z":-1},"blockType":2},{"position":{"x":8,"y":-42,"z":-2},"blockType":2},{"position":{"x":2,"y":-42,"z":8},"blockType":2},{"position":{"x":1,"y":-42,"z":8},"blockType":2},{"position":{"x":0,"y":-42,"z":8},"blockType":2},{"position":{"x":-1,"y":-42,"z":8},"blockType":2},{"position":{"x":-2,"y":-42,"z":8},"blockType":2},{"position":{"x":-2,"y":-42,"z":-8},"blockType":2},{"position":{"x":-1,"y":-42,"z":-8},"blockType":2},{"position":{"x":0,"y":-42,"z":-8},"blockType":2},{"position":{"x":1,"y":-42,"z":-8},"blockType":2},{"position":{"x":2,"y":-42,"z":-8},"blockType":2},{"position":{"x":5,"y":-42,"z":-3},"blockType":2},{"position":{"x":4,"y":-42,"z":-4},"blockType":2},{"position":{"x":3,"y":-42,"z":-5},"blockType":2},{"position":{"x":6,"y":-42,"z":-3},"blockType":2},{"position":{"x":5,"y":-42,"z":-4},"blockType":2},{"position":{"x":4,"y":-42,"z":-5},"blockType":2},{"position":{"x":3,"y":-42,"z":-6},"blockType":2},{"position":{"x":7,"y":-42,"z":-3},"blockType":2},{"position":{"x":6,"y":-42,"z":-4},"blockType":2},{"position":{"x":5,"y":-42,"z":-5},"blockType":2},{"position":{"x":4,"y":-42,"z":-6},"blockType":2},{"position":{"x":3,"y":-42,"z":-7},"blockType":2},{"position":{"x":5,"y":-42,"z":3},"blockType":2},{"position":{"x":4,"y":-42,"z":4},"blockType":2},{"position":{"x":3,"y":-42,"z":5},"blockType":2},{"position":{"x":3,"y":-42,"z":6},"blockType":2},{"position":{"x":4,"y":-42,"z":5},"blockType":2},{"position":{"x":5,"y":-42,"z":4},"blockType":2},{"position":{"x":6,"y":-42,"z":3},"blockType":2},{"position":{"x":7,"y":-42,"z":3},"blockType":2},{"position":{"x":6,"y":-42,"z":4},"blockType":2},{"position":{"x":5,"y":-42,"z":5},"blockType":2},{"position":{"x":4,"y":-42,"z":6},"blockType":2},{"position":{"x":3,"y":-42,"z":7},"blockType":2},{"position":{"x":-3,"y":-42,"z":-5},"blockType":2},{"position":{"x":-4,"y":-42,"z":-4},"blockType":2},{"position":{"x":-5,"y":-42,"z":-3},"blockType":2},{"position":{"x":-6,"y":-42,"z":-3},"blockType":2},{"position":{"x":-5,"y":-42,"z":-4},"blockType":2},{"position":{"x":-4,"y":-42,"z":-5},"blockType":2},{"position":{"x":-3,"y":-42,"z":-6},"blockType":2},{"position":{"x":-3,"y":-42,"z":-7},"blockType":2},{"position":{"x":-4,"y":-42,"z":-6},"blockType":2},{"position":{"x":-5,"y":-42,"z":-5},"blockType":2},{"position":{"x":-6,"y":-42,"z":-4},"blockType":2},{"position":{"x":-7,"y":-42,"z":-3},"blockType":2},{"position":{"x":-3,"y":-42,"z":5},"blockType":2},{"position":{"x":-4,"y":-42,"z":4},"blockType":2},{"position":{"x":-5,"y":-42,"z":3},"blockType":2},{"position":{"x":-6,"y":-42,"z":3},"blockType":2},{"position":{"x":-5,"y":-42,"z":4},"blockType":2},{"position":{"x":-4,"y":-42,"z":5},"blockType":2},{"position":{"x":-3,"y":-42,"z":6},"blockType":2},{"position":{"x":-3,"y":-42,"z":7},"blockType":2},{"position":{"x":-4,"y":-42,"z":6},"blockType":2},{"position":{"x":-5,"y":-42,"z":5},"blockType":2},{"position":{"x":-6,"y":-42,"z":4},"blockType":2},{"position":{"x":-7,"y":-42,"z":3},"blockType":2},{"position":{"x":-5,"y":-42,"z":-2},"blockType":8},{"position":{"x":-5,"y":-42,"z":2},"blockType":8},{"position":{"x":-8,"y":-42,"z":-2},"blockType":8},{"position":{"x":-8,"y":-42,"z":2},"blockType":8},{"position":{"x":-7,"y":-42,"z":2},"blockType":8},{"position":{"x":-6,"y":-42,"z":2},"blockType":8},{"position":{"x":-6,"y":-42,"z":-2},"blockType":8},{"position":{"x":-7,"y":-42,"z":-2},"blockType":8},{"position":{"x":-3,"y":-42,"z":-2},"blockType":6},{"position":{"x":-4,"y":-42,"z":-2},"blockType":6},{"position":{"x":-4,"y":-41,"z":-3},"blockType":2},{"position":{"x":-3,"y":-41,"z":-4},"blockType":2},{"position":{"x":-4,"y":-41,"z":3},"blockType":2},{"position":{"x":-3,"y":-41,"z":4},"blockType":2},{"position":{"x":-2,"y":-41,"z":5},"blockType":2},{"position":{"x":-1,"y":-41,"z":5},"blockType":2},{"position":{"x":0,"y":-41,"z":5},"blockType":2},{"position":{"x":1,"y":-41,"z":5},"blockType":2},{"position":{"x":2,"y":-41,"z":5},"blockType":2},{"position":{"x":3,"y":-41,"z":4},"blockType":2},{"position":{"x":4,"y":-41,"z":3},"blockType":2},{"position":{"x":5,"y":-41,"z":2},"blockType":2},{"position":{"x":5,"y":-41,"z":1},"blockType":2},{"position":{"x":5,"y":-41,"z":0},"blockType":2},{"position":{"x":5,"y":-41,"z":-1},"blockType":2},{"position":{"x":5,"y":-41,"z":-2},"blockType":2},{"position":{"x":4,"y":-41,"z":-3},"blockType":2},{"position":{"x":3,"y":-41,"z":-4},"blockType":2},{"position":{"x":-2,"y":-41,"z":-5},"blockType":2},{"position":{"x":-1,"y":-41,"z":-5},"blockType":2},{"position":{"x":0,"y":-41,"z":-5},"blockType":2},{"position":{"x":1,"y":-41,"z":-5},"blockType":2},{"position":{"x":2,"y":-41,"z":-5},"blockType":2},{"position":{"x":2,"y":-41,"z":6},"blockType":2},{"position":{"x":1,"y":-41,"z":6},"blockType":2},{"position":{"x":0,"y":-41,"z":6},"blockType":2},{"position":{"x":-1,"y":-41,"z":6},"blockType":2},{"position":{"x":-2,"y":-41,"z":6},"blockType":2},{"position":{"x":2,"y":-41,"z":-6},"blockType":2},{"position":{"x":1,"y":-41,"z":-6},"blockType":2},{"position":{"x":0,"y":-41,"z":-6},"blockType":2},{"position":{"x":-1,"y":-41,"z":-6},"blockType":2},{"position":{"x":-2,"y":-41,"z":-6},"blockType":2},{"position":{"x":6,"y":-41,"z":2},"blockType":2},{"position":{"x":6,"y":-41,"z":1},"blockType":2},{"position":{"x":6,"y":-41,"z":0},"blockType":2},{"position":{"x":6,"y":-41,"z":-1},"blockType":2},{"position":{"x":6,"y":-41,"z":-2},"blockType":2},{"position":{"x":7,"y":-41,"z":2},"blockType":2},{"position":{"x":7,"y":-41,"z":1},"blockType":2},{"position":{"x":7,"y":-41,"z":0},"blockType":2},{"position":{"x":7,"y":-41,"z":-1},"blockType":2},{"position":{"x":7,"y":-41,"z":-2},"blockType":2},{"position":{"x":2,"y":-41,"z":-7},"blockType":2},{"position":{"x":1,"y":-41,"z":-7},"blockType":2},{"position":{"x":0,"y":-41,"z":-7},"blockType":2},{"position":{"x":-1,"y":-41,"z":-7},"blockType":2},{"position":{"x":-2,"y":-41,"z":-7},"blockType":2},{"position":{"x":2,"y":-41,"z":7},"blockType":2},{"position":{"x":1,"y":-41,"z":7},"blockType":2},{"position":{"x":0,"y":-41,"z":7},"blockType":2},{"position":{"x":-1,"y":-41,"z":7},"blockType":2},{"position":{"x":-2,"y":-41,"z":7},"blockType":2},{"position":{"x":8,"y":-41,"z":2},"blockType":2},{"position":{"x":8,"y":-41,"z":1},"blockType":2},{"position":{"x":8,"y":-41,"z":0},"blockType":2},{"position":{"x":8,"y":-41,"z":-1},"blockType":2},{"position":{"x":8,"y":-41,"z":-2},"blockType":2},{"position":{"x":2,"y":-41,"z":8},"blockType":2},{"position":{"x":1,"y":-41,"z":8},"blockType":2},{"position":{"x":0,"y":-41,"z":8},"blockType":2},{"position":{"x":-1,"y":-41,"z":8},"blockType":2},{"position":{"x":-2,"y":-41,"z":8},"blockType":2},{"position":{"x":-2,"y":-41,"z":-8},"blockType":2},{"position":{"x":-1,"y":-41,"z":-8},"blockType":2},{"position":{"x":0,"y":-41,"z":-8},"blockType":2},{"position":{"x":1,"y":-41,"z":-8},"blockType":2},{"position":{"x":2,"y":-41,"z":-8},"blockType":2},{"position":{"x":5,"y":-41,"z":-3},"blockType":2},{"position":{"x":4,"y":-41,"z":-4},"blockType":2},{"position":{"x":3,"y":-41,"z":-5},"blockType":2},{"position":{"x":6,"y":-41,"z":-3},"blockType":2},{"position":{"x":5,"y":-41,"z":-4},"blockType":2},{"position":{"x":4,"y":-41,"z":-5},"blockType":2},{"position":{"x":3,"y":-41,"z":-6},"blockType":2},{"position":{"x":7,"y":-41,"z":-3},"blockType":2},{"position":{"x":6,"y":-41,"z":-4},"blockType":2},{"position":{"x":5,"y":-41,"z":-5},"blockType":2},{"position":{"x":4,"y":-41,"z":-6},"blockType":2},{"position":{"x":3,"y":-41,"z":-7},"blockType":2},{"position":{"x":5,"y":-41,"z":3},"blockType":2},{"position":{"x":4,"y":-41,"z":4},"blockType":2},{"position":{"x":3,"y":-41,"z":5},"blockType":2},{"position":{"x":3,"y":-41,"z":6},"blockType":2},{"position":{"x":4,"y":-41,"z":5},"blockType":2},{"position":{"x":5,"y":-41,"z":4},"blockType":2},{"position":{"x":6,"y":-41,"z":3},"blockType":2},{"position":{"x":7,"y":-41,"z":3},"blockType":2},{"position":{"x":6,"y":-41,"z":4},"blockType":2},{"position":{"x":5,"y":-41,"z":5},"blockType":2},{"position":{"x":4,"y":-41,"z":6},"blockType":2},{"position":{"x":3,"y":-41,"z":7},"blockType":2},{"position":{"x":-3,"y":-41,"z":-5},"blockType":2},{"position":{"x":-4,"y":-41,"z":-4},"blockType":2},{"position":{"x":-5,"y":-41,"z":-3},"blockType":2},{"position":{"x":-6,"y":-41,"z":-3},"blockType":2},{"position":{"x":-5,"y":-41,"z":-4},"blockType":2},{"position":{"x":-4,"y":-41,"z":-5},"blockType":2},{"position":{"x":-3,"y":-41,"z":-6},"blockType":2},{"position":{"x":-3,"y":-41,"z":-7},"blockType":2},{"position":{"x":-4,"y":-41,"z":-6},"blockType":2},{"position":{"x":-5,"y":-41,"z":-5},"blockType":2},{"position":{"x":-6,"y":-41,"z":-4},"blockType":2},{"position":{"x":-7,"y":-41,"z":-3},"blockType":2},{"position":{"x":-3,"y":-41,"z":5},"blockType":2},{"position":{"x":-4,"y":-41,"z":4},"blockType":2},{"position":{"x":-5,"y":-41,"z":3},"blockType":2},{"position":{"x":-6,"y":-41,"z":3},"blockType":2},{"position":{"x":-5,"y":-41,"z":4},"blockType":2},{"position":{"x":-4,"y":-41,"z":5},"blockType":2},{"position":{"x":-3,"y":-41,"z":6},"blockType":2},{"position":{"x":-3,"y":-41,"z":7},"blockType":2},{"position":{"x":-4,"y":-41,"z":6},"blockType":2},{"position":{"x":-5,"y":-41,"z":5},"blockType":2},{"position":{"x":-6,"y":-41,"z":4},"blockType":2},{"position":{"x":-7,"y":-41,"z":3},"blockType":2},{"position":{"x":-5,"y":-41,"z":-2},"blockType":8},{"position":{"x":-8,"y":-41,"z":-2},"blockType":8},{"position":{"x":-8,"y":-41,"z":2},"blockType":8},{"position":{"x":-5,"y":-41,"z":2},"blockType":8},{"position":{"x":-3,"y":-41,"z":-3},"blockType":6},{"position":{"x":-2,"y":-41,"z":-2},"blockType":6},{"position":{"x":-4,"y":-40,"z":-3},"blockType":2},{"position":{"x":-3,"y":-40,"z":-4},"blockType":2},{"position":{"x":-4,"y":-40,"z":3},"blockType":2},{"position":{"x":-3,"y":-40,"z":4},"blockType":2},{"position":{"x":-2,"y":-40,"z":5},"blockType":2},{"position":{"x":-1,"y":-40,"z":5},"blockType":2},{"position":{"x":0,"y":-40,"z":5},"blockType":2},{"position":{"x":1,"y":-40,"z":5},"blockType":2},{"position":{"x":2,"y":-40,"z":5},"blockType":2},{"position":{"x":3,"y":-40,"z":4},"blockType":2},{"position":{"x":4,"y":-40,"z":3},"blockType":2},{"position":{"x":5,"y":-40,"z":2},"blockType":2},{"position":{"x":5,"y":-40,"z":1},"blockType":2},{"position":{"x":5,"y":-40,"z":0},"blockType":2},{"position":{"x":5,"y":-40,"z":-1},"blockType":2},{"position":{"x":5,"y":-40,"z":-2},"blockType":2},{"position":{"x":4,"y":-40,"z":-3},"blockType":2},{"position":{"x":3,"y":-40,"z":-4},"blockType":2},{"position":{"x":-2,"y":-40,"z":-5},"blockType":2},{"position":{"x":-1,"y":-40,"z":-5},"blockType":2},{"position":{"x":0,"y":-40,"z":-5},"blockType":2},{"position":{"x":1,"y":-40,"z":-5},"blockType":2},{"position":{"x":2,"y":-40,"z":-5},"blockType":2},{"position":{"x":2,"y":-40,"z":6},"blockType":2},{"position":{"x":1,"y":-40,"z":6},"blockType":2},{"position":{"x":0,"y":-40,"z":6},"blockType":2},{"position":{"x":-1,"y":-40,"z":6},"blockType":2},{"position":{"x":-2,"y":-40,"z":6},"blockType":2},{"position":{"x":2,"y":-40,"z":-6},"blockType":2},{"position":{"x":1,"y":-40,"z":-6},"blockType":2},{"position":{"x":0,"y":-40,"z":-6},"blockType":2},{"position":{"x":-1,"y":-40,"z":-6},"blockType":2},{"position":{"x":-2,"y":-40,"z":-6},"blockType":2},{"position":{"x":6,"y":-40,"z":2},"blockType":2},{"position":{"x":6,"y":-40,"z":1},"blockType":2},{"position":{"x":6,"y":-40,"z":0},"blockType":2},{"position":{"x":6,"y":-40,"z":-1},"blockType":2},{"position":{"x":6,"y":-40,"z":-2},"blockType":2},{"position":{"x":7,"y":-40,"z":2},"blockType":2},{"position":{"x":7,"y":-40,"z":1},"blockType":2},{"position":{"x":7,"y":-40,"z":0},"blockType":2},{"position":{"x":7,"y":-40,"z":-1},"blockType":2},{"position":{"x":7,"y":-40,"z":-2},"blockType":2},{"position":{"x":2,"y":-40,"z":-7},"blockType":2},{"position":{"x":1,"y":-40,"z":-7},"blockType":2},{"position":{"x":0,"y":-40,"z":-7},"blockType":2},{"position":{"x":-1,"y":-40,"z":-7},"blockType":2},{"position":{"x":-2,"y":-40,"z":-7},"blockType":2},{"position":{"x":2,"y":-40,"z":7},"blockType":2},{"position":{"x":1,"y":-40,"z":7},"blockType":2},{"position":{"x":0,"y":-40,"z":7},"blockType":2},{"position":{"x":-1,"y":-40,"z":7},"blockType":2},{"position":{"x":-2,"y":-40,"z":7},"blockType":2},{"position":{"x":8,"y":-40,"z":2},"blockType":2},{"position":{"x":8,"y":-40,"z":1},"blockType":2},{"position":{"x":8,"y":-40,"z":0},"blockType":2},{"position":{"x":8,"y":-40,"z":-1},"blockType":2},{"position":{"x":8,"y":-40,"z":-2},"blockType":2},{"position":{"x":2,"y":-40,"z":8},"blockType":2},{"position":{"x":1,"y":-40,"z":8},"blockType":2},{"position":{"x":0,"y":-40,"z":8},"blockType":2},{"position":{"x":-1,"y":-40,"z":8},"blockType":2},{"position":{"x":-2,"y":-40,"z":8},"blockType":2},{"position":{"x":-2,"y":-40,"z":-8},"blockType":2},{"position":{"x":-1,"y":-40,"z":-8},"blockType":2},{"position":{"x":0,"y":-40,"z":-8},"blockType":2},{"position":{"x":1,"y":-40,"z":-8},"blockType":2},{"position":{"x":2,"y":-40,"z":-8},"blockType":2},{"position":{"x":5,"y":-40,"z":-3},"blockType":2},{"position":{"x":4,"y":-40,"z":-4},"blockType":2},{"position":{"x":3,"y":-40,"z":-5},"blockType":2},{"position":{"x":6,"y":-40,"z":-3},"blockType":2},{"position":{"x":5,"y":-40,"z":-4},"blockType":2},{"position":{"x":4,"y":-40,"z":-5},"blockType":2},{"position":{"x":3,"y":-40,"z":-6},"blockType":2},{"position":{"x":7,"y":-40,"z":-3},"blockType":2},{"position":{"x":6,"y":-40,"z":-4},"blockType":2},{"position":{"x":5,"y":-40,"z":-5},"blockType":2},{"position":{"x":4,"y":-40,"z":-6},"blockType":2},{"position":{"x":3,"y":-40,"z":-7},"blockType":2},{"position":{"x":5,"y":-40,"z":3},"blockType":2},{"position":{"x":4,"y":-40,"z":4},"blockType":2},{"position":{"x":3,"y":-40,"z":5},"blockType":2},{"position":{"x":3,"y":-40,"z":6},"blockType":2},{"position":{"x":4,"y":-40,"z":5},"blockType":2},{"position":{"x":5,"y":-40,"z":4},"blockType":2},{"position":{"x":6,"y":-40,"z":3},"blockType":2},{"position":{"x":7,"y":-40,"z":3},"blockType":2},{"position":{"x":6,"y":-40,"z":4},"blockType":2},{"position":{"x":5,"y":-40,"z":5},"blockType":2},{"position":{"x":4,"y":-40,"z":6},"blockType":2},{"position":{"x":3,"y":-40,"z":7},"blockType":2},{"position":{"x":-3,"y":-40,"z":-5},"blockType":2},{"position":{"x":-4,"y":-40,"z":-4},"blockType":2},{"position":{"x":-5,"y":-40,"z":-3},"blockType":2},{"position":{"x":-6,"y":-40,"z":-3},"blockType":2},{"position":{"x":-5,"y":-40,"z":-4},"blockType":2},{"position":{"x":-4,"y":-40,"z":-5},"blockType":2},{"position":{"x":-3,"y":-40,"z":-6},"blockType":2},{"position":{"x":-3,"y":-40,"z":-7},"blockType":2},{"position":{"x":-4,"y":-40,"z":-6},"blockType":2},{"position":{"x":-5,"y":-40,"z":-5},"blockType":2},{"position":{"x":-6,"y":-40,"z":-4},"blockType":2},{"position":{"x":-7,"y":-40,"z":-3},"blockType":2},{"position":{"x":-3,"y":-40,"z":5},"blockType":2},{"position":{"x":-4,"y":-40,"z":4},"blockType":2},{"position":{"x":-5,"y":-40,"z":3},"blockType":2},{"position":{"x":-6,"y":-40,"z":3},"blockType":2},{"position":{"x":-5,"y":-40,"z":4},"blockType":2},{"position":{"x":-4,"y":-40,"z":5},"blockType":2},{"position":{"x":-3,"y":-40,"z":6},"blockType":2},{"position":{"x":-3,"y":-40,"z":7},"blockType":2},{"position":{"x":-4,"y":-40,"z":6},"blockType":2},{"position":{"x":-5,"y":-40,"z":5},"blockType":2},{"position":{"x":-6,"y":-40,"z":4},"blockType":2},{"position":{"x":-7,"y":-40,"z":3},"blockType":2},{"position":{"x":-5,"y":-40,"z":-2},"blockType":8},{"position":{"x":-8,"y":-40,"z":-2},"blockType":8},{"position":{"x":-8,"y":-40,"z":2},"blockType":8},{"position":{"x":-5,"y":-40,"z":2},"blockType":8},{"position":{"x":-2,"y":-40,"z":-3},"blockType":6},{"position":{"x":-2,"y":-40,"z":-4},"blockType":6},{"position":{"x":-4,"y":-39,"z":-3},"blockType":2},{"position":{"x":-3,"y":-39,"z":-4},"blockType":2},{"position":{"x":-4,"y":-39,"z":3},"blockType":2},{"position":{"x":-3,"y":-39,"z":4},"blockType":2},{"position":{"x":-2,"y":-39,"z":5},"blockType":2},{"position":{"x":-1,"y":-39,"z":5},"blockType":2},{"position":{"x":0,"y":-39,"z":5},"blockType":2},{"position":{"x":1,"y":-39,"z":5},"blockType":2},{"position":{"x":2,"y":-39,"z":5},"blockType":2},{"position":{"x":3,"y":-39,"z":4},"blockType":2},{"position":{"x":4,"y":-39,"z":3},"blockType":2},{"position":{"x":5,"y":-39,"z":2},"blockType":2},{"position":{"x":5,"y":-39,"z":1},"blockType":2},{"position":{"x":5,"y":-39,"z":0},"blockType":2},{"position":{"x":5,"y":-39,"z":-1},"blockType":2},{"position":{"x":5,"y":-39,"z":-2},"blockType":2},{"position":{"x":4,"y":-39,"z":-3},"blockType":2},{"position":{"x":3,"y":-39,"z":-4},"blockType":2},{"position":{"x":-2,"y":-39,"z":-5},"blockType":2},{"position":{"x":-1,"y":-39,"z":-5},"blockType":2},{"position":{"x":0,"y":-39,"z":-5},"blockType":2},{"position":{"x":1,"y":-39,"z":-5},"blockType":2},{"position":{"x":2,"y":-39,"z":-5},"blockType":2},{"position":{"x":2,"y":-39,"z":6},"blockType":2},{"position":{"x":1,"y":-39,"z":6},"blockType":2},{"position":{"x":0,"y":-39,"z":6},"blockType":2},{"position":{"x":-1,"y":-39,"z":6},"blockType":2},{"position":{"x":-2,"y":-39,"z":6},"blockType":2},{"position":{"x":2,"y":-39,"z":-6},"blockType":2},{"position":{"x":1,"y":-39,"z":-6},"blockType":2},{"position":{"x":0,"y":-39,"z":-6},"blockType":2},{"position":{"x":-1,"y":-39,"z":-6},"blockType":2},{"position":{"x":-2,"y":-39,"z":-6},"blockType":2},{"position":{"x":6,"y":-39,"z":2},"blockType":2},{"position":{"x":6,"y":-39,"z":1},"blockType":2},{"position":{"x":6,"y":-39,"z":0},"blockType":2},{"position":{"x":6,"y":-39,"z":-1},"blockType":2},{"position":{"x":6,"y":-39,"z":-2},"blockType":2},{"position":{"x":7,"y":-39,"z":2},"blockType":2},{"position":{"x":7,"y":-39,"z":1},"blockType":2},{"position":{"x":7,"y":-39,"z":0},"blockType":2},{"position":{"x":7,"y":-39,"z":-1},"blockType":2},{"position":{"x":7,"y":-39,"z":-2},"blockType":2},{"position":{"x":2,"y":-39,"z":-7},"blockType":2},{"position":{"x":1,"y":-39,"z":-7},"blockType":2},{"position":{"x":0,"y":-39,"z":-7},"blockType":2},{"position":{"x":-1,"y":-39,"z":-7},"blockType":2},{"position":{"x":-2,"y":-39,"z":-7},"blockType":2},{"position":{"x":2,"y":-39,"z":7},"blockType":2},{"position":{"x":1,"y":-39,"z":7},"blockType":2},{"position":{"x":0,"y":-39,"z":7},"blockType":2},{"position":{"x":-1,"y":-39,"z":7},"blockType":2},{"position":{"x":-2,"y":-39,"z":7},"blockType":2},{"position":{"x":8,"y":-39,"z":2},"blockType":2},{"position":{"x":8,"y":-39,"z":1},"blockType":2},{"position":{"x":8,"y":-39,"z":0},"blockType":2},{"position":{"x":8,"y":-39,"z":-1},"blockType":2},{"position":{"x":8,"y":-39,"z":-2},"blockType":2},{"position":{"x":2,"y":-39,"z":8},"blockType":2},{"position":{"x":1,"y":-39,"z":8},"blockType":2},{"position":{"x":0,"y":-39,"z":8},"blockType":2},{"position":{"x":-1,"y":-39,"z":8},"blockType":2},{"position":{"x":-2,"y":-39,"z":8},"blockType":2},{"position":{"x":-2,"y":-39,"z":-8},"blockType":2},{"position":{"x":-1,"y":-39,"z":-8},"blockType":2},{"position":{"x":0,"y":-39,"z":-8},"blockType":2},{"position":{"x":1,"y":-39,"z":-8},"blockType":2},{"position":{"x":2,"y":-39,"z":-8},"blockType":2},{"position":{"x":5,"y":-39,"z":-3},"blockType":2},{"position":{"x":4,"y":-39,"z":-4},"blockType":2},{"position":{"x":3,"y":-39,"z":-5},"blockType":2},{"position":{"x":6,"y":-39,"z":-3},"blockType":2},{"position":{"x":5,"y":-39,"z":-4},"blockType":2},{"position":{"x":4,"y":-39,"z":-5},"blockType":2},{"position":{"x":3,"y":-39,"z":-6},"blockType":2},{"position":{"x":7,"y":-39,"z":-3},"blockType":2},{"position":{"x":6,"y":-39,"z":-4},"blockType":2},{"position":{"x":5,"y":-39,"z":-5},"blockType":2},{"position":{"x":4,"y":-39,"z":-6},"blockType":2},{"position":{"x":3,"y":-39,"z":-7},"blockType":2},{"position":{"x":5,"y":-39,"z":3},"blockType":2},{"position":{"x":4,"y":-39,"z":4},"blockType":2},{"position":{"x":3,"y":-39,"z":5},"blockType":2},{"position":{"x":3,"y":-39,"z":6},"blockType":2},{"position":{"x":4,"y":-39,"z":5},"blockType":2},{"position":{"x":5,"y":-39,"z":4},"blockType":2},{"position":{"x":6,"y":-39,"z":3},"blockType":2},{"position":{"x":7,"y":-39,"z":3},"blockType":2},{"position":{"x":6,"y":-39,"z":4},"blockType":2},{"position":{"x":5,"y":-39,"z":5},"blockType":2},{"position":{"x":4,"y":-39,"z":6},"blockType":2},{"position":{"x":3,"y":-39,"z":7},"blockType":2},{"position":{"x":-3,"y":-39,"z":-5},"blockType":2},{"position":{"x":-4,"y":-39,"z":-4},"blockType":2},{"position":{"x":-5,"y":-39,"z":-3},"blockType":2},{"position":{"x":-6,"y":-39,"z":-3},"blockType":2},{"position":{"x":-5,"y":-39,"z":-4},"blockType":2},{"position":{"x":-4,"y":-39,"z":-5},"blockType":2},{"position":{"x":-3,"y":-39,"z":-6},"blockType":2},{"position":{"x":-3,"y":-39,"z":-7},"blockType":2},{"position":{"x":-4,"y":-39,"z":-6},"blockType":2},{"position":{"x":-5,"y":-39,"z":-5},"blockType":2},{"position":{"x":-6,"y":-39,"z":-4},"blockType":2},{"position":{"x":-7,"y":-39,"z":-3},"blockType":2},{"position":{"x":-3,"y":-39,"z":5},"blockType":2},{"position":{"x":-4,"y":-39,"z":4},"blockType":2},{"position":{"x":-5,"y":-39,"z":3},"blockType":2},{"position":{"x":-6,"y":-39,"z":3},"blockType":2},{"position":{"x":-5,"y":-39,"z":4},"blockType":2},{"position":{"x":-4,"y":-39,"z":5},"blockType":2},{"position":{"x":-3,"y":-39,"z":6},"blockType":2},{"position":{"x":-3,"y":-39,"z":7},"blockType":2},{"position":{"x":-4,"y":-39,"z":6},"blockType":2},{"position":{"x":-5,"y":-39,"z":5},"blockType":2},{"position":{"x":-6,"y":-39,"z":4},"blockType":2},{"position":{"x":-7,"y":-39,"z":3},"blockType":2},{"position":{"x":-5,"y":-39,"z":-2},"blockType":8},{"position":{"x":-8,"y":-39,"z":-2},"blockType":8},{"position":{"x":-8,"y":-39,"z":2},"blockType":8},{"position":{"x":-5,"y":-39,"z":2},"blockType":8},{"position":{"x":-1,"y":-39,"z":-3},"blockType":6},{"position":{"x":-1,"y":-39,"z":-4},"blockType":6},{"position":{"x":0,"y":-39,"z":-3},"blockType":6},{"position":{"x":1,"y":-39,"z":-3},"blockType":6},{"position":{"x":0,"y":-39,"z":-4},"blockType":6},{"position":{"x":1,"y":-39,"z":-4},"blockType":6},{"position":{"x":-4,"y":-38,"z":-3},"blockType":2},{"position":{"x":-3,"y":-38,"z":-4},"blockType":2},{"position":{"x":-4,"y":-38,"z":3},"blockType":2},{"position":{"x":-3,"y":-38,"z":4},"blockType":2},{"position":{"x":-2,"y":-38,"z":5},"blockType":2},{"position":{"x":-1,"y":-38,"z":5},"blockType":2},{"position":{"x":0,"y":-38,"z":5},"blockType":2},{"position":{"x":1,"y":-38,"z":5},"blockType":2},{"position":{"x":2,"y":-38,"z":5},"blockType":2},{"position":{"x":3,"y":-38,"z":4},"blockType":2},{"position":{"x":4,"y":-38,"z":3},"blockType":2},{"position":{"x":5,"y":-38,"z":2},"blockType":2},{"position":{"x":5,"y":-38,"z":1},"blockType":2},{"position":{"x":5,"y":-38,"z":0},"blockType":2},{"position":{"x":5,"y":-38,"z":-1},"blockType":2},{"position":{"x":5,"y":-38,"z":-2},"blockType":2},{"position":{"x":4,"y":-38,"z":-3},"blockType":2},{"position":{"x":3,"y":-38,"z":-4},"blockType":2},{"position":{"x":2,"y":-38,"z":6},"blockType":2},{"position":{"x":1,"y":-38,"z":6},"blockType":2},{"position":{"x":0,"y":-38,"z":6},"blockType":2},{"position":{"x":-1,"y":-38,"z":6},"blockType":2},{"position":{"x":-2,"y":-38,"z":6},"blockType":2},{"position":{"x":6,"y":-38,"z":2},"blockType":2},{"position":{"x":6,"y":-38,"z":1},"blockType":2},{"position":{"x":6,"y":-38,"z":0},"blockType":2},{"position":{"x":6,"y":-38,"z":-1},"blockType":2},{"position":{"x":6,"y":-38,"z":-2},"blockType":2},{"position":{"x":7,"y":-38,"z":2},"blockType":2},{"position":{"x":7,"y":-38,"z":1},"blockType":2},{"position":{"x":7,"y":-38,"z":0},"blockType":2},{"position":{"x":7,"y":-38,"z":-1},"blockType":2},{"position":{"x":7,"y":-38,"z":-2},"blockType":2},{"position":{"x":2,"y":-38,"z":7},"blockType":2},{"position":{"x":1,"y":-38,"z":7},"blockType":2},{"position":{"x":0,"y":-38,"z":7},"blockType":2},{"position":{"x":-1,"y":-38,"z":7},"blockType":2},{"position":{"x":-2,"y":-38,"z":7},"blockType":2},{"position":{"x":8,"y":-38,"z":2},"blockType":2},{"position":{"x":8,"y":-38,"z":1},"blockType":2},{"position":{"x":8,"y":-38,"z":0},"blockType":2},{"position":{"x":8,"y":-38,"z":-1},"blockType":2},{"position":{"x":8,"y":-38,"z":-2},"blockType":2},{"position":{"x":2,"y":-38,"z":8},"blockType":2},{"position":{"x":1,"y":-38,"z":8},"blockType":2},{"position":{"x":0,"y":-38,"z":8},"blockType":2},{"position":{"x":-1,"y":-38,"z":8},"blockType":2},{"position":{"x":-2,"y":-38,"z":8},"blockType":2},{"position":{"x":5,"y":-38,"z":-3},"blockType":2},{"position":{"x":4,"y":-38,"z":-4},"blockType":2},{"position":{"x":3,"y":-38,"z":-5},"blockType":2},{"position":{"x":6,"y":-38,"z":-3},"blockType":2},{"position":{"x":5,"y":-38,"z":-4},"blockType":2},{"position":{"x":4,"y":-38,"z":-5},"blockType":2},{"position":{"x":3,"y":-38,"z":-6},"blockType":2},{"position":{"x":7,"y":-38,"z":-3},"blockType":2},{"position":{"x":6,"y":-38,"z":-4},"blockType":2},{"position":{"x":5,"y":-38,"z":-5},"blockType":2},{"position":{"x":4,"y":-38,"z":-6},"blockType":2},{"position":{"x":3,"y":-38,"z":-7},"blockType":2},{"position":{"x":5,"y":-38,"z":3},"blockType":2},{"position":{"x":4,"y":-38,"z":4},"blockType":2},{"position":{"x":3,"y":-38,"z":5},"blockType":2},{"position":{"x":3,"y":-38,"z":6},"blockType":2},{"position":{"x":4,"y":-38,"z":5},"blockType":2},{"position":{"x":5,"y":-38,"z":4},"blockType":2},{"position":{"x":6,"y":-38,"z":3},"blockType":2},{"position":{"x":7,"y":-38,"z":3},"blockType":2},{"position":{"x":6,"y":-38,"z":4},"blockType":2},{"position":{"x":5,"y":-38,"z":5},"blockType":2},{"position":{"x":4,"y":-38,"z":6},"blockType":2},{"position":{"x":3,"y":-38,"z":7},"blockType":2},{"position":{"x":-3,"y":-38,"z":-5},"blockType":2},{"position":{"x":-4,"y":-38,"z":-4},"blockType":2},{"position":{"x":-5,"y":-38,"z":-3},"blockType":2},{"position":{"x":-6,"y":-38,"z":-3},"blockType":2},{"position":{"x":-5,"y":-38,"z":-4},"blockType":2},{"position":{"x":-4,"y":-38,"z":-5},"blockType":2},{"position":{"x":-3,"y":-38,"z":-6},"blockType":2},{"position":{"x":-3,"y":-38,"z":-7},"blockType":2},{"position":{"x":-4,"y":-38,"z":-6},"blockType":2},{"position":{"x":-5,"y":-38,"z":-5},"blockType":2},{"position":{"x":-6,"y":-38,"z":-4},"blockType":2},{"position":{"x":-7,"y":-38,"z":-3},"blockType":2},{"position":{"x":-3,"y":-38,"z":5},"blockType":2},{"position":{"x":-4,"y":-38,"z":4},"blockType":2},{"position":{"x":-5,"y":-38,"z":3},"blockType":2},{"position":{"x":-6,"y":-38,"z":3},"blockType":2},{"position":{"x":-5,"y":-38,"z":4},"blockType":2},{"position":{"x":-4,"y":-38,"z":5},"blockType":2},{"position":{"x":-3,"y":-38,"z":6},"blockType":2},{"position":{"x":-3,"y":-38,"z":7},"blockType":2},{"position":{"x":-4,"y":-38,"z":6},"blockType":2},{"position":{"x":-5,"y":-38,"z":5},"blockType":2},{"position":{"x":-6,"y":-38,"z":4},"blockType":2},{"position":{"x":-7,"y":-38,"z":3},"blockType":2},{"position":{"x":-5,"y":-38,"z":-2},"blockType":8},{"position":{"x":-8,"y":-38,"z":-2},"blockType":8},{"position":{"x":-8,"y":-38,"z":2},"blockType":8},{"position":{"x":-5,"y":-38,"z":2},"blockType":8},{"position":{"x":-5,"y":-38,"z":-1},"blockType":8},{"position":{"x":-5,"y":-38,"z":0},"blockType":8},{"position":{"x":-5,"y":-38,"z":1},"blockType":8},{"position":{"x":-6,"y":-38,"z":-2},"blockType":8},{"position":{"x":-7,"y":-38,"z":-2},"blockType":8},{"position":{"x":-6,"y":-38,"z":2},"blockType":8},{"position":{"x":-7,"y":-38,"z":2},"blockType":8},{"position":{"x":-8,"y":-38,"z":1},"blockType":8},{"position":{"x":-8,"y":-38,"z":0},"blockType":8},{"position":{"x":-8,"y":-38,"z":-1},"blockType":8},{"position":{"x":2,"y":-38,"z":-8},"blockType":8},{"position":{"x":2,"y":-38,"z":-7},"blockType":8},{"position":{"x":2,"y":-38,"z":-6},"blockType":8},{"position":{"x":2,"y":-38,"z":-5},"blockType":8},{"position":{"x":-2,"y":-38,"z":-8},"blockType":8},{"position":{"x":-2,"y":-38,"z":-7},"blockType":8},{"position":{"x":-2,"y":-38,"z":-6},"blockType":8},{"position":{"x":-2,"y":-38,"z":-5},"blockType":8},{"position":{"x":2,"y":-38,"z":-4},"blockType":6},{"position":{"x":2,"y":-38,"z":-3},"blockType":6},{"position":{"x":-5,"y":-37,"z":2},"blockType":2},{"position":{"x":-5,"y":-37,"z":1},"blockType":2},{"position":{"x":-5,"y":-37,"z":0},"blockType":2},{"position":{"x":-5,"y":-37,"z":-1},"blockType":2},{"position":{"x":-5,"y":-37,"z":-2},"blockType":2},{"position":{"x":-4,"y":-37,"z":-3},"blockType":2},{"position":{"x":-3,"y":-37,"z":-4},"blockType":2},{"position":{"x":-4,"y":-37,"z":3},"blockType":2},{"position":{"x":-3,"y":-37,"z":4},"blockType":2},{"position":{"x":-2,"y":-37,"z":5},"blockType":2},{"position":{"x":-1,"y":-37,"z":5},"blockType":2},{"position":{"x":0,"y":-37,"z":5},"blockType":2},{"position":{"x":1,"y":-37,"z":5},"blockType":2},{"position":{"x":2,"y":-37,"z":5},"blockType":2},{"position":{"x":3,"y":-37,"z":4},"blockType":2},{"position":{"x":4,"y":-37,"z":3},"blockType":2},{"position":{"x":5,"y":-37,"z":2},"blockType":2},{"position":{"x":5,"y":-37,"z":1},"blockType":2},{"position":{"x":5,"y":-37,"z":0},"blockType":2},{"position":{"x":5,"y":-37,"z":-1},"blockType":2},{"position":{"x":5,"y":-37,"z":-2},"blockType":2},{"position":{"x":4,"y":-37,"z":-3},"blockType":2},{"position":{"x":3,"y":-37,"z":-4},"blockType":2},{"position":{"x":2,"y":-37,"z":6},"blockType":2},{"position":{"x":1,"y":-37,"z":6},"blockType":2},{"position":{"x":0,"y":-37,"z":6},"blockType":2},{"position":{"x":-1,"y":-37,"z":6},"blockType":2},{"position":{"x":-2,"y":-37,"z":6},"blockType":2},{"position":{"x":-6,"y":-37,"z":2},"blockType":2},{"position":{"x":-6,"y":-37,"z":1},"blockType":2},{"position":{"x":-6,"y":-37,"z":0},"blockType":2},{"position":{"x":-6,"y":-37,"z":-1},"blockType":2},{"position":{"x":-6,"y":-37,"z":-2},"blockType":2},{"position":{"x":6,"y":-37,"z":2},"blockType":2},{"position":{"x":6,"y":-37,"z":1},"blockType":2},{"position":{"x":6,"y":-37,"z":0},"blockType":2},{"position":{"x":6,"y":-37,"z":-1},"blockType":2},{"position":{"x":6,"y":-37,"z":-2},"blockType":2},{"position":{"x":7,"y":-37,"z":2},"blockType":2},{"position":{"x":7,"y":-37,"z":1},"blockType":2},{"position":{"x":7,"y":-37,"z":0},"blockType":2},{"position":{"x":7,"y":-37,"z":-1},"blockType":2},{"position":{"x":7,"y":-37,"z":-2},"blockType":2},{"position":{"x":-7,"y":-37,"z":-2},"blockType":2},{"position":{"x":-7,"y":-37,"z":-1},"blockType":2},{"position":{"x":-7,"y":-37,"z":0},"blockType":2},{"position":{"x":-7,"y":-37,"z":1},"blockType":2},{"position":{"x":-7,"y":-37,"z":2},"blockType":2},{"position":{"x":2,"y":-37,"z":7},"blockType":2},{"position":{"x":1,"y":-37,"z":7},"blockType":2},{"position":{"x":0,"y":-37,"z":7},"blockType":2},{"position":{"x":-1,"y":-37,"z":7},"blockType":2},{"position":{"x":-2,"y":-37,"z":7},"blockType":2},{"position":{"x":8,"y":-37,"z":2},"blockType":2},{"position":{"x":8,"y":-37,"z":1},"blockType":2},{"position":{"x":8,"y":-37,"z":0},"blockType":2},{"position":{"x":8,"y":-37,"z":-1},"blockType":2},{"position":{"x":8,"y":-37,"z":-2},"blockType":2},{"position":{"x":2,"y":-37,"z":8},"blockType":2},{"position":{"x":1,"y":-37,"z":8},"blockType":2},{"position":{"x":0,"y":-37,"z":8},"blockType":2},{"position":{"x":-1,"y":-37,"z":8},"blockType":2},{"position":{"x":-2,"y":-37,"z":8},"blockType":2},{"position":{"x":-8,"y":-37,"z":-2},"blockType":2},{"position":{"x":-8,"y":-37,"z":-1},"blockType":2},{"position":{"x":-8,"y":-37,"z":0},"blockType":2},{"position":{"x":-8,"y":-37,"z":1},"blockType":2},{"position":{"x":-8,"y":-37,"z":2},"blockType":2},{"position":{"x":5,"y":-37,"z":-3},"blockType":2},{"position":{"x":4,"y":-37,"z":-4},"blockType":2},{"position":{"x":3,"y":-37,"z":-5},"blockType":2},{"position":{"x":6,"y":-37,"z":-3},"blockType":2},{"position":{"x":5,"y":-37,"z":-4},"blockType":2},{"position":{"x":4,"y":-37,"z":-5},"blockType":2},{"position":{"x":3,"y":-37,"z":-6},"blockType":2},{"position":{"x":7,"y":-37,"z":-3},"blockType":2},{"position":{"x":6,"y":-37,"z":-4},"blockType":2},{"position":{"x":5,"y":-37,"z":-5},"blockType":2},{"position":{"x":4,"y":-37,"z":-6},"blockType":2},{"position":{"x":3,"y":-37,"z":-7},"blockType":2},{"position":{"x":5,"y":-37,"z":3},"blockType":2},{"position":{"x":4,"y":-37,"z":4},"blockType":2},{"position":{"x":3,"y":-37,"z":5},"blockType":2},{"position":{"x":3,"y":-37,"z":6},"blockType":2},{"position":{"x":4,"y":-37,"z":5},"blockType":2},{"position":{"x":5,"y":-37,"z":4},"blockType":2},{"position":{"x":6,"y":-37,"z":3},"blockType":2},{"position":{"x":7,"y":-37,"z":3},"blockType":2},{"position":{"x":6,"y":-37,"z":4},"blockType":2},{"position":{"x":5,"y":-37,"z":5},"blockType":2},{"position":{"x":4,"y":-37,"z":6},"blockType":2},{"position":{"x":3,"y":-37,"z":7},"blockType":2},{"position":{"x":-3,"y":-37,"z":-5},"blockType":2},{"position":{"x":-4,"y":-37,"z":-4},"blockType":2},{"position":{"x":-5,"y":-37,"z":-3},"blockType":2},{"position":{"x":-6,"y":-37,"z":-3},"blockType":2},{"position":{"x":-5,"y":-37,"z":-4},"blockType":2},{"position":{"x":-4,"y":-37,"z":-5},"blockType":2},{"position":{"x":-3,"y":-37,"z":-6},"blockType":2},{"position":{"x":-3,"y":-37,"z":-7},"blockType":2},{"position":{"x":-4,"y":-37,"z":-6},"blockType":2},{"position":{"x":-5,"y":-37,"z":-5},"blockType":2},{"position":{"x":-6,"y":-37,"z":-4},"blockType":2},{"position":{"x":-7,"y":-37,"z":-3},"blockType":2},{"position":{"x":-3,"y":-37,"z":5},"blockType":2},{"position":{"x":-4,"y":-37,"z":4},"blockType":2},{"position":{"x":-5,"y":-37,"z":3},"blockType":2},{"position":{"x":-6,"y":-37,"z":3},"blockType":2},{"position":{"x":-5,"y":-37,"z":4},"blockType":2},{"position":{"x":-4,"y":-37,"z":5},"blockType":2},{"position":{"x":-3,"y":-37,"z":6},"blockType":2},{"position":{"x":-3,"y":-37,"z":7},"blockType":2},{"position":{"x":-4,"y":-37,"z":6},"blockType":2},{"position":{"x":-5,"y":-37,"z":5},"blockType":2},{"position":{"x":-6,"y":-37,"z":4},"blockType":2},{"position":{"x":-7,"y":-37,"z":3},"blockType":2},{"position":{"x":2,"y":-37,"z":-5},"blockType":8},{"position":{"x":2,"y":-37,"z":-8},"blockType":8},{"position":{"x":-2,"y":-37,"z":-8},"blockType":8},{"position":{"x":-2,"y":-37,"z":-5},"blockType":8},{"position":{"x":3,"y":-37,"z":-3},"blockType":6},{"position":{"x":2,"y":-37,"z":-2},"blockType":6},{"position":{"x":-5,"y":-36,"z":2},"blockType":2},{"position":{"x":-5,"y":-36,"z":1},"blockType":2},{"position":{"x":-5,"y":-36,"z":0},"blockType":2},{"position":{"x":-5,"y":-36,"z":-1},"blockType":2},{"position":{"x":-5,"y":-36,"z":-2},"blockType":2},{"position":{"x":-4,"y":-36,"z":-3},"blockType":2},{"position":{"x":-3,"y":-36,"z":-4},"blockType":2},{"position":{"x":-4,"y":-36,"z":3},"blockType":2},{"position":{"x":-3,"y":-36,"z":4},"blockType":2},{"position":{"x":-2,"y":-36,"z":5},"blockType":2},{"position":{"x":-1,"y":-36,"z":5},"blockType":2},{"position":{"x":0,"y":-36,"z":5},"blockType":2},{"position":{"x":1,"y":-36,"z":5},"blockType":2},{"position":{"x":2,"y":-36,"z":5},"blockType":2},{"position":{"x":3,"y":-36,"z":4},"blockType":2},{"position":{"x":4,"y":-36,"z":3},"blockType":2},{"position":{"x":5,"y":-36,"z":2},"blockType":2},{"position":{"x":5,"y":-36,"z":1},"blockType":2},{"position":{"x":5,"y":-36,"z":0},"blockType":2},{"position":{"x":5,"y":-36,"z":-1},"blockType":2},{"position":{"x":5,"y":-36,"z":-2},"blockType":2},{"position":{"x":4,"y":-36,"z":-3},"blockType":2},{"position":{"x":3,"y":-36,"z":-4},"blockType":2},{"position":{"x":2,"y":-36,"z":6},"blockType":2},{"position":{"x":1,"y":-36,"z":6},"blockType":2},{"position":{"x":0,"y":-36,"z":6},"blockType":2},{"position":{"x":-1,"y":-36,"z":6},"blockType":2},{"position":{"x":-2,"y":-36,"z":6},"blockType":2},{"position":{"x":-6,"y":-36,"z":2},"blockType":2},{"position":{"x":-6,"y":-36,"z":1},"blockType":2},{"position":{"x":-6,"y":-36,"z":0},"blockType":2},{"position":{"x":-6,"y":-36,"z":-1},"blockType":2},{"position":{"x":-6,"y":-36,"z":-2},"blockType":2},{"position":{"x":6,"y":-36,"z":2},"blockType":2},{"position":{"x":6,"y":-36,"z":1},"blockType":2},{"position":{"x":6,"y":-36,"z":0},"blockType":2},{"position":{"x":6,"y":-36,"z":-1},"blockType":2},{"position":{"x":6,"y":-36,"z":-2},"blockType":2},{"position":{"x":7,"y":-36,"z":2},"blockType":2},{"position":{"x":7,"y":-36,"z":1},"blockType":2},{"position":{"x":7,"y":-36,"z":0},"blockType":2},{"position":{"x":7,"y":-36,"z":-1},"blockType":2},{"position":{"x":7,"y":-36,"z":-2},"blockType":2},{"position":{"x":-7,"y":-36,"z":-2},"blockType":2},{"position":{"x":-7,"y":-36,"z":-1},"blockType":2},{"position":{"x":-7,"y":-36,"z":0},"blockType":2},{"position":{"x":-7,"y":-36,"z":1},"blockType":2},{"position":{"x":-7,"y":-36,"z":2},"blockType":2},{"position":{"x":2,"y":-36,"z":7},"blockType":2},{"position":{"x":1,"y":-36,"z":7},"blockType":2},{"position":{"x":0,"y":-36,"z":7},"blockType":2},{"position":{"x":-1,"y":-36,"z":7},"blockType":2},{"position":{"x":-2,"y":-36,"z":7},"blockType":2},{"position":{"x":8,"y":-36,"z":2},"blockType":2},{"position":{"x":8,"y":-36,"z":1},"blockType":2},{"position":{"x":8,"y":-36,"z":0},"blockType":2},{"position":{"x":8,"y":-36,"z":-1},"blockType":2},{"position":{"x":8,"y":-36,"z":-2},"blockType":2},{"position":{"x":2,"y":-36,"z":8},"blockType":2},{"position":{"x":1,"y":-36,"z":8},"blockType":2},{"position":{"x":0,"y":-36,"z":8},"blockType":2},{"position":{"x":-1,"y":-36,"z":8},"blockType":2},{"position":{"x":-2,"y":-36,"z":8},"blockType":2},{"position":{"x":-8,"y":-36,"z":-2},"blockType":2},{"position":{"x":-8,"y":-36,"z":-1},"blockType":2},{"position":{"x":-8,"y":-36,"z":0},"blockType":2},{"position":{"x":-8,"y":-36,"z":1},"blockType":2},{"position":{"x":-8,"y":-36,"z":2},"blockType":2},{"position":{"x":5,"y":-36,"z":-3},"blockType":2},{"position":{"x":4,"y":-36,"z":-4},"blockType":2},{"position":{"x":3,"y":-36,"z":-5},"blockType":2},{"position":{"x":6,"y":-36,"z":-3},"blockType":2},{"position":{"x":5,"y":-36,"z":-4},"blockType":2},{"position":{"x":4,"y":-36,"z":-5},"blockType":2},{"position":{"x":3,"y":-36,"z":-6},"blockType":2},{"position":{"x":7,"y":-36,"z":-3},"blockType":2},{"position":{"x":6,"y":-36,"z":-4},"blockType":2},{"position":{"x":5,"y":-36,"z":-5},"blockType":2},{"position":{"x":4,"y":-36,"z":-6},"blockType":2},{"position":{"x":3,"y":-36,"z":-7},"blockType":2},{"position":{"x":5,"y":-36,"z":3},"blockType":2},{"position":{"x":4,"y":-36,"z":4},"blockType":2},{"position":{"x":3,"y":-36,"z":5},"blockType":2},{"position":{"x":3,"y":-36,"z":6},"blockType":2},{"position":{"x":4,"y":-36,"z":5},"blockType":2},{"position":{"x":5,"y":-36,"z":4},"blockType":2},{"position":{"x":6,"y":-36,"z":3},"blockType":2},{"position":{"x":7,"y":-36,"z":3},"blockType":2},{"position":{"x":6,"y":-36,"z":4},"blockType":2},{"position":{"x":5,"y":-36,"z":5},"blockType":2},{"position":{"x":4,"y":-36,"z":6},"blockType":2},{"position":{"x":3,"y":-36,"z":7},"blockType":2},{"position":{"x":-3,"y":-36,"z":-5},"blockType":2},{"position":{"x":-4,"y":-36,"z":-4},"blockType":2},{"position":{"x":-5,"y":-36,"z":-3},"blockType":2},{"position":{"x":-6,"y":-36,"z":-3},"blockType":2},{"position":{"x":-5,"y":-36,"z":-4},"blockType":2},{"position":{"x":-4,"y":-36,"z":-5},"blockType":2},{"position":{"x":-3,"y":-36,"z":-6},"blockType":2},{"position":{"x":-3,"y":-36,"z":-7},"blockType":2},{"position":{"x":-4,"y":-36,"z":-6},"blockType":2},{"position":{"x":-5,"y":-36,"z":-5},"blockType":2},{"position":{"x":-6,"y":-36,"z":-4},"blockType":2},{"position":{"x":-7,"y":-36,"z":-3},"blockType":2},{"position":{"x":-3,"y":-36,"z":5},"blockType":2},{"position":{"x":-4,"y":-36,"z":4},"blockType":2},{"position":{"x":-5,"y":-36,"z":3},"blockType":2},{"position":{"x":-6,"y":-36,"z":3},"blockType":2},{"position":{"x":-5,"y":-36,"z":4},"blockType":2},{"position":{"x":-4,"y":-36,"z":5},"blockType":2},{"position":{"x":-3,"y":-36,"z":6},"blockType":2},{"position":{"x":-3,"y":-36,"z":7},"blockType":2},{"position":{"x":-4,"y":-36,"z":6},"blockType":2},{"position":{"x":-5,"y":-36,"z":5},"blockType":2},{"position":{"x":-6,"y":-36,"z":4},"blockType":2},{"position":{"x":-7,"y":-36,"z":3},"blockType":2},{"position":{"x":2,"y":-36,"z":-5},"blockType":8},{"position":{"x":2,"y":-36,"z":-8},"blockType":8},{"position":{"x":-2,"y":-36,"z":-8},"blockType":8},{"position":{"x":-2,"y":-36,"z":-5},"blockType":8},{"position":{"x":3,"y":-36,"z":-2},"blockType":6},{"position":{"x":4,"y":-36,"z":-2},"blockType":6},{"position":{"x":-5,"y":-35,"z":2},"blockType":2},{"position":{"x":-5,"y":-35,"z":1},"blockType":2},{"position":{"x":-5,"y":-35,"z":0},"blockType":2},{"position":{"x":-5,"y":-35,"z":-1},"blockType":2},{"position":{"x":-5,"y":-35,"z":-2},"blockType":2},{"position":{"x":-4,"y":-35,"z":-3},"blockType":2},{"position":{"x":-3,"y":-35,"z":-4},"blockType":2},{"position":{"x":-4,"y":-35,"z":3},"blockType":2},{"position":{"x":-3,"y":-35,"z":4},"blockType":2},{"position":{"x":-2,"y":-35,"z":5},"blockType":2},{"position":{"x":-1,"y":-35,"z":5},"blockType":2},{"position":{"x":0,"y":-35,"z":5},"blockType":2},{"position":{"x":1,"y":-35,"z":5},"blockType":2},{"position":{"x":2,"y":-35,"z":5},"blockType":2},{"position":{"x":3,"y":-35,"z":4},"blockType":2},{"position":{"x":4,"y":-35,"z":3},"blockType":2},{"position":{"x":5,"y":-35,"z":2},"blockType":2},{"position":{"x":5,"y":-35,"z":1},"blockType":2},{"position":{"x":5,"y":-35,"z":0},"blockType":2},{"position":{"x":5,"y":-35,"z":-1},"blockType":2},{"position":{"x":5,"y":-35,"z":-2},"blockType":2},{"position":{"x":4,"y":-35,"z":-3},"blockType":2},{"position":{"x":3,"y":-35,"z":-4},"blockType":2},{"position":{"x":2,"y":-35,"z":6},"blockType":2},{"position":{"x":1,"y":-35,"z":6},"blockType":2},{"position":{"x":0,"y":-35,"z":6},"blockType":2},{"position":{"x":-1,"y":-35,"z":6},"blockType":2},{"position":{"x":-2,"y":-35,"z":6},"blockType":2},{"position":{"x":-6,"y":-35,"z":2},"blockType":2},{"position":{"x":-6,"y":-35,"z":1},"blockType":2},{"position":{"x":-6,"y":-35,"z":0},"blockType":2},{"position":{"x":-6,"y":-35,"z":-1},"blockType":2},{"position":{"x":-6,"y":-35,"z":-2},"blockType":2},{"position":{"x":6,"y":-35,"z":2},"blockType":2},{"position":{"x":6,"y":-35,"z":1},"blockType":2},{"position":{"x":6,"y":-35,"z":0},"blockType":2},{"position":{"x":6,"y":-35,"z":-1},"blockType":2},{"position":{"x":6,"y":-35,"z":-2},"blockType":2},{"position":{"x":7,"y":-35,"z":2},"blockType":2},{"position":{"x":7,"y":-35,"z":1},"blockType":2},{"position":{"x":7,"y":-35,"z":0},"blockType":2},{"position":{"x":7,"y":-35,"z":-1},"blockType":2},{"position":{"x":7,"y":-35,"z":-2},"blockType":2},{"position":{"x":-7,"y":-35,"z":-2},"blockType":2},{"position":{"x":-7,"y":-35,"z":-1},"blockType":2},{"position":{"x":-7,"y":-35,"z":0},"blockType":2},{"position":{"x":-7,"y":-35,"z":1},"blockType":2},{"position":{"x":-7,"y":-35,"z":2},"blockType":2},{"position":{"x":2,"y":-35,"z":7},"blockType":2},{"position":{"x":1,"y":-35,"z":7},"blockType":2},{"position":{"x":0,"y":-35,"z":7},"blockType":2},{"position":{"x":-1,"y":-35,"z":7},"blockType":2},{"position":{"x":-2,"y":-35,"z":7},"blockType":2},{"position":{"x":8,"y":-35,"z":2},"blockType":2},{"position":{"x":8,"y":-35,"z":1},"blockType":2},{"position":{"x":8,"y":-35,"z":0},"blockType":2},{"position":{"x":8,"y":-35,"z":-1},"blockType":2},{"position":{"x":8,"y":-35,"z":-2},"blockType":2},{"position":{"x":2,"y":-35,"z":8},"blockType":2},{"position":{"x":1,"y":-35,"z":8},"blockType":2},{"position":{"x":0,"y":-35,"z":8},"blockType":2},{"position":{"x":-1,"y":-35,"z":8},"blockType":2},{"position":{"x":-2,"y":-35,"z":8},"blockType":2},{"position":{"x":-8,"y":-35,"z":-2},"blockType":2},{"position":{"x":-8,"y":-35,"z":-1},"blockType":2},{"position":{"x":-8,"y":-35,"z":0},"blockType":2},{"position":{"x":-8,"y":-35,"z":1},"blockType":2},{"position":{"x":-8,"y":-35,"z":2},"blockType":2},{"position":{"x":5,"y":-35,"z":-3},"blockType":2},{"position":{"x":4,"y":-35,"z":-4},"blockType":2},{"position":{"x":3,"y":-35,"z":-5},"blockType":2},{"position":{"x":6,"y":-35,"z":-3},"blockType":2},{"position":{"x":5,"y":-35,"z":-4},"blockType":2},{"position":{"x":4,"y":-35,"z":-5},"blockType":2},{"position":{"x":3,"y":-35,"z":-6},"blockType":2},{"position":{"x":7,"y":-35,"z":-3},"blockType":2},{"position":{"x":6,"y":-35,"z":-4},"blockType":2},{"position":{"x":5,"y":-35,"z":-5},"blockType":2},{"position":{"x":4,"y":-35,"z":-6},"blockType":2},{"position":{"x":3,"y":-35,"z":-7},"blockType":2},{"position":{"x":5,"y":-35,"z":3},"blockType":2},{"position":{"x":4,"y":-35,"z":4},"blockType":2},{"position":{"x":3,"y":-35,"z":5},"blockType":2},{"position":{"x":3,"y":-35,"z":6},"blockType":2},{"position":{"x":4,"y":-35,"z":5},"blockType":2},{"position":{"x":5,"y":-35,"z":4},"blockType":2},{"position":{"x":6,"y":-35,"z":3},"blockType":2},{"position":{"x":7,"y":-35,"z":3},"blockType":2},{"position":{"x":6,"y":-35,"z":4},"blockType":2},{"position":{"x":5,"y":-35,"z":5},"blockType":2},{"position":{"x":4,"y":-35,"z":6},"blockType":2},{"position":{"x":3,"y":-35,"z":7},"blockType":2},{"position":{"x":-3,"y":-35,"z":-5},"blockType":2},{"position":{"x":-4,"y":-35,"z":-4},"blockType":2},{"position":{"x":-5,"y":-35,"z":-3},"blockType":2},{"position":{"x":-6,"y":-35,"z":-3},"blockType":2},{"position":{"x":-5,"y":-35,"z":-4},"blockType":2},{"position":{"x":-4,"y":-35,"z":-5},"blockType":2},{"position":{"x":-3,"y":-35,"z":-6},"blockType":2},{"position":{"x":-3,"y":-35,"z":-7},"blockType":2},{"position":{"x":-4,"y":-35,"z":-6},"blockType":2},{"position":{"x":-5,"y":-35,"z":-5},"blockType":2},{"position":{"x":-6,"y":-35,"z":-4},"blockType":2},{"position":{"x":-7,"y":-35,"z":-3},"blockType":2},{"position":{"x":-3,"y":-35,"z":5},"blockType":2},{"position":{"x":-4,"y":-35,"z":4},"blockType":2},{"position":{"x":-5,"y":-35,"z":3},"blockType":2},{"position":{"x":-6,"y":-35,"z":3},"blockType":2},{"position":{"x":-5,"y":-35,"z":4},"blockType":2},{"position":{"x":-4,"y":-35,"z":5},"blockType":2},{"position":{"x":-3,"y":-35,"z":6},"blockType":2},{"position":{"x":-3,"y":-35,"z":7},"blockType":2},{"position":{"x":-4,"y":-35,"z":6},"blockType":2},{"position":{"x":-5,"y":-35,"z":5},"blockType":2},{"position":{"x":-6,"y":-35,"z":4},"blockType":2},{"position":{"x":-7,"y":-35,"z":3},"blockType":2},{"position":{"x":2,"y":-35,"z":-5},"blockType":8},{"position":{"x":2,"y":-35,"z":-8},"blockType":8},{"position":{"x":-2,"y":-35,"z":-8},"blockType":8},{"position":{"x":-2,"y":-35,"z":-5},"blockType":8},{"position":{"x":3,"y":-35,"z":-1},"blockType":6},{"position":{"x":4,"y":-35,"z":-1},"blockType":6},{"position":{"x":3,"y":-35,"z":0},"blockType":6},{"position":{"x":4,"y":-35,"z":0},"blockType":6},{"position":{"x":3,"y":-35,"z":1},"blockType":6},{"position":{"x":4,"y":-35,"z":1},"blockType":6},{"position":{"x":-5,"y":-34,"z":2},"blockType":2},{"position":{"x":-5,"y":-34,"z":1},"blockType":2},{"position":{"x":-5,"y":-34,"z":0},"blockType":2},{"position":{"x":-5,"y":-34,"z":-1},"blockType":2},{"position":{"x":-5,"y":-34,"z":-2},"blockType":2},{"position":{"x":-4,"y":-34,"z":-3},"blockType":2},{"position":{"x":-3,"y":-34,"z":-4},"blockType":2},{"position":{"x":-4,"y":-34,"z":3},"blockType":2},{"position":{"x":-3,"y":-34,"z":4},"blockType":2},{"position":{"x":-2,"y":-34,"z":5},"blockType":2},{"position":{"x":-1,"y":-34,"z":5},"blockType":2},{"position":{"x":0,"y":-34,"z":5},"blockType":2},{"position":{"x":1,"y":-34,"z":5},"blockType":2},{"position":{"x":2,"y":-34,"z":5},"blockType":2},{"position":{"x":3,"y":-34,"z":4},"blockType":2},{"position":{"x":4,"y":-34,"z":3},"blockType":2},{"position":{"x":4,"y":-34,"z":-3},"blockType":2},{"position":{"x":3,"y":-34,"z":-4},"blockType":2},{"position":{"x":2,"y":-34,"z":6},"blockType":2},{"position":{"x":1,"y":-34,"z":6},"blockType":2},{"position":{"x":0,"y":-34,"z":6},"blockType":2},{"position":{"x":-1,"y":-34,"z":6},"blockType":2},{"position":{"x":-2,"y":-34,"z":6},"blockType":2},{"position":{"x":-6,"y":-34,"z":2},"blockType":2},{"position":{"x":-6,"y":-34,"z":1},"blockType":2},{"position":{"x":-6,"y":-34,"z":0},"blockType":2},{"position":{"x":-6,"y":-34,"z":-1},"blockType":2},{"position":{"x":-6,"y":-34,"z":-2},"blockType":2},{"position":{"x":-7,"y":-34,"z":-2},"blockType":2},{"position":{"x":-7,"y":-34,"z":-1},"blockType":2},{"position":{"x":-7,"y":-34,"z":0},"blockType":2},{"position":{"x":-7,"y":-34,"z":1},"blockType":2},{"position":{"x":-7,"y":-34,"z":2},"blockType":2},{"position":{"x":2,"y":-34,"z":7},"blockType":2},{"position":{"x":1,"y":-34,"z":7},"blockType":2},{"position":{"x":0,"y":-34,"z":7},"blockType":2},{"position":{"x":-1,"y":-34,"z":7},"blockType":2},{"position":{"x":-2,"y":-34,"z":7},"blockType":2},{"position":{"x":2,"y":-34,"z":8},"blockType":2},{"position":{"x":1,"y":-34,"z":8},"blockType":2},{"position":{"x":0,"y":-34,"z":8},"blockType":2},{"position":{"x":-1,"y":-34,"z":8},"blockType":2},{"position":{"x":-2,"y":-34,"z":8},"blockType":2},{"position":{"x":-8,"y":-34,"z":-2},"blockType":2},{"position":{"x":-8,"y":-34,"z":-1},"blockType":2},{"position":{"x":-8,"y":-34,"z":0},"blockType":2},{"position":{"x":-8,"y":-34,"z":1},"blockType":2},{"position":{"x":-8,"y":-34,"z":2},"blockType":2},{"position":{"x":5,"y":-34,"z":-3},"blockType":2},{"position":{"x":4,"y":-34,"z":-4},"blockType":2},{"position":{"x":3,"y":-34,"z":-5},"blockType":2},{"position":{"x":6,"y":-34,"z":-3},"blockType":2},{"position":{"x":5,"y":-34,"z":-4},"blockType":2},{"position":{"x":4,"y":-34,"z":-5},"blockType":2},{"position":{"x":3,"y":-34,"z":-6},"blockType":2},{"position":{"x":7,"y":-34,"z":-3},"blockType":2},{"position":{"x":6,"y":-34,"z":-4},"blockType":2},{"position":{"x":5,"y":-34,"z":-5},"blockType":2},{"position":{"x":4,"y":-34,"z":-6},"blockType":2},{"position":{"x":3,"y":-34,"z":-7},"blockType":2},{"position":{"x":5,"y":-34,"z":3},"blockType":2},{"position":{"x":4,"y":-34,"z":4},"blockType":2},{"position":{"x":3,"y":-34,"z":5},"blockType":2},{"position":{"x":3,"y":-34,"z":6},"blockType":2},{"position":{"x":4,"y":-34,"z":5},"blockType":2},{"position":{"x":5,"y":-34,"z":4},"blockType":2},{"position":{"x":6,"y":-34,"z":3},"blockType":2},{"position":{"x":7,"y":-34,"z":3},"blockType":2},{"position":{"x":6,"y":-34,"z":4},"blockType":2},{"position":{"x":5,"y":-34,"z":5},"blockType":2},{"position":{"x":4,"y":-34,"z":6},"blockType":2},{"position":{"x":3,"y":-34,"z":7},"blockType":2},{"position":{"x":-3,"y":-34,"z":-5},"blockType":2},{"position":{"x":-4,"y":-34,"z":-4},"blockType":2},{"position":{"x":-5,"y":-34,"z":-3},"blockType":2},{"position":{"x":-6,"y":-34,"z":-3},"blockType":2},{"position":{"x":-5,"y":-34,"z":-4},"blockType":2},{"position":{"x":-4,"y":-34,"z":-5},"blockType":2},{"position":{"x":-3,"y":-34,"z":-6},"blockType":2},{"position":{"x":-3,"y":-34,"z":-7},"blockType":2},{"position":{"x":-4,"y":-34,"z":-6},"blockType":2},{"position":{"x":-5,"y":-34,"z":-5},"blockType":2},{"position":{"x":-6,"y":-34,"z":-4},"blockType":2},{"position":{"x":-7,"y":-34,"z":-3},"blockType":2},{"position":{"x":-3,"y":-34,"z":5},"blockType":2},{"position":{"x":-4,"y":-34,"z":4},"blockType":2},{"position":{"x":-5,"y":-34,"z":3},"blockType":2},{"position":{"x":-6,"y":-34,"z":3},"blockType":2},{"position":{"x":-5,"y":-34,"z":4},"blockType":2},{"position":{"x":-4,"y":-34,"z":5},"blockType":2},{"position":{"x":-3,"y":-34,"z":6},"blockType":2},{"position":{"x":-3,"y":-34,"z":7},"blockType":2},{"position":{"x":-4,"y":-34,"z":6},"blockType":2},{"position":{"x":-5,"y":-34,"z":5},"blockType":2},{"position":{"x":-6,"y":-34,"z":4},"blockType":2},{"position":{"x":-7,"y":-34,"z":3},"blockType":2},{"position":{"x":2,"y":-34,"z":-5},"blockType":8},{"position":{"x":2,"y":-34,"z":-8},"blockType":8},{"position":{"x":-2,"y":-34,"z":-8},"blockType":8},{"position":{"x":-2,"y":-34,"z":-5},"blockType":8},{"position":{"x":1,"y":-34,"z":-5},"blockType":8},{"position":{"x":0,"y":-34,"z":-5},"blockType":8},{"position":{"x":-1,"y":-34,"z":-5},"blockType":8},{"position":{"x":-2,"y":-34,"z":-6},"blockType":8},{"position":{"x":-2,"y":-34,"z":-7},"blockType":8},{"position":{"x":2,"y":-34,"z":-6},"blockType":8},{"position":{"x":2,"y":-34,"z":-7},"blockType":8},{"position":{"x":1,"y":-34,"z":-8},"blockType":8},{"position":{"x":0,"y":-34,"z":-8},"blockType":8},{"position":{"x":-1,"y":-34,"z":-8},"blockType":8},{"position":{"x":5,"y":-34,"z":2},"blockType":8},{"position":{"x":8,"y":-34,"z":2},"blockType":8},{"position":{"x":7,"y":-34,"z":2},"blockType":8},{"position":{"x":6,"y":-34,"z":2},"blockType":8},{"position":{"x":5,"y":-34,"z":-2},"blockType":8},{"position":{"x":6,"y":-34,"z":-2},"blockType":8},{"position":{"x":7,"y":-34,"z":-2},"blockType":8},{"position":{"x":8,"y":-34,"z":-2},"blockType":8},{"position":{"x":3,"y":-34,"z":2},"blockType":6},{"position":{"x":4,"y":-34,"z":2},"blockType":6},{"position":{"x":-5,"y":-33,"z":2},"blockType":2},{"position":{"x":-5,"y":-33,"z":1},"blockType":2},{"position":{"x":-5,"y":-33,"z":0},"blockType":2},{"position":{"x":-5,"y":-33,"z":-1},"blockType":2},{"position":{"x":-5,"y":-33,"z":-2},"blockType":2},{"position":{"x":-4,"y":-33,"z":-3},"blockType":2},{"position":{"x":-3,"y":-33,"z":-4},"blockType":2},{"position":{"x":-4,"y":-33,"z":3},"blockType":2},{"position":{"x":-3,"y":-33,"z":4},"blockType":2},{"position":{"x":-2,"y":-33,"z":5},"blockType":2},{"position":{"x":-1,"y":-33,"z":5},"blockType":2},{"position":{"x":0,"y":-33,"z":5},"blockType":2},{"position":{"x":1,"y":-33,"z":5},"blockType":2},{"position":{"x":2,"y":-33,"z":5},"blockType":2},{"position":{"x":3,"y":-33,"z":4},"blockType":2},{"position":{"x":4,"y":-33,"z":3},"blockType":2},{"position":{"x":4,"y":-33,"z":-3},"blockType":2},{"position":{"x":3,"y":-33,"z":-4},"blockType":2},{"position":{"x":2,"y":-33,"z":6},"blockType":2},{"position":{"x":1,"y":-33,"z":6},"blockType":2},{"position":{"x":0,"y":-33,"z":6},"blockType":2},{"position":{"x":-1,"y":-33,"z":6},"blockType":2},{"position":{"x":-2,"y":-33,"z":6},"blockType":2},{"position":{"x":-6,"y":-33,"z":2},"blockType":2},{"position":{"x":-6,"y":-33,"z":1},"blockType":2},{"position":{"x":-6,"y":-33,"z":0},"blockType":2},{"position":{"x":-6,"y":-33,"z":-1},"blockType":2},{"position":{"x":-6,"y":-33,"z":-2},"blockType":2},{"position":{"x":-7,"y":-33,"z":-2},"blockType":2},{"position":{"x":-7,"y":-33,"z":-1},"blockType":2},{"position":{"x":-7,"y":-33,"z":0},"blockType":2},{"position":{"x":-7,"y":-33,"z":1},"blockType":2},{"position":{"x":-7,"y":-33,"z":2},"blockType":2},{"position":{"x":2,"y":-33,"z":7},"blockType":2},{"position":{"x":1,"y":-33,"z":7},"blockType":2},{"position":{"x":0,"y":-33,"z":7},"blockType":2},{"position":{"x":-1,"y":-33,"z":7},"blockType":2},{"position":{"x":-2,"y":-33,"z":7},"blockType":2},{"position":{"x":2,"y":-33,"z":8},"blockType":2},{"position":{"x":1,"y":-33,"z":8},"blockType":2},{"position":{"x":0,"y":-33,"z":8},"blockType":2},{"position":{"x":-1,"y":-33,"z":8},"blockType":2},{"position":{"x":-2,"y":-33,"z":8},"blockType":2},{"position":{"x":-8,"y":-33,"z":-2},"blockType":2},{"position":{"x":-8,"y":-33,"z":-1},"blockType":2},{"position":{"x":-8,"y":-33,"z":0},"blockType":2},{"position":{"x":-8,"y":-33,"z":1},"blockType":2},{"position":{"x":-8,"y":-33,"z":2},"blockType":2},{"position":{"x":5,"y":-33,"z":-3},"blockType":2},{"position":{"x":4,"y":-33,"z":-4},"blockType":2},{"position":{"x":3,"y":-33,"z":-5},"blockType":2},{"position":{"x":6,"y":-33,"z":-3},"blockType":2},{"position":{"x":5,"y":-33,"z":-4},"blockType":2},{"position":{"x":4,"y":-33,"z":-5},"blockType":2},{"position":{"x":3,"y":-33,"z":-6},"blockType":2},{"position":{"x":7,"y":-33,"z":-3},"blockType":2},{"position":{"x":6,"y":-33,"z":-4},"blockType":2},{"position":{"x":5,"y":-33,"z":-5},"blockType":2},{"position":{"x":4,"y":-33,"z":-6},"blockType":2},{"position":{"x":3,"y":-33,"z":-7},"blockType":2},{"position":{"x":5,"y":-33,"z":3},"blockType":2},{"position":{"x":4,"y":-33,"z":4},"blockType":2},{"position":{"x":3,"y":-33,"z":5},"blockType":2},{"position":{"x":3,"y":-33,"z":6},"blockType":2},{"position":{"x":4,"y":-33,"z":5},"blockType":2},{"position":{"x":5,"y":-33,"z":4},"blockType":2},{"position":{"x":6,"y":-33,"z":3},"blockType":2},{"position":{"x":7,"y":-33,"z":3},"blockType":2},{"position":{"x":6,"y":-33,"z":4},"blockType":2},{"position":{"x":5,"y":-33,"z":5},"blockType":2},{"position":{"x":4,"y":-33,"z":6},"blockType":2},{"position":{"x":3,"y":-33,"z":7},"blockType":2},{"position":{"x":-3,"y":-33,"z":-5},"blockType":2},{"position":{"x":-4,"y":-33,"z":-4},"blockType":2},{"position":{"x":-5,"y":-33,"z":-3},"blockType":2},{"position":{"x":-6,"y":-33,"z":-3},"blockType":2},{"position":{"x":-5,"y":-33,"z":-4},"blockType":2},{"position":{"x":-4,"y":-33,"z":-5},"blockType":2},{"position":{"x":-3,"y":-33,"z":-6},"blockType":2},{"position":{"x":-3,"y":-33,"z":-7},"blockType":2},{"position":{"x":-4,"y":-33,"z":-6},"blockType":2},{"position":{"x":-5,"y":-33,"z":-5},"blockType":2},{"position":{"x":-6,"y":-33,"z":-4},"blockType":2},{"position":{"x":-7,"y":-33,"z":-3},"blockType":2},{"position":{"x":-3,"y":-33,"z":5},"blockType":2},{"position":{"x":-4,"y":-33,"z":4},"blockType":2},{"position":{"x":-5,"y":-33,"z":3},"blockType":2},{"position":{"x":-6,"y":-33,"z":3},"blockType":2},{"position":{"x":-5,"y":-33,"z":4},"blockType":2},{"position":{"x":-4,"y":-33,"z":5},"blockType":2},{"position":{"x":-3,"y":-33,"z":6},"blockType":2},{"position":{"x":-3,"y":-33,"z":7},"blockType":2},{"position":{"x":-4,"y":-33,"z":6},"blockType":2},{"position":{"x":-5,"y":-33,"z":5},"blockType":2},{"position":{"x":-6,"y":-33,"z":4},"blockType":2},{"position":{"x":-7,"y":-33,"z":3},"blockType":2},{"position":{"x":5,"y":-33,"z":2},"blockType":8},{"position":{"x":8,"y":-33,"z":2},"blockType":8},{"position":{"x":5,"y":-33,"z":-2},"blockType":8},{"position":{"x":8,"y":-33,"z":-2},"blockType":8},{"position":{"x":2,"y":-33,"z":-5},"blockType":2},{"position":{"x":1,"y":-33,"z":-5},"blockType":2},{"position":{"x":0,"y":-33,"z":-5},"blockType":2},{"position":{"x":-1,"y":-33,"z":-5},"blockType":2},{"position":{"x":-2,"y":-33,"z":-5},"blockType":2},{"position":{"x":-2,"y":-33,"z":-6},"blockType":2},{"position":{"x":-2,"y":-33,"z":-7},"blockType":2},{"position":{"x":-2,"y":-33,"z":-8},"blockType":2},{"position":{"x":-1,"y":-33,"z":-8},"blockType":2},{"position":{"x":0,"y":-33,"z":-8},"blockType":2},{"position":{"x":1,"y":-33,"z":-8},"blockType":2},{"position":{"x":2,"y":-33,"z":-8},"blockType":2},{"position":{"x":2,"y":-33,"z":-6},"blockType":2},{"position":{"x":2,"y":-33,"z":-7},"blockType":2},{"position":{"x":1,"y":-33,"z":-6},"blockType":2},{"position":{"x":0,"y":-33,"z":-6},"blockType":2},{"position":{"x":-1,"y":-33,"z":-6},"blockType":2},{"position":{"x":1,"y":-33,"z":-7},"blockType":2},{"position":{"x":0,"y":-33,"z":-7},"blockType":2},{"position":{"x":-1,"y":-33,"z":-7},"blockType":2},{"position":{"x":2,"y":-33,"z":2},"blockType":6},{"position":{"x":3,"y":-33,"z":3},"blockType":6},{"position":{"x":-5,"y":-32,"z":2},"blockType":2},{"position":{"x":-5,"y":-32,"z":1},"blockType":2},{"position":{"x":-5,"y":-32,"z":0},"blockType":2},{"position":{"x":-5,"y":-32,"z":-1},"blockType":2},{"position":{"x":-5,"y":-32,"z":-2},"blockType":2},{"position":{"x":-4,"y":-32,"z":-3},"blockType":2},{"position":{"x":-3,"y":-32,"z":-4},"blockType":2},{"position":{"x":-4,"y":-32,"z":3},"blockType":2},{"position":{"x":-3,"y":-32,"z":4},"blockType":2},{"position":{"x":-2,"y":-32,"z":5},"blockType":2},{"position":{"x":-1,"y":-32,"z":5},"blockType":2},{"position":{"x":0,"y":-32,"z":5},"blockType":2},{"position":{"x":1,"y":-32,"z":5},"blockType":2},{"position":{"x":2,"y":-32,"z":5},"blockType":2},{"position":{"x":3,"y":-32,"z":4},"blockType":2},{"position":{"x":4,"y":-32,"z":3},"blockType":2},{"position":{"x":4,"y":-32,"z":-3},"blockType":2},{"position":{"x":3,"y":-32,"z":-4},"blockType":2},{"position":{"x":2,"y":-32,"z":6},"blockType":2},{"position":{"x":1,"y":-32,"z":6},"blockType":2},{"position":{"x":0,"y":-32,"z":6},"blockType":2},{"position":{"x":-1,"y":-32,"z":6},"blockType":2},{"position":{"x":-2,"y":-32,"z":6},"blockType":2},{"position":{"x":-6,"y":-32,"z":2},"blockType":2},{"position":{"x":-6,"y":-32,"z":1},"blockType":2},{"position":{"x":-6,"y":-32,"z":0},"blockType":2},{"position":{"x":-6,"y":-32,"z":-1},"blockType":2},{"position":{"x":-6,"y":-32,"z":-2},"blockType":2},{"position":{"x":-7,"y":-32,"z":-2},"blockType":2},{"position":{"x":-7,"y":-32,"z":-1},"blockType":2},{"position":{"x":-7,"y":-32,"z":0},"blockType":2},{"position":{"x":-7,"y":-32,"z":1},"blockType":2},{"position":{"x":-7,"y":-32,"z":2},"blockType":2},{"position":{"x":2,"y":-32,"z":7},"blockType":2},{"position":{"x":1,"y":-32,"z":7},"blockType":2},{"position":{"x":0,"y":-32,"z":7},"blockType":2},{"position":{"x":-1,"y":-32,"z":7},"blockType":2},{"position":{"x":-2,"y":-32,"z":7},"blockType":2},{"position":{"x":2,"y":-32,"z":8},"blockType":2},{"position":{"x":1,"y":-32,"z":8},"blockType":2},{"position":{"x":0,"y":-32,"z":8},"blockType":2},{"position":{"x":-1,"y":-32,"z":8},"blockType":2},{"position":{"x":-2,"y":-32,"z":8},"blockType":2},{"position":{"x":-8,"y":-32,"z":-2},"blockType":2},{"position":{"x":-8,"y":-32,"z":-1},"blockType":2},{"position":{"x":-8,"y":-32,"z":0},"blockType":2},{"position":{"x":-8,"y":-32,"z":1},"blockType":2},{"position":{"x":-8,"y":-32,"z":2},"blockType":2},{"position":{"x":5,"y":-32,"z":-3},"blockType":2},{"position":{"x":4,"y":-32,"z":-4},"blockType":2},{"position":{"x":3,"y":-32,"z":-5},"blockType":2},{"position":{"x":6,"y":-32,"z":-3},"blockType":2},{"position":{"x":5,"y":-32,"z":-4},"blockType":2},{"position":{"x":4,"y":-32,"z":-5},"blockType":2},{"position":{"x":3,"y":-32,"z":-6},"blockType":2},{"position":{"x":7,"y":-32,"z":-3},"blockType":2},{"position":{"x":6,"y":-32,"z":-4},"blockType":2},{"position":{"x":5,"y":-32,"z":-5},"blockType":2},{"position":{"x":4,"y":-32,"z":-6},"blockType":2},{"position":{"x":3,"y":-32,"z":-7},"blockType":2},{"position":{"x":5,"y":-32,"z":3},"blockType":2},{"position":{"x":4,"y":-32,"z":4},"blockType":2},{"position":{"x":3,"y":-32,"z":5},"blockType":2},{"position":{"x":3,"y":-32,"z":6},"blockType":2},{"position":{"x":4,"y":-32,"z":5},"blockType":2},{"position":{"x":5,"y":-32,"z":4},"blockType":2},{"position":{"x":6,"y":-32,"z":3},"blockType":2},{"position":{"x":7,"y":-32,"z":3},"blockType":2},{"position":{"x":6,"y":-32,"z":4},"blockType":2},{"position":{"x":5,"y":-32,"z":5},"blockType":2},{"position":{"x":4,"y":-32,"z":6},"blockType":2},{"position":{"x":3,"y":-32,"z":7},"blockType":2},{"position":{"x":-3,"y":-32,"z":-5},"blockType":2},{"position":{"x":-4,"y":-32,"z":-4},"blockType":2},{"position":{"x":-5,"y":-32,"z":-3},"blockType":2},{"position":{"x":-6,"y":-32,"z":-3},"blockType":2},{"position":{"x":-5,"y":-32,"z":-4},"blockType":2},{"position":{"x":-4,"y":-32,"z":-5},"blockType":2},{"position":{"x":-3,"y":-32,"z":-6},"blockType":2},{"position":{"x":-3,"y":-32,"z":-7},"blockType":2},{"position":{"x":-4,"y":-32,"z":-6},"blockType":2},{"position":{"x":-5,"y":-32,"z":-5},"blockType":2},{"position":{"x":-6,"y":-32,"z":-4},"blockType":2},{"position":{"x":-7,"y":-32,"z":-3},"blockType":2},{"position":{"x":-3,"y":-32,"z":5},"blockType":2},{"position":{"x":-4,"y":-32,"z":4},"blockType":2},{"position":{"x":-5,"y":-32,"z":3},"blockType":2},{"position":{"x":-6,"y":-32,"z":3},"blockType":2},{"position":{"x":-5,"y":-32,"z":4},"blockType":2},{"position":{"x":-4,"y":-32,"z":5},"blockType":2},{"position":{"x":-3,"y":-32,"z":6},"blockType":2},{"position":{"x":-3,"y":-32,"z":7},"blockType":2},{"position":{"x":-4,"y":-32,"z":6},"blockType":2},{"position":{"x":-5,"y":-32,"z":5},"blockType":2},{"position":{"x":-6,"y":-32,"z":4},"blockType":2},{"position":{"x":-7,"y":-32,"z":3},"blockType":2},{"position":{"x":5,"y":-32,"z":2},"blockType":8},{"position":{"x":8,"y":-32,"z":2},"blockType":8},{"position":{"x":5,"y":-32,"z":-2},"blockType":8},{"position":{"x":8,"y":-32,"z":-2},"blockType":8},{"position":{"x":2,"y":-32,"z":-5},"blockType":2},{"position":{"x":1,"y":-32,"z":-5},"blockType":2},{"position":{"x":0,"y":-32,"z":-5},"blockType":2},{"position":{"x":-1,"y":-32,"z":-5},"blockType":2},{"position":{"x":-2,"y":-32,"z":-5},"blockType":2},{"position":{"x":-2,"y":-32,"z":-6},"blockType":2},{"position":{"x":-2,"y":-32,"z":-7},"blockType":2},{"position":{"x":-2,"y":-32,"z":-8},"blockType":2},{"position":{"x":-1,"y":-32,"z":-8},"blockType":2},{"position":{"x":0,"y":-32,"z":-8},"blockType":2},{"position":{"x":1,"y":-32,"z":-8},"blockType":2},{"position":{"x":2,"y":-32,"z":-8},"blockType":2},{"position":{"x":2,"y":-32,"z":-6},"blockType":2},{"position":{"x":2,"y":-32,"z":-7},"blockType":2},{"position":{"x":1,"y":-32,"z":-6},"blockType":2},{"position":{"x":0,"y":-32,"z":-6},"blockType":2},{"position":{"x":-1,"y":-32,"z":-6},"blockType":2},{"position":{"x":1,"y":-32,"z":-7},"blockType":2},{"position":{"x":0,"y":-32,"z":-7},"blockType":2},{"position":{"x":-1,"y":-32,"z":-7},"blockType":2},{"position":{"x":2,"y":-32,"z":3},"blockType":6},{"position":{"x":2,"y":-32,"z":4},"blockType":6},{"position":{"x":-5,"y":-31,"z":2},"blockType":2},{"position":{"x":-5,"y":-31,"z":1},"blockType":2},{"position":{"x":-5,"y":-31,"z":0},"blockType":2},{"position":{"x":-5,"y":-31,"z":-1},"blockType":2},{"position":{"x":-5,"y":-31,"z":-2},"blockType":2},{"position":{"x":-4,"y":-31,"z":-3},"blockType":2},{"position":{"x":-3,"y":-31,"z":-4},"blockType":2},{"position":{"x":-4,"y":-31,"z":3},"blockType":2},{"position":{"x":-3,"y":-31,"z":4},"blockType":2},{"position":{"x":-2,"y":-31,"z":5},"blockType":2},{"position":{"x":-1,"y":-31,"z":5},"blockType":2},{"position":{"x":0,"y":-31,"z":5},"blockType":2},{"position":{"x":1,"y":-31,"z":5},"blockType":2},{"position":{"x":2,"y":-31,"z":5},"blockType":2},{"position":{"x":3,"y":-31,"z":4},"blockType":2},{"position":{"x":4,"y":-31,"z":3},"blockType":2},{"position":{"x":4,"y":-31,"z":-3},"blockType":2},{"position":{"x":3,"y":-31,"z":-4},"blockType":2},{"position":{"x":2,"y":-31,"z":6},"blockType":2},{"position":{"x":1,"y":-31,"z":6},"blockType":2},{"position":{"x":0,"y":-31,"z":6},"blockType":2},{"position":{"x":-1,"y":-31,"z":6},"blockType":2},{"position":{"x":-2,"y":-31,"z":6},"blockType":2},{"position":{"x":-6,"y":-31,"z":2},"blockType":2},{"position":{"x":-6,"y":-31,"z":1},"blockType":2},{"position":{"x":-6,"y":-31,"z":0},"blockType":2},{"position":{"x":-6,"y":-31,"z":-1},"blockType":2},{"position":{"x":-6,"y":-31,"z":-2},"blockType":2},{"position":{"x":-7,"y":-31,"z":-2},"blockType":2},{"position":{"x":-7,"y":-31,"z":-1},"blockType":2},{"position":{"x":-7,"y":-31,"z":0},"blockType":2},{"position":{"x":-7,"y":-31,"z":1},"blockType":2},{"position":{"x":-7,"y":-31,"z":2},"blockType":2},{"position":{"x":2,"y":-31,"z":7},"blockType":2},{"position":{"x":1,"y":-31,"z":7},"blockType":2},{"position":{"x":0,"y":-31,"z":7},"blockType":2},{"position":{"x":-1,"y":-31,"z":7},"blockType":2},{"position":{"x":-2,"y":-31,"z":7},"blockType":2},{"position":{"x":2,"y":-31,"z":8},"blockType":2},{"position":{"x":1,"y":-31,"z":8},"blockType":2},{"position":{"x":0,"y":-31,"z":8},"blockType":2},{"position":{"x":-1,"y":-31,"z":8},"blockType":2},{"position":{"x":-2,"y":-31,"z":8},"blockType":2},{"position":{"x":-8,"y":-31,"z":-2},"blockType":2},{"position":{"x":-8,"y":-31,"z":-1},"blockType":2},{"position":{"x":-8,"y":-31,"z":0},"blockType":2},{"position":{"x":-8,"y":-31,"z":1},"blockType":2},{"position":{"x":-8,"y":-31,"z":2},"blockType":2},{"position":{"x":5,"y":-31,"z":-3},"blockType":2},{"position":{"x":4,"y":-31,"z":-4},"blockType":2},{"position":{"x":3,"y":-31,"z":-5},"blockType":2},{"position":{"x":6,"y":-31,"z":-3},"blockType":2},{"position":{"x":5,"y":-31,"z":-4},"blockType":2},{"position":{"x":4,"y":-31,"z":-5},"blockType":2},{"position":{"x":3,"y":-31,"z":-6},"blockType":2},{"position":{"x":7,"y":-31,"z":-3},"blockType":2},{"position":{"x":6,"y":-31,"z":-4},"blockType":2},{"position":{"x":5,"y":-31,"z":-5},"blockType":2},{"position":{"x":4,"y":-31,"z":-6},"blockType":2},{"position":{"x":3,"y":-31,"z":-7},"blockType":2},{"position":{"x":5,"y":-31,"z":3},"blockType":2},{"position":{"x":4,"y":-31,"z":4},"blockType":2},{"position":{"x":3,"y":-31,"z":5},"blockType":2},{"position":{"x":3,"y":-31,"z":6},"blockType":2},{"position":{"x":4,"y":-31,"z":5},"blockType":2},{"position":{"x":5,"y":-31,"z":4},"blockType":2},{"position":{"x":6,"y":-31,"z":3},"blockType":2},{"position":{"x":7,"y":-31,"z":3},"blockType":2},{"position":{"x":6,"y":-31,"z":4},"blockType":2},{"position":{"x":5,"y":-31,"z":5},"blockType":2},{"position":{"x":4,"y":-31,"z":6},"blockType":2},{"position":{"x":3,"y":-31,"z":7},"blockType":2},{"position":{"x":-3,"y":-31,"z":-5},"blockType":2},{"position":{"x":-4,"y":-31,"z":-4},"blockType":2},{"position":{"x":-5,"y":-31,"z":-3},"blockType":2},{"position":{"x":-6,"y":-31,"z":-3},"blockType":2},{"position":{"x":-5,"y":-31,"z":-4},"blockType":2},{"position":{"x":-4,"y":-31,"z":-5},"blockType":2},{"position":{"x":-3,"y":-31,"z":-6},"blockType":2},{"position":{"x":-3,"y":-31,"z":-7},"blockType":2},{"position":{"x":-4,"y":-31,"z":-6},"blockType":2},{"position":{"x":-5,"y":-31,"z":-5},"blockType":2},{"position":{"x":-6,"y":-31,"z":-4},"blockType":2},{"position":{"x":-7,"y":-31,"z":-3},"blockType":2},{"position":{"x":-3,"y":-31,"z":5},"blockType":2},{"position":{"x":-4,"y":-31,"z":4},"blockType":2},{"position":{"x":-5,"y":-31,"z":3},"blockType":2},{"position":{"x":-6,"y":-31,"z":3},"blockType":2},{"position":{"x":-5,"y":-31,"z":4},"blockType":2},{"position":{"x":-4,"y":-31,"z":5},"blockType":2},{"position":{"x":-3,"y":-31,"z":6},"blockType":2},{"position":{"x":-3,"y":-31,"z":7},"blockType":2},{"position":{"x":-4,"y":-31,"z":6},"blockType":2},{"position":{"x":-5,"y":-31,"z":5},"blockType":2},{"position":{"x":-6,"y":-31,"z":4},"blockType":2},{"position":{"x":-7,"y":-31,"z":3},"blockType":2},{"position":{"x":5,"y":-31,"z":2},"blockType":8},{"position":{"x":8,"y":-31,"z":2},"blockType":8},{"position":{"x":5,"y":-31,"z":-2},"blockType":8},{"position":{"x":8,"y":-31,"z":-2},"blockType":8},{"position":{"x":2,"y":-31,"z":-5},"blockType":2},{"position":{"x":1,"y":-31,"z":-5},"blockType":2},{"position":{"x":0,"y":-31,"z":-5},"blockType":2},{"position":{"x":-1,"y":-31,"z":-5},"blockType":2},{"position":{"x":-2,"y":-31,"z":-5},"blockType":2},{"position":{"x":-2,"y":-31,"z":-6},"blockType":2},{"position":{"x":-2,"y":-31,"z":-7},"blockType":2},{"position":{"x":-2,"y":-31,"z":-8},"blockType":2},{"position":{"x":-1,"y":-31,"z":-8},"blockType":2},{"position":{"x":0,"y":-31,"z":-8},"blockType":2},{"position":{"x":1,"y":-31,"z":-8},"blockType":2},{"position":{"x":2,"y":-31,"z":-8},"blockType":2},{"position":{"x":2,"y":-31,"z":-6},"blockType":2},{"position":{"x":2,"y":-31,"z":-7},"blockType":2},{"position":{"x":1,"y":-31,"z":-6},"blockType":2},{"position":{"x":0,"y":-31,"z":-6},"blockType":2},{"position":{"x":-1,"y":-31,"z":-6},"blockType":2},{"position":{"x":1,"y":-31,"z":-7},"blockType":2},{"position":{"x":0,"y":-31,"z":-7},"blockType":2},{"position":{"x":-1,"y":-31,"z":-7},"blockType":2},{"position":{"x":1,"y":-31,"z":3},"blockType":6},{"position":{"x":1,"y":-31,"z":4},"blockType":6},{"position":{"x":0,"y":-31,"z":3},"blockType":6},{"position":{"x":0,"y":-31,"z":4},"blockType":6},{"position":{"x":-1,"y":-31,"z":3},"blockType":6},{"position":{"x":-1,"y":-31,"z":4},"blockType":6},{"position":{"x":-5,"y":-30,"z":2},"blockType":2},{"position":{"x":-5,"y":-30,"z":1},"blockType":2},{"position":{"x":-5,"y":-30,"z":0},"blockType":2},{"position":{"x":-5,"y":-30,"z":-1},"blockType":2},{"position":{"x":-5,"y":-30,"z":-2},"blockType":2},{"position":{"x":-4,"y":-30,"z":-3},"blockType":2},{"position":{"x":-3,"y":-30,"z":-4},"blockType":2},{"position":{"x":-4,"y":-30,"z":3},"blockType":2},{"position":{"x":-3,"y":-30,"z":4},"blockType":2},{"position":{"x":3,"y":-30,"z":4},"blockType":2},{"position":{"x":4,"y":-30,"z":3},"blockType":2},{"position":{"x":4,"y":-30,"z":-3},"blockType":2},{"position":{"x":3,"y":-30,"z":-4},"blockType":2},{"position":{"x":-6,"y":-30,"z":2},"blockType":2},{"position":{"x":-6,"y":-30,"z":1},"blockType":2},{"position":{"x":-6,"y":-30,"z":0},"blockType":2},{"position":{"x":-6,"y":-30,"z":-1},"blockType":2},{"position":{"x":-6,"y":-30,"z":-2},"blockType":2},{"position":{"x":-7,"y":-30,"z":-2},"blockType":2},{"position":{"x":-7,"y":-30,"z":-1},"blockType":2},{"position":{"x":-7,"y":-30,"z":0},"blockType":2},{"position":{"x":-7,"y":-30,"z":1},"blockType":2},{"position":{"x":-7,"y":-30,"z":2},"blockType":2},{"position":{"x":-8,"y":-30,"z":-2},"blockType":2},{"position":{"x":-8,"y":-30,"z":-1},"blockType":2},{"position":{"x":-8,"y":-30,"z":0},"blockType":2},{"position":{"x":-8,"y":-30,"z":1},"blockType":2},{"position":{"x":-8,"y":-30,"z":2},"blockType":2},{"position":{"x":5,"y":-30,"z":-3},"blockType":2},{"position":{"x":4,"y":-30,"z":-4},"blockType":2},{"position":{"x":3,"y":-30,"z":-5},"blockType":2},{"position":{"x":6,"y":-30,"z":-3},"blockType":2},{"position":{"x":5,"y":-30,"z":-4},"blockType":2},{"position":{"x":4,"y":-30,"z":-5},"blockType":2},{"position":{"x":3,"y":-30,"z":-6},"blockType":2},{"position":{"x":7,"y":-30,"z":-3},"blockType":2},{"position":{"x":6,"y":-30,"z":-4},"blockType":2},{"position":{"x":5,"y":-30,"z":-5},"blockType":2},{"position":{"x":4,"y":-30,"z":-6},"blockType":2},{"position":{"x":3,"y":-30,"z":-7},"blockType":2},{"position":{"x":5,"y":-30,"z":3},"blockType":2},{"position":{"x":4,"y":-30,"z":4},"blockType":2},{"position":{"x":3,"y":-30,"z":5},"blockType":2},{"position":{"x":3,"y":-30,"z":6},"blockType":2},{"position":{"x":4,"y":-30,"z":5},"blockType":2},{"position":{"x":5,"y":-30,"z":4},"blockType":2},{"position":{"x":6,"y":-30,"z":3},"blockType":2},{"position":{"x":7,"y":-30,"z":3},"blockType":2},{"position":{"x":6,"y":-30,"z":4},"blockType":2},{"position":{"x":5,"y":-30,"z":5},"blockType":2},{"position":{"x":4,"y":-30,"z":6},"blockType":2},{"position":{"x":3,"y":-30,"z":7},"blockType":2},{"position":{"x":-3,"y":-30,"z":-5},"blockType":2},{"position":{"x":-4,"y":-30,"z":-4},"blockType":2},{"position":{"x":-5,"y":-30,"z":-3},"blockType":2},{"position":{"x":-6,"y":-30,"z":-3},"blockType":2},{"position":{"x":-5,"y":-30,"z":-4},"blockType":2},{"position":{"x":-4,"y":-30,"z":-5},"blockType":2},{"position":{"x":-3,"y":-30,"z":-6},"blockType":2},{"position":{"x":-3,"y":-30,"z":-7},"blockType":2},{"position":{"x":-4,"y":-30,"z":-6},"blockType":2},{"position":{"x":-5,"y":-30,"z":-5},"blockType":2},{"position":{"x":-6,"y":-30,"z":-4},"blockType":2},{"position":{"x":-7,"y":-30,"z":-3},"blockType":2},{"position":{"x":-3,"y":-30,"z":5},"blockType":2},{"position":{"x":-4,"y":-30,"z":4},"blockType":2},{"position":{"x":-5,"y":-30,"z":3},"blockType":2},{"position":{"x":-6,"y":-30,"z":3},"blockType":2},{"position":{"x":-5,"y":-30,"z":4},"blockType":2},{"position":{"x":-4,"y":-30,"z":5},"blockType":2},{"position":{"x":-3,"y":-30,"z":6},"blockType":2},{"position":{"x":-3,"y":-30,"z":7},"blockType":2},{"position":{"x":-4,"y":-30,"z":6},"blockType":2},{"position":{"x":-5,"y":-30,"z":5},"blockType":2},{"position":{"x":-6,"y":-30,"z":4},"blockType":2},{"position":{"x":-7,"y":-30,"z":3},"blockType":2},{"position":{"x":5,"y":-30,"z":2},"blockType":8},{"position":{"x":8,"y":-30,"z":2},"blockType":8},{"position":{"x":5,"y":-30,"z":-2},"blockType":8},{"position":{"x":8,"y":-30,"z":-2},"blockType":8},{"position":{"x":2,"y":-30,"z":-5},"blockType":2},{"position":{"x":1,"y":-30,"z":-5},"blockType":2},{"position":{"x":0,"y":-30,"z":-5},"blockType":2},{"position":{"x":-1,"y":-30,"z":-5},"blockType":2},{"position":{"x":-2,"y":-30,"z":-5},"blockType":2},{"position":{"x":-2,"y":-30,"z":-6},"blockType":2},{"position":{"x":-2,"y":-30,"z":-7},"blockType":2},{"position":{"x":-2,"y":-30,"z":-8},"blockType":2},{"position":{"x":-1,"y":-30,"z":-8},"blockType":2},{"position":{"x":0,"y":-30,"z":-8},"blockType":2},{"position":{"x":1,"y":-30,"z":-8},"blockType":2},{"position":{"x":2,"y":-30,"z":-8},"blockType":2},{"position":{"x":2,"y":-30,"z":-6},"blockType":2},{"position":{"x":2,"y":-30,"z":-7},"blockType":2},{"position":{"x":1,"y":-30,"z":-6},"blockType":2},{"position":{"x":0,"y":-30,"z":-6},"blockType":2},{"position":{"x":-1,"y":-30,"z":-6},"blockType":2},{"position":{"x":1,"y":-30,"z":-7},"blockType":2},{"position":{"x":0,"y":-30,"z":-7},"blockType":2},{"position":{"x":-1,"y":-30,"z":-7},"blockType":2},{"position":{"x":5,"y":-30,"z":1},"blockType":8},{"position":{"x":5,"y":-30,"z":0},"blockType":8},{"position":{"x":5,"y":-30,"z":-1},"blockType":8},{"position":{"x":6,"y":-30,"z":-2},"blockType":8},{"position":{"x":7,"y":-30,"z":-2},"blockType":8},{"position":{"x":6,"y":-30,"z":2},"blockType":8},{"position":{"x":7,"y":-30,"z":2},"blockType":8},{"position":{"x":8,"y":-30,"z":1},"blockType":8},{"position":{"x":8,"y":-30,"z":0},"blockType":8},{"position":{"x":8,"y":-30,"z":-1},"blockType":8},{"position":{"x":-2,"y":-30,"z":4},"blockType":6},{"position":{"x":-2,"y":-30,"z":3},"blockType":6},{"position":{"x":-2,"y":-30,"z":5},"blockType":8},{"position":{"x":-2,"y":-30,"z":8},"blockType":8},{"position":{"x":2,"y":-30,"z":8},"blockType":8},{"position":{"x":2,"y":-30,"z":7},"blockType":8},{"position":{"x":2,"y":-30,"z":6},"blockType":8},{"position":{"x":2,"y":-30,"z":5},"blockType":8},{"position":{"x":-2,"y":-30,"z":6},"blockType":8},{"position":{"x":-2,"y":-30,"z":7},"blockType":8},{"position":{"x":-5,"y":-29,"z":2},"blockType":2},{"position":{"x":-5,"y":-29,"z":1},"blockType":2},{"position":{"x":-5,"y":-29,"z":0},"blockType":2},{"position":{"x":-5,"y":-29,"z":-1},"blockType":2},{"position":{"x":-5,"y":-29,"z":-2},"blockType":2},{"position":{"x":-4,"y":-29,"z":-3},"blockType":2},{"position":{"x":-3,"y":-29,"z":-4},"blockType":2},{"position":{"x":-4,"y":-29,"z":3},"blockType":2},{"position":{"x":-3,"y":-29,"z":4},"blockType":2},{"position":{"x":3,"y":-29,"z":4},"blockType":2},{"position":{"x":4,"y":-29,"z":3},"blockType":2},{"position":{"x":4,"y":-29,"z":-3},"blockType":2},{"position":{"x":3,"y":-29,"z":-4},"blockType":2},{"position":{"x":-6,"y":-29,"z":2},"blockType":2},{"position":{"x":-6,"y":-29,"z":1},"blockType":2},{"position":{"x":-6,"y":-29,"z":0},"blockType":2},{"position":{"x":-6,"y":-29,"z":-1},"blockType":2},{"position":{"x":-6,"y":-29,"z":-2},"blockType":2},{"position":{"x":-7,"y":-29,"z":-2},"blockType":2},{"position":{"x":-7,"y":-29,"z":-1},"blockType":2},{"position":{"x":-7,"y":-29,"z":0},"blockType":2},{"position":{"x":-7,"y":-29,"z":1},"blockType":2},{"position":{"x":-7,"y":-29,"z":2},"blockType":2},{"position":{"x":-8,"y":-29,"z":-2},"blockType":2},{"position":{"x":-8,"y":-29,"z":-1},"blockType":2},{"position":{"x":-8,"y":-29,"z":0},"blockType":2},{"position":{"x":-8,"y":-29,"z":1},"blockType":2},{"position":{"x":-8,"y":-29,"z":2},"blockType":2},{"position":{"x":5,"y":-29,"z":-3},"blockType":2},{"position":{"x":4,"y":-29,"z":-4},"blockType":2},{"position":{"x":3,"y":-29,"z":-5},"blockType":2},{"position":{"x":6,"y":-29,"z":-3},"blockType":2},{"position":{"x":5,"y":-29,"z":-4},"blockType":2},{"position":{"x":4,"y":-29,"z":-5},"blockType":2},{"position":{"x":3,"y":-29,"z":-6},"blockType":2},{"position":{"x":7,"y":-29,"z":-3},"blockType":2},{"position":{"x":6,"y":-29,"z":-4},"blockType":2},{"position":{"x":5,"y":-29,"z":-5},"blockType":2},{"position":{"x":4,"y":-29,"z":-6},"blockType":2},{"position":{"x":3,"y":-29,"z":-7},"blockType":2},{"position":{"x":5,"y":-29,"z":3},"blockType":2},{"position":{"x":4,"y":-29,"z":4},"blockType":2},{"position":{"x":3,"y":-29,"z":5},"blockType":2},{"position":{"x":3,"y":-29,"z":6},"blockType":2},{"position":{"x":4,"y":-29,"z":5},"blockType":2},{"position":{"x":5,"y":-29,"z":4},"blockType":2},{"position":{"x":6,"y":-29,"z":3},"blockType":2},{"position":{"x":7,"y":-29,"z":3},"blockType":2},{"position":{"x":6,"y":-29,"z":4},"blockType":2},{"position":{"x":5,"y":-29,"z":5},"blockType":2},{"position":{"x":4,"y":-29,"z":6},"blockType":2},{"position":{"x":3,"y":-29,"z":7},"blockType":2},{"position":{"x":-3,"y":-29,"z":-5},"blockType":2},{"position":{"x":-4,"y":-29,"z":-4},"blockType":2},{"position":{"x":-5,"y":-29,"z":-3},"blockType":2},{"position":{"x":-6,"y":-29,"z":-3},"blockType":2},{"position":{"x":-5,"y":-29,"z":-4},"blockType":2},{"position":{"x":-4,"y":-29,"z":-5},"blockType":2},{"position":{"x":-3,"y":-29,"z":-6},"blockType":2},{"position":{"x":-3,"y":-29,"z":-7},"blockType":2},{"position":{"x":-4,"y":-29,"z":-6},"blockType":2},{"position":{"x":-5,"y":-29,"z":-5},"blockType":2},{"position":{"x":-6,"y":-29,"z":-4},"blockType":2},{"position":{"x":-7,"y":-29,"z":-3},"blockType":2},{"position":{"x":-3,"y":-29,"z":5},"blockType":2},{"position":{"x":-4,"y":-29,"z":4},"blockType":2},{"position":{"x":-5,"y":-29,"z":3},"blockType":2},{"position":{"x":-6,"y":-29,"z":3},"blockType":2},{"position":{"x":-5,"y":-29,"z":4},"blockType":2},{"position":{"x":-4,"y":-29,"z":5},"blockType":2},{"position":{"x":-3,"y":-29,"z":6},"blockType":2},{"position":{"x":-3,"y":-29,"z":7},"blockType":2},{"position":{"x":-4,"y":-29,"z":6},"blockType":2},{"position":{"x":-5,"y":-29,"z":5},"blockType":2},{"position":{"x":-6,"y":-29,"z":4},"blockType":2},{"position":{"x":-7,"y":-29,"z":3},"blockType":2},{"position":{"x":2,"y":-29,"z":-5},"blockType":2},{"position":{"x":1,"y":-29,"z":-5},"blockType":2},{"position":{"x":0,"y":-29,"z":-5},"blockType":2},{"position":{"x":-1,"y":-29,"z":-5},"blockType":2},{"position":{"x":-2,"y":-29,"z":-5},"blockType":2},{"position":{"x":-2,"y":-29,"z":-6},"blockType":2},{"position":{"x":-2,"y":-29,"z":-7},"blockType":2},{"position":{"x":-2,"y":-29,"z":-8},"blockType":2},{"position":{"x":-1,"y":-29,"z":-8},"blockType":2},{"position":{"x":0,"y":-29,"z":-8},"blockType":2},{"position":{"x":1,"y":-29,"z":-8},"blockType":2},{"position":{"x":2,"y":-29,"z":-8},"blockType":2},{"position":{"x":2,"y":-29,"z":-6},"blockType":2},{"position":{"x":2,"y":-29,"z":-7},"blockType":2},{"position":{"x":1,"y":-29,"z":-6},"blockType":2},{"position":{"x":0,"y":-29,"z":-6},"blockType":2},{"position":{"x":-1,"y":-29,"z":-6},"blockType":2},{"position":{"x":1,"y":-29,"z":-7},"blockType":2},{"position":{"x":0,"y":-29,"z":-7},"blockType":2},{"position":{"x":-1,"y":-29,"z":-7},"blockType":2},{"position":{"x":5,"y":-29,"z":2},"blockType":2},{"position":{"x":6,"y":-29,"z":2},"blockType":2},{"position":{"x":7,"y":-29,"z":2},"blockType":2},{"position":{"x":8,"y":-29,"z":2},"blockType":2},{"position":{"x":8,"y":-29,"z":-2},"blockType":2},{"position":{"x":7,"y":-29,"z":-2},"blockType":2},{"position":{"x":7,"y":-29,"z":-1},"blockType":2},{"position":{"x":8,"y":-29,"z":-1},"blockType":2},{"position":{"x":7,"y":-29,"z":0},"blockType":2},{"position":{"x":8,"y":-29,"z":1},"blockType":2},{"position":{"x":8,"y":-29,"z":0},"blockType":2},{"position":{"x":7,"y":-29,"z":1},"blockType":2},{"position":{"x":6,"y":-29,"z":1},"blockType":2},{"position":{"x":6,"y":-29,"z":0},"blockType":2},{"position":{"x":6,"y":-29,"z":-1},"blockType":2},{"position":{"x":6,"y":-29,"z":-2},"blockType":2},{"position":{"x":5,"y":-29,"z":-2},"blockType":2},{"position":{"x":5,"y":-29,"z":-1},"blockType":2},{"position":{"x":5,"y":-29,"z":0},"blockType":2},{"position":{"x":5,"y":-29,"z":1},"blockType":2},{"position":{"x":-2,"y":-29,"z":5},"blockType":8},{"position":{"x":-2,"y":-29,"z":8},"blockType":8},{"position":{"x":2,"y":-29,"z":8},"blockType":8},{"position":{"x":2,"y":-29,"z":5},"blockType":8},{"position":{"x":-2,"y":-29,"z":2},"blockType":6},{"position":{"x":-3,"y":-29,"z":3},"blockType":6},{"position":{"x":-5,"y":-28,"z":2},"blockType":2},{"position":{"x":-5,"y":-28,"z":1},"blockType":2},{"position":{"x":-5,"y":-28,"z":0},"blockType":2},{"position":{"x":-5,"y":-28,"z":-1},"blockType":2},{"position":{"x":-5,"y":-28,"z":-2},"blockType":2},{"position":{"x":-4,"y":-28,"z":-3},"blockType":2},{"position":{"x":-3,"y":-28,"z":-4},"blockType":2},{"position":{"x":-4,"y":-28,"z":3},"blockType":2},{"position":{"x":-3,"y":-28,"z":4},"blockType":2},{"position":{"x":3,"y":-28,"z":4},"blockType":2},{"position":{"x":4,"y":-28,"z":3},"blockType":2},{"position":{"x":4,"y":-28,"z":-3},"blockType":2},{"position":{"x":3,"y":-28,"z":-4},"blockType":2},{"position":{"x":-6,"y":-28,"z":2},"blockType":2},{"position":{"x":-6,"y":-28,"z":1},"blockType":2},{"position":{"x":-6,"y":-28,"z":0},"blockType":2},{"position":{"x":-6,"y":-28,"z":-1},"blockType":2},{"position":{"x":-6,"y":-28,"z":-2},"blockType":2},{"position":{"x":-7,"y":-28,"z":-2},"blockType":2},{"position":{"x":-7,"y":-28,"z":-1},"blockType":2},{"position":{"x":-7,"y":-28,"z":0},"blockType":2},{"position":{"x":-7,"y":-28,"z":1},"blockType":2},{"position":{"x":-7,"y":-28,"z":2},"blockType":2},{"position":{"x":-8,"y":-28,"z":-2},"blockType":2},{"position":{"x":-8,"y":-28,"z":-1},"blockType":2},{"position":{"x":-8,"y":-28,"z":0},"blockType":2},{"position":{"x":-8,"y":-28,"z":1},"blockType":2},{"position":{"x":-8,"y":-28,"z":2},"blockType":2},{"position":{"x":5,"y":-28,"z":-3},"blockType":2},{"position":{"x":4,"y":-28,"z":-4},"blockType":2},{"position":{"x":3,"y":-28,"z":-5},"blockType":2},{"position":{"x":6,"y":-28,"z":-3},"blockType":2},{"position":{"x":5,"y":-28,"z":-4},"blockType":2},{"position":{"x":4,"y":-28,"z":-5},"blockType":2},{"position":{"x":3,"y":-28,"z":-6},"blockType":2},{"position":{"x":7,"y":-28,"z":-3},"blockType":2},{"position":{"x":6,"y":-28,"z":-4},"blockType":2},{"position":{"x":5,"y":-28,"z":-5},"blockType":2},{"position":{"x":4,"y":-28,"z":-6},"blockType":2},{"position":{"x":3,"y":-28,"z":-7},"blockType":2},{"position":{"x":5,"y":-28,"z":3},"blockType":2},{"position":{"x":4,"y":-28,"z":4},"blockType":2},{"position":{"x":3,"y":-28,"z":5},"blockType":2},{"position":{"x":3,"y":-28,"z":6},"blockType":2},{"position":{"x":4,"y":-28,"z":5},"blockType":2},{"position":{"x":5,"y":-28,"z":4},"blockType":2},{"position":{"x":6,"y":-28,"z":3},"blockType":2},{"position":{"x":7,"y":-28,"z":3},"blockType":2},{"position":{"x":6,"y":-28,"z":4},"blockType":2},{"position":{"x":5,"y":-28,"z":5},"blockType":2},{"position":{"x":4,"y":-28,"z":6},"blockType":2},{"position":{"x":3,"y":-28,"z":7},"blockType":2},{"position":{"x":-3,"y":-28,"z":-5},"blockType":2},{"position":{"x":-4,"y":-28,"z":-4},"blockType":2},{"position":{"x":-5,"y":-28,"z":-3},"blockType":2},{"position":{"x":-6,"y":-28,"z":-3},"blockType":2},{"position":{"x":-5,"y":-28,"z":-4},"blockType":2},{"position":{"x":-4,"y":-28,"z":-5},"blockType":2},{"position":{"x":-3,"y":-28,"z":-6},"blockType":2},{"position":{"x":-3,"y":-28,"z":-7},"blockType":2},{"position":{"x":-4,"y":-28,"z":-6},"blockType":2},{"position":{"x":-5,"y":-28,"z":-5},"blockType":2},{"position":{"x":-6,"y":-28,"z":-4},"blockType":2},{"position":{"x":-7,"y":-28,"z":-3},"blockType":2},{"position":{"x":-3,"y":-28,"z":5},"blockType":2},{"position":{"x":-4,"y":-28,"z":4},"blockType":2},{"position":{"x":-5,"y":-28,"z":3},"blockType":2},{"position":{"x":-6,"y":-28,"z":3},"blockType":2},{"position":{"x":-5,"y":-28,"z":4},"blockType":2},{"position":{"x":-4,"y":-28,"z":5},"blockType":2},{"position":{"x":-3,"y":-28,"z":6},"blockType":2},{"position":{"x":-3,"y":-28,"z":7},"blockType":2},{"position":{"x":-4,"y":-28,"z":6},"blockType":2},{"position":{"x":-5,"y":-28,"z":5},"blockType":2},{"position":{"x":-6,"y":-28,"z":4},"blockType":2},{"position":{"x":-7,"y":-28,"z":3},"blockType":2},{"position":{"x":2,"y":-28,"z":-5},"blockType":2},{"position":{"x":1,"y":-28,"z":-5},"blockType":2},{"position":{"x":0,"y":-28,"z":-5},"blockType":2},{"position":{"x":-1,"y":-28,"z":-5},"blockType":2},{"position":{"x":-2,"y":-28,"z":-5},"blockType":2},{"position":{"x":-2,"y":-28,"z":-6},"blockType":2},{"position":{"x":-2,"y":-28,"z":-7},"blockType":2},{"position":{"x":-2,"y":-28,"z":-8},"blockType":2},{"position":{"x":-1,"y":-28,"z":-8},"blockType":2},{"position":{"x":0,"y":-28,"z":-8},"blockType":2},{"position":{"x":1,"y":-28,"z":-8},"blockType":2},{"position":{"x":2,"y":-28,"z":-8},"blockType":2},{"position":{"x":2,"y":-28,"z":-6},"blockType":2},{"position":{"x":2,"y":-28,"z":-7},"blockType":2},{"position":{"x":1,"y":-28,"z":-6},"blockType":2},{"position":{"x":0,"y":-28,"z":-6},"blockType":2},{"position":{"x":-1,"y":-28,"z":-6},"blockType":2},{"position":{"x":1,"y":-28,"z":-7},"blockType":2},{"position":{"x":0,"y":-28,"z":-7},"blockType":2},{"position":{"x":-1,"y":-28,"z":-7},"blockType":2},{"position":{"x":5,"y":-28,"z":2},"blockType":2},{"position":{"x":6,"y":-28,"z":2},"blockType":2},{"position":{"x":7,"y":-28,"z":2},"blockType":2},{"position":{"x":8,"y":-28,"z":2},"blockType":2},{"position":{"x":8,"y":-28,"z":-2},"blockType":2},{"position":{"x":7,"y":-28,"z":-2},"blockType":2},{"position":{"x":7,"y":-28,"z":-1},"blockType":2},{"position":{"x":8,"y":-28,"z":-1},"blockType":2},{"position":{"x":7,"y":-28,"z":0},"blockType":2},{"position":{"x":8,"y":-28,"z":1},"blockType":2},{"position":{"x":8,"y":-28,"z":0},"blockType":2},{"position":{"x":7,"y":-28,"z":1},"blockType":2},{"position":{"x":6,"y":-28,"z":1},"blockType":2},{"position":{"x":6,"y":-28,"z":0},"blockType":2},{"position":{"x":6,"y":-28,"z":-1},"blockType":2},{"position":{"x":6,"y":-28,"z":-2},"blockType":2},{"position":{"x":5,"y":-28,"z":-2},"blockType":2},{"position":{"x":5,"y":-28,"z":-1},"blockType":2},{"position":{"x":5,"y":-28,"z":0},"blockType":2},{"position":{"x":5,"y":-28,"z":1},"blockType":2},{"position":{"x":-2,"y":-28,"z":5},"blockType":8},{"position":{"x":-2,"y":-28,"z":8},"blockType":8},{"position":{"x":2,"y":-28,"z":8},"blockType":8},{"position":{"x":2,"y":-28,"z":5},"blockType":8},{"position":{"x":-3,"y":-28,"z":2},"blockType":6},{"position":{"x":-5,"y":-27,"z":2},"blockType":2},{"position":{"x":-5,"y":-27,"z":1},"blockType":2},{"position":{"x":-5,"y":-27,"z":0},"blockType":2},{"position":{"x":-5,"y":-27,"z":-1},"blockType":2},{"position":{"x":-5,"y":-27,"z":-2},"blockType":2},{"position":{"x":-4,"y":-27,"z":-3},"blockType":2},{"position":{"x":-3,"y":-27,"z":-4},"blockType":2},{"position":{"x":-4,"y":-27,"z":3},"blockType":2},{"position":{"x":-3,"y":-27,"z":4},"blockType":2},{"position":{"x":3,"y":-27,"z":4},"blockType":2},{"position":{"x":4,"y":-27,"z":3},"blockType":2},{"position":{"x":4,"y":-27,"z":-3},"blockType":2},{"position":{"x":3,"y":-27,"z":-4},"blockType":2},{"position":{"x":-6,"y":-27,"z":2},"blockType":2},{"position":{"x":-6,"y":-27,"z":1},"blockType":2},{"position":{"x":-6,"y":-27,"z":0},"blockType":2},{"position":{"x":-6,"y":-27,"z":-1},"blockType":2},{"position":{"x":-6,"y":-27,"z":-2},"blockType":2},