{"directory":"/Resources/BlockStructure/","configurationData":{"type":0,"distance":0,"padding":0,"height":0,"isTwoDirection":false},"blocks":[{"position":{"x":0,"y":1,"z":0},"blockType":5},{"position":{"x":0,"y":0,"z":0},"blockType":5},{"position":{"x":0,"y":2,"z":0},"blockType":5},{"position":{"x":0,"y":3,"z":0},"blockType":5},{"position":{"x":0,"y":4,"z":0},"blockType":5},{"position":{"x":-1,"y":4,"z":0},"blockType":40},{"position":{"x":-1,"y":4,"z":-1},"blockType":40},{"position":{"x":0,"y":4,"z":-1},"blockType":40},{"position":{"x":1,"y":4,"z":-1},"blockType":40},{"position":{"x":-1,"y":4,"z":1},"blockType":40},{"position":{"x":0,"y":4,"z":1},"blockType":40},{"position":{"x":1,"y":4,"z":1},"blockType":40},{"position":{"x":1,"y":4,"z":0},"blockType":40},{"position":{"x":-1,"y":4,"z":-2},"blockType":40},{"position":{"x":0,"y":4,"z":-2},"blockType":40},{"position":{"x":1,"y":4,"z":-2},"blockType":40},{"position":{"x":-2,"y":4,"z":-1},"blockType":40},{"position":{"x":-2,"y":4,"z":0},"blockType":40},{"position":{"x":-2,"y":4,"z":1},"blockType":40},{"position":{"x":-1,"y":4,"z":2},"blockType":40},{"position":{"x":0,"y":4,"z":2},"blockType":40},{"position":{"x":1,"y":4,"z":2},"blockType":40},{"position":{"x":2,"y":4,"z":1},"blockType":40},{"position":{"x":2,"y":4,"z":0},"blockType":40},{"position":{"x":2,"y":4,"z":-1},"blockType":40},{"position":{"x":0,"y":5,"z":0},"blockType":5},{"position":{"x":-1,"y":5,"z":0},"blockType":40},{"position":{"x":-1,"y":5,"z":-1},"blockType":40},{"position":{"x":0,"y":5,"z":-1},"blockType":40},{"position":{"x":1,"y":5,"z":-1},"blockType":40},{"position":{"x":-1,"y":5,"z":1},"blockType":40},{"position":{"x":0,"y":5,"z":1},"blockType":40},{"position":{"x":1,"y":5,"z":1},"blockType":40},{"position":{"x":1,"y":5,"z":0},"blockType":40},{"position":{"x":-1,"y":5,"z":-2},"blockType":40},{"position":{"x":0,"y":5,"z":-2},"blockType":40},{"position":{"x":1,"y":5,"z":-2},"blockType":40},{"position":{"x":-2,"y":5,"z":-1},"blockType":40},{"position":{"x":-2,"y":5,"z":0},"blockType":40},{"position":{"x":-2,"y":5,"z":1},"blockType":40},{"position":{"x":-1,"y":5,"z":2},"blockType":40},{"position":{"x":0,"y":5,"z":2},"blockType":40},{"position":{"x":1,"y":5,"z":2},"blockType":40},{"position":{"x":2,"y":5,"z":1},"blockType":40},{"position":{"x":2,"y":5,"z":0},"blockType":40},{"position":{"x":2,"y":5,"z":-1},"blockType":40},{"position":{"x":-1,"y":5,"z":-3},"blockType":40},{"position":{"x":0,"y":5,"z":-3},"blockType":40},{"position":{"x":1,"y":5,"z":-3},"blockType":40},{"position":{"x":-2,"y":5,"z":-2},"blockType":40},{"position":{"x":-3,"y":5,"z":-1},"blockType":40},{"position":{"x":-3,"y":5,"z":0},"blockType":40},{"position":{"x":-3,"y":5,"z":1},"blockType":40},{"position":{"x":-2,"y":5,"z":2},"blockType":40},{"position":{"x":-1,"y":5,"z":3},"blockType":40},{"position":{"x":0,"y":5,"z":3},"blockType":40},{"position":{"x":1,"y":5,"z":3},"blockType":40},{"position":{"x":2,"y":5,"z":2},"blockType":40},{"position":{"x":3,"y":5,"z":1},"blockType":40},{"position":{"x":3,"y":5,"z":0},"blockType":40},{"position":{"x":3,"y":5,"z":-1},"blockType":40},{"position":{"x":2,"y":5,"z":-2},"blockType":40},{"position":{"x":0,"y":6,"z":0},"blockType":5},{"position":{"x":-1,"y":6,"z":0},"blockType":40},{"position":{"x":-1,"y":6,"z":-1},"blockType":40},{"position":{"x":0,"y":6,"z":-1},"blockType":40},{"position":{"x":1,"y":6,"z":-1},"blockType":40},{"position":{"x":-1,"y":6,"z":1},"blockType":40},{"position":{"x":0,"y":6,"z":1},"blockType":40},{"position":{"x":1,"y":6,"z":1},"blockType":40},{"position":{"x":1,"y":6,"z":0},"blockType":40},{"position":{"x":-1,"y":6,"z":-2},"blockType":40},{"position":{"x":0,"y":6,"z":-2},"blockType":40},{"position":{"x":1,"y":6,"z":-2},"blockType":40},{"position":{"x":-2,"y":6,"z":-1},"blockType":40},{"position":{"x":-2,"y":6,"z":0},"blockType":40},{"position":{"x":-2,"y":6,"z":1},"blockType":40},{"position":{"x":-1,"y":6,"z":2},"blockType":40},{"position":{"x":0,"y":6,"z":2},"blockType":40},{"position":{"x":1,"y":6,"z":2},"blockType":40},{"position":{"x":2,"y":6,"z":1},"blockType":40},{"position":{"x":2,"y":6,"z":0},"blockType":40},{"position":{"x":2,"y":6,"z":-1},"blockType":40},{"position":{"x":-1,"y":6,"z":-3},"blockType":40},{"position":{"x":0,"y":6,"z":-3},"blockType":40},{"position":{"x":1,"y":6,"z":-3},"blockType":40},{"position":{"x":-2,"y":6,"z":-2},"blockType":40},{"position":{"x":-3,"y":6,"z":-1},"blockType":40},{"position":{"x":-3,"y":6,"z":0},"blockType":40},{"position":{"x":-3,"y":6,"z":1},"blockType":40},{"position":{"x":-2,"y":6,"z":2},"blockType":40},{"position":{"x":-1,"y":6,"z":3},"blockType":40},{"position":{"x":0,"y":6,"z":3},"blockType":40},{"position":{"x":1,"y":6,"z":3},"blockType":40},{"position":{"x":2,"y":6,"z":2},"blockType":40},{"position":{"x":3,"y":6,"z":1},"blockType":40},{"position":{"x":3,"y":6,"z":0},"blockType":40},{"position":{"x":3,"y":6,"z":-1},"blockType":40},{"position":{"x":2,"y":6,"z":-2},"blockType":40},{"position":{"x":0,"y":7,"z":0},"blockType":5},{"position":{"x":-1,"y":7,"z":0},"blockType":40},{"position":{"x":-1,"y":7,"z":-1},"blockType":40},{"position":{"x":0,"y":7,"z":-1},"blockType":40},{"position":{"x":1,"y":7,"z":-1},"blockType":40},{"position":{"x":-1,"y":7,"z":1},"blockType":40},{"position":{"x":0,"y":7,"z":1},"blockType":40},{"position":{"x":1,"y":7,"z":1},"blockType":40},{"position":{"x":1,"y":7,"z":0},"blockType":40},{"position":{"x":-1,"y":7,"z":-2},"blockType":40},{"position":{"x":0,"y":7,"z":-2},"blockType":40},{"position":{"x":1,"y":7,"z":-2},"blockType":40},{"position":{"x":-2,"y":7,"z":-1},"blockType":40},{"position":{"x":-2,"y":7,"z":0},"blockType":40},{"position":{"x":-2,"y":7,"z":1},"blockType":40},{"position":{"x":-1,"y":7,"z":2},"blockType":40},{"position":{"x":0,"y":7,"z":2},"blockType":40},{"position":{"x":1,"y":7,"z":2},"blockType":40},{"position":{"x":2,"y":7,"z":1},"blockType":40},{"position":{"x":2,"y":7,"z":0},"blockType":40},{"position":{"x":2,"y":7,"z":-1},"blockType":40},{"position":{"x":-1,"y":7,"z":-3},"blockType":40},{"position":{"x":0,"y":7,"z":-3},"blockType":40},{"position":{"x":1,"y":7,"z":-3},"blockType":40},{"position":{"x":-2,"y":7,"z":-2},"blockType":40},{"position":{"x":-3,"y":7,"z":-1},"blockType":40},{"position":{"x":-3,"y":7,"z":0},"blockType":40},{"position":{"x":-3,"y":7,"z":1},"blockType":40},{"position":{"x":-2,"y":7,"z":2},"blockType":40},{"position":{"x":-1,"y":7,"z":3},"blockType":40},{"position":{"x":0,"y":7,"z":3},"blockType":40},{"position":{"x":1,"y":7,"z":3},"blockType":40},{"position":{"x":2,"y":7,"z":2},"blockType":40},{"position":{"x":3,"y":7,"z":1},"blockType":40},{"position":{"x":3,"y":7,"z":0},"blockType":40},{"position":{"x":3,"y":7,"z":-1},"blockType":40},{"position":{"x":2,"y":7,"z":-2},"blockType":40},{"position":{"x":-1,"y":8,"z":0},"blockType":40},{"position":{"x":-1,"y":8,"z":-1},"blockType":40},{"position":{"x":0,"y":8,"z":-1},"blockType":40},{"position":{"x":1,"y":8,"z":-1},"blockType":40},{"position":{"x":-1,"y":8,"z":1},"blockType":40},{"position":{"x":0,"y":8,"z":1},"blockType":40},{"position":{"x":1,"y":8,"z":1},"blockType":40},{"position":{"x":1,"y":8,"z":0},"blockType":40},{"position":{"x":-1,"y":8,"z":-2},"blockType":40},{"position":{"x":0,"y":8,"z":-2},"blockType":40},{"position":{"x":1,"y":8,"z":-2},"blockType":40},{"position":{"x":-2,"y":8,"z":-1},"blockType":40},{"position":{"x":-2,"y":8,"z":0},"blockType":40},{"position":{"x":-2,"y":8,"z":1},"blockType":40},{"position":{"x":-1,"y":8,"z":2},"blockType":40},{"position":{"x":0,"y":8,"z":2},"blockType":40},{"position":{"x":1,"y":8,"z":2},"blockType":40},{"position":{"x":2,"y":8,"z":1},"blockType":40},{"position":{"x":2,"y":8,"z":0},"blockType":40},{"position":{"x":2,"y":8,"z":-1},"blockType":40},{"position":{"x":0,"y":8,"z":0},"blockType":40}]}